Workbook
Name precio: 'Supuestos'!$C$2
Name acciones_diluidas: 'Supuestos'!$C$3
Name ingresos_base: 'Supuestos'!$C$4
Name fraccion: 'Supuestos'!$C$5
Name fraccion_flujo: 'Supuestos'!$C$6
Name mitad_de_anio: 'Supuestos'!$C$7
Name bin_inicial: 'Supuestos'!$C$8
Name ke: 'Supuestos'!$C$9
Name horizonte_meses: 'Supuestos'!$C$10
Name dpa_horizonte: 'Supuestos'!$C$11
Name ajuste_puente: 'Supuestos'!$C$12
Name deuda_neta: 'Supuestos'!$C$13
Name wacc_calculado: 'Supuestos'!$C$14
Name sbc_coste: 'Supuestos'!$C$15
Name wacc_pes: 'Pesimista'!$C$2
Name g_pes: 'Pesimista'!$C$3
Name peso_pes: 'Pesimista'!$C$4
Name ronic_pes: 'Pesimista'!$C$5
Name multiplo_pes: 'Pesimista'!$C$6
Name fm_pes: 'Pesimista'!$C$7
Name suma_va_pes: 'Pesimista'!$C$34
Name vt_pes: 'Pesimista'!$C$35
Name va_vt_pes: 'Pesimista'!$C$36
Name ev_pes: 'Pesimista'!$C$37
Name fondos_propios_pes: 'Pesimista'!$C$38
Name acciones_valor_pes: 'Pesimista'!$C$39
Name valor_accion_pes: 'Pesimista'!$C$40
Name valor_h_pes: 'Pesimista'!$C$41
Name wacc_base: 'Base'!$C$2
Name g_base: 'Base'!$C$3
Name peso_base: 'Base'!$C$4
Name ronic_base: 'Base'!$C$5
Name multiplo_base: 'Base'!$C$6
Name fm_base: 'Base'!$C$7
Name suma_va_base: 'Base'!$C$34
Name vt_base: 'Base'!$C$35
Name va_vt_base: 'Base'!$C$36
Name ev_base: 'Base'!$C$37
Name fondos_propios_base: 'Base'!$C$38
Name acciones_valor_base: 'Base'!$C$39
Name valor_accion_base: 'Base'!$C$40
Name valor_h_base: 'Base'!$C$41
Name wacc_opt: 'Optimista'!$C$2
Name g_opt: 'Optimista'!$C$3
Name peso_opt: 'Optimista'!$C$4
Name ronic_opt: 'Optimista'!$C$5
Name multiplo_opt: 'Optimista'!$C$6
Name fm_opt: 'Optimista'!$C$7
Name suma_va_opt: 'Optimista'!$C$34
Name vt_opt: 'Optimista'!$C$35
Name va_vt_opt: 'Optimista'!$C$36
Name ev_opt: 'Optimista'!$C$37
Name fondos_propios_opt: 'Optimista'!$C$38
Name acciones_valor_opt: 'Optimista'!$C$39
Name valor_accion_opt: 'Optimista'!$C$40
Name valor_h_opt: 'Optimista'!$C$41
Name valor_razonable: 'Resumen'!$C$7
Name po: 'Resumen'!$C$8
Name potencial: 'Resumen'!$C$9
Name margen_seguridad: 'Resumen'!$C$10

Sheet Supuestos
A1: Rango | B1: Supuesto | C1: Valor | D1: Origen / justificación
A2: precio | B2: Precio: cierre oficial en la fecha de valoración (USD/acción) | C2: 0.83 | D2: Nasdaq
A3: acciones_diluidas | B3: Acciones diluidas | C3: 23791210 | D3: acciones admitidas a negociación que publica la bolsa (incluyen la autocartera): el emisor no publica acciones medias ni instrumentos dilutivos en cifras
A4: ingresos_base | B4: Ingresos del año base (USD) | C4: 16834046 | D4: SEC (hechos verificados)
A5: fraccion | B5: Fracción del ejercicio 1 que queda (f) | C5: 0.26575342 | D5: días hasta el cierre / días del ejercicio
A6: fraccion_flujo | B6: Parte del FCFF del año 1 que entra (f_flujo) | C6: 1 | D6: días del último balance al cierre / días del ejercicio
A7: mitad_de_anio | B7: Convención de mitad de año (1 sí, 0 no) | C7: 1 | D7: entradas del analista
A8: bin_inicial | B8: Bases imponibles negativas iniciales (USD) | C8: 0 | D8: entradas del analista
A9: ke | B9: Coste de los fondos propios (Ke) | C9: 0.11774702 | D9: rf + β × ERP + prima
A10: horizonte_meses | B10: Horizonte (meses) | C10: 12 | D10: entradas del analista
A11: dpa_horizonte | B11: Dividendos por acción esperados en el horizonte (USD) | C11: 0 | D11: DPA anual vigente × horizonte / 12: bolsa, SEC o el cero que declara el 10-K (fuente en el informe)
A12: ajuste_puente | B12: Ajuste del puente: − deuda + caja + inversiones ± ajustes (USD) | C12: -2595141.7 | D12: último balance publicado
A13: deuda_neta | B13: Deuda neta (USD) | C13: 3524141.7 | D13: último balance publicado
... A15: sbc_coste | B15: SBC como coste de caja (1 sí, 0 no) | C15: 1 | D15: entradas del analista

Sheet Resumen
A1: Escenario | B1: Probabilidad | C1: V₀ | D1: V_h | E1: WACC
A2: pesimista | B2: =peso_pes | C2: =valor_accion_pes | D2: =valor_h_pes | E2: =wacc_pes
A3: base | B3: =peso_base | C3: =valor_accion_base | D3: =valor_h_base | E3: =wacc_base
A4: optimista | B4: =peso_opt | C4: =valor_accion_opt | D4: =valor_h_opt | E4: =wacc_opt
A7: valor_razonable | B7: Valor razonable hoy (Σ p·V₀) | C7: =SUMPRODUCT(B2:B4,C2:C4)
A8: po | B8: Precio objetivo (Σ p·V_h) | C8: =SUMPRODUCT(B2:B4,D2:D4)
A9: potencial | B9: Potencial | C9: =po/precio-1
A10: margen_seguridad | B10: Margen de seguridad | C10: =1-precio/valor_razonable
A11: downside | B11: Downside pesimista | C11: =valor_h_pes/precio-1
A12: recorrido_riesgo | B12: Recorrido / riesgo | C12: =IF(valor_h_pes>=precio,"sin pérdida",(po-precio)/(precio-valor_h_pes))

Sheet Pesimista
A1: Escenario pesimista: fórmulas vivas del motor (05 §3–§7)
A2: wacc_pes | B2: WACC del escenario | C2: 0.10452873
A3: g_pes | B3: Crecimiento terminal (g) | C3: 0.015
A4: peso_pes | B4: Probabilidad | C4: 0.3
A5: ronic_pes | B5: RONIC | C5: 0.1
A6: multiplo_pes | B6: Múltiplo de salida
A7: fm_pes | B7: ΔFM / Δingresos | C7: 0.12
B9: Año | C9: Año 1 | D9: Año 2 | E9: Año 3 | F9: Año 4 | G9: Año 5 | H9: Año 6 | I9: Año 7 | J9: Año 8 | K9: Año 9 | L9: Año 10
B10: crecimiento | C10: 0.12 | D10: 0.06 | E10: 0.04 | F10: 0.035 | G10: 0.03 | H10: 0.027 | I10: 0.024 | J10: 0.021 | K10: 0.018 | L10: 0.015
B11: margen | C11: -0.01 | D11: 0.01 | E11: 0.025 | F11: 0.0325 | G11: 0.04 | H11: 0.042 | I11: 0.044 | J11: 0.046 | K11: 0.048 | L11: 0.05
B12: impuesto | C12: 0 | D12: 0.075 | E12: 0.15 | F12: 0.16428571 | G12: 0.17857143 | H12: 0.19285714 | I12: 0.20714286 | J12: 0.22142857 | K12: 0.23571429 | L12: 0.25
B13: da | C13: 0.04 | D13: 0.04 | E13: 0.04 | F13: 0.04 | G13: 0.04 | H13: 0.04 | I13: 0.04 | J13: 0.04 | K13: 0.04 | L13: 0.04
B14: capex | C14: 0.035 | D14: 0.034444444 | E14: 0.033888889 | F14: 0.033333333 | G14: 0.032777778 | H14: 0.032222222 | I14: 0.031666667 | J14: 0.031111111 | K14: 0.030555556 | L14: 0.03
B15: sbc | C15: 0 | D15: 0 | E15: 0 | F15: 0 | G15: 0 | H15: 0 | I15: 0 | J15: 0 | K15: 0 | L15: 0
B17: Ingresos | C17: =ingresos_base*(1+C10) | D17: =C17*(1+D10) | E17: =D17*(1+E10) | F17: =E17*(1+F10) | G17: =F17*(1+G10) | H17: =G17*(1+H10) | I17: =H17*(1+I10) | J17: =I17*(1+J10) | K17: =J17*(1+K10) | L17: =K17*(1+L10)
B18: EBIT | C18: =C17*C11+(1-sbc_coste)*C25 | D18: =D17*D11+(1-sbc_coste)*D25 | E18: =E17*E11+(1-sbc_coste)*E25 | F18: =F17*F11+(1-sbc_coste)*F25 | G18: =G17*G11+(1-sbc_coste)*G25 | H18: =H17*H11+(1-sbc_coste)*H25 | I18: =I17*I11+(1-sbc_coste)*I25 | J18: =J17*J11+(1-sbc_coste)*J25 | ... L18: =L17*L11+(1-sbc_coste)*L25
B19: Bases imponibles negativas al inicio | C19: =bin_inicial | D19: =MAX(0,C19-MAX(C18,0))+MAX(-C18,0) | E19: =MAX(0,D19-MAX(D18,0))+MAX(-D18,0) | F19: =MAX(0,E19-MAX(E18,0))+MAX(-E18,0) | G19: =MAX(0,F19-MAX(F18,0))+MAX(-F18,0) | H19: =MAX(0,G19-MAX(G18,0))+MAX(-G18,0) | I19: =MAX(0,H19-MAX(H18,0))+MAX(-H18,0) | J19: =MAX(0,I19-MAX(I18,0))+MAX(-I18,0) | K19: =MAX(0,J19-MAX(J18,0))+MAX(-J18,0) | L19: =MAX(0,K19-MAX(K18,0))+MAX(-K18,0)
B20: Impuestos en caja | C20: =MAX(0,C18-C19)*C12 | D20: =MAX(0,D18-D19)*D12 | E20: =MAX(0,E18-E19)*E12 | F20: =MAX(0,F18-F19)*F12 | G20: =MAX(0,G18-G19)*G12 | H20: =MAX(0,H18-H19)*H12 | I20: =MAX(0,I18-I19)*I12 | J20: =MAX(0,J18-J19)*J12 | ... L20: =MAX(0,L18-L19)*L12
B21: NOPAT | C21: =C18-C20 | D21: =D18-D20 | E21: =E18-E20 | F21: =F18-F20 | G21: =G18-G20 | H21: =H18-H20 | I21: =I18-I20 | J21: =J18-J20 | ... L21: =L18-L20
B22: D&A | C22: =C17*C13 | D22: =D17*D13 | E22: =E17*E13 | F22: =F17*F13 | G22: =G17*G13 | H22: =H17*H13 | I22: =I17*I13 | J22: =J17*J13 | ... L22: =L17*L13
B23: Capex | C23: =C17*C14 | D23: =D17*D14 | E23: =E17*E14 | F23: =F17*F14 | G23: =G17*G14 | H23: =H17*H14 | I23: =I17*I14 | J23: =J17*J14 | ... L23: =L17*L14
B24: ΔFM | C24: =(C17-ingresos_base)*fm_pes | D24: =(D17-C17)*fm_pes | E24: =(E17-D17)*fm_pes | F24: =(F17-E17)*fm_pes | G24: =(G17-F17)*fm_pes | H24: =(H17-G17)*fm_pes | I24: =(I17-H17)*fm_pes | J24: =(J17-I17)*fm_pes | K24: =(K17-J17)*fm_pes | L24: =(L17-K17)*fm_pes
B25: SBC | C25: =C17*C15 | D25: =D17*D15 | E25: =E17*E15 | F25: =F17*F15 | G25: =G17*G15 | H25: =H17*H15 | I25: =I17*I15 | J25: =J17*J15 | ... L25: =L17*L15
B26: Partidas del paquete | C26: 0 | D26: 0 | E26: 0 | F26: 0 | G26: 0 | H26: 0 | I26: 0 | J26: 0 | K26: 0 | L26: 0
B27: FCFF | C27: =C21+C22-C23-C24-C26 | D27: =D21+D22-D23-D24-D26 | E27: =E21+E22-E23-E24-E26 | F27: =F21+F22-F23-F24-F26 | G27: =G21+G22-G23-G24-G26 | H27: =H21+H22-H23-H24-H26 | I27: =I21+I22-I23-I24-I26 | J27: =J21+J22-J23-J24-J26 | ... L27: =L21+L22-L23-L24-L26
B28: EBITDA | C28: =C18+C22 | D28: =D18+D22 | E28: =E18+E22 | F28: =F18+F22 | G28: =G18+G22 | H28: =H18+H22 | I28: =I18+I22 | J28: =J18+J22 | ... L28: =L18+L22
B29: Momento de descuento (años) | C29: =IF(mitad_de_anio=1,fraccion-fraccion_flujo/2,fraccion) | D29: =fraccion+1-IF(mitad_de_anio=1,0.5,0) | E29: =fraccion+2-IF(mitad_de_anio=1,0.5,0) | F29: =fraccion+3-IF(mitad_de_anio=1,0.5,0) | G29: =fraccion+4-IF(mitad_de_anio=1,0.5,0) | H29: =fraccion+5-IF(mitad_de_anio=1,0.5,0) | I29: =fraccion+6-IF(mitad_de_anio=1,0.5,0) | J29: =fraccion+7-IF(mitad_de_anio=1,0.5,0) | K29: =fraccion+8-IF(mitad_de_anio=1,0.5,0) | L29: =fraccion+9-IF(mitad_de_anio=1,0.5,0)
B30: Factor de descuento | C30: =(1+wacc_pes)^(-C29) | D30: =(1+wacc_pes)^(-D29) | E30: =(1+wacc_pes)^(-E29) | F30: =(1+wacc_pes)^(-F29) | G30: =(1+wacc_pes)^(-G29) | H30: =(1+wacc_pes)^(-H29) | I30: =(1+wacc_pes)^(-I29) | J30: =(1+wacc_pes)^(-J29) | ... L30: =(1+wacc_pes)^(-L29)
B31: Parte del año que cuenta | C31: =fraccion_flujo | D31: 1 | E31: 1 | F31: 1 | G31: 1 | H31: 1 | I31: 1 | J31: 1 | K31: 1 | L31: 1
B32: Valor actual del FCFF | C32: =C27*C30*C31 | D32: =D27*D30*D31 | E32: =E27*E30*E31 | F32: =F27*F30*F31 | G32: =G27*G30*G31 | H32: =H27*H30*H31 | I32: =I27*I30*I31 | J32: =J27*J30*J31 | ... L32: =L27*L30*L31
A34: suma_va_pes | B34: Suma del valor actual de los FCFF | C34: =SUM(C32:L32)
A35: vt_pes | B35: Valor terminal (value_driver) | C35: =L21*(1+g_pes)*(1-g_pes/ronic_pes)/(wacc_pes-g_pes)
A36: va_vt_pes | B36: Valor actual del valor terminal | C36: =C35*(1+wacc_pes)^(-(fraccion+10-1))
A37: ev_pes | B37: Valor de empresa | C37: =C34+C36
A38: fondos_propios_pes | B38: Fondos propios | C38: =C37+ajuste_puente
A39: acciones_valor_pes | B39: Acciones del valor por acción (+ las que pagan la SBC con «dilución») | C39: =acciones_diluidas+(1-sbc_coste)*SUMPRODUCT(C25:L25,C31:L31)/precio
A40: valor_accion_pes | B40: Valor por acción hoy (V₀) | C40: =C38/C39
A41: valor_h_pes | B41: Valor por acción en el horizonte (V_h) | C41: =C40*(1+ke)^(horizonte_meses/12)-dpa_horizonte
B43: Contraste del valor terminal por los tres métodos
A44: vt_value_driver_pes | B44: Value driver: NOPAT × (1 + g) × (1 − g / RONIC) / (WACC − g) | C44: =L21*(1+g_pes)*(1-g_pes/ronic_pes)/(wacc_pes-g_pes)
...

Sheet Base
A1: Escenario base: fórmulas vivas del motor (05 §3–§7)
A2: wacc_base | B2: WACC del escenario | C2: 0.10452873
A3: g_base | B3: Crecimiento terminal (g) | C3: 0.02
A4: peso_base | B4: Probabilidad | C4: 0.5
A5: ronic_base | B5: RONIC | C5: 0.12
A6: multiplo_base | B6: Múltiplo de salida
A7: fm_base | B7: ΔFM / Δingresos | C7: 0.08
B9: Año | C9: Año 1 | D9: Año 2 | E9: Año 3 | F9: Año 4 | G9: Año 5 | H9: Año 6 | I9: Año 7 | J9: Año 8 | K9: Año 9 | L9: Año 10
B10: crecimiento | C10: 0.16 | D10: 0.13 | E10: 0.11 | F10: 0.095 | G10: 0.08 | H10: 0.068 | I10: 0.056 | J10: 0.044 | K10: 0.032 | L10: 0.02
B11: margen | C11: 0.015 | D11: 0.035 | E11: 0.055 | F11: 0.0625 | G11: 0.07 | H11: 0.072 | I11: 0.074 | J11: 0.076 | K11: 0.078 | L11: 0.08
B12: impuesto | C12: 0.05 | D12: 0.125 | E12: 0.2 | F12: 0.20714286 | G12: 0.21428571 | H12: 0.22142857 | I12: 0.22857143 | J12: 0.23571429 | K12: 0.24285714 | L12: 0.25
B13: da | C13: 0.04 | D13: 0.04 | E13: 0.04 | F13: 0.04 | G13: 0.04 | H13: 0.04 | I13: 0.04 | J13: 0.04 | K13: 0.04 | L13: 0.04
B14: capex | C14: 0.035 | D14: 0.034444444 | E14: 0.033888889 | F14: 0.033333333 | G14: 0.032777778 | H14: 0.032222222 | I14: 0.031666667 | J14: 0.031111111 | K14: 0.030555556 | L14: 0.03
B15: sbc | C15: 0 | D15: 0 | E15: 0 | F15: 0 | G15: 0 | H15: 0 | I15: 0 | J15: 0 | K15: 0 | L15: 0
B17: Ingresos | C17: =ingresos_base*(1+C10) | D17: =C17*(1+D10) | E17: =D17*(1+E10) | F17: =E17*(1+F10) | G17: =F17*(1+G10) | H17: =G17*(1+H10) | I17: =H17*(1+I10) | J17: =I17*(1+J10) | K17: =J17*(1+K10) | L17: =K17*(1+L10)
B18: EBIT | C18: =C17*C11+(1-sbc_coste)*C25 | D18: =D17*D11+(1-sbc_coste)*D25 | E18: =E17*E11+(1-sbc_coste)*E25 | F18: =F17*F11+(1-sbc_coste)*F25 | G18: =G17*G11+(1-sbc_coste)*G25 | H18: =H17*H11+(1-sbc_coste)*H25 | I18: =I17*I11+(1-sbc_coste)*I25 | J18: =J17*J11+(1-sbc_coste)*J25 | ... L18: =L17*L11+(1-sbc_coste)*L25
B19: Bases imponibles negativas al inicio | C19: =bin_inicial | D19: =MAX(0,C19-MAX(C18,0))+MAX(-C18,0) | E19: =MAX(0,D19-MAX(D18,0))+MAX(-D18,0) | F19: =MAX(0,E19-MAX(E18,0))+MAX(-E18,0) | G19: =MAX(0,F19-MAX(F18,0))+MAX(-F18,0) | H19: =MAX(0,G19-MAX(G18,0))+MAX(-G18,0) | I19: =MAX(0,H19-MAX(H18,0))+MAX(-H18,0) | J19: =MAX(0,I19-MAX(I18,0))+MAX(-I18,0) | K19: =MAX(0,J19-MAX(J18,0))+MAX(-J18,0) | L19: =MAX(0,K19-MAX(K18,0))+MAX(-K18,0)
B20: Impuestos en caja | C20: =MAX(0,C18-C19)*C12 | D20: =MAX(0,D18-D19)*D12 | E20: =MAX(0,E18-E19)*E12 | F20: =MAX(0,F18-F19)*F12 | G20: =MAX(0,G18-G19)*G12 | H20: =MAX(0,H18-H19)*H12 | I20: =MAX(0,I18-I19)*I12 | J20: =MAX(0,J18-J19)*J12 | ... L20: =MAX(0,L18-L19)*L12
B21: NOPAT | C21: =C18-C20 | D21: =D18-D20 | E21: =E18-E20 | F21: =F18-F20 | G21: =G18-G20 | H21: =H18-H20 | I21: =I18-I20 | J21: =J18-J20 | ... L21: =L18-L20
B22: D&A | C22: =C17*C13 | D22: =D17*D13 | E22: =E17*E13 | F22: =F17*F13 | G22: =G17*G13 | H22: =H17*H13 | I22: =I17*I13 | J22: =J17*J13 | ... L22: =L17*L13
B23: Capex | C23: =C17*C14 | D23: =D17*D14 | E23: =E17*E14 | F23: =F17*F14 | G23: =G17*G14 | H23: =H17*H14 | I23: =I17*I14 | J23: =J17*J14 | ... L23: =L17*L14
B24: ΔFM | C24: =(C17-ingresos_base)*fm_base | D24: =(D17-C17)*fm_base | E24: =(E17-D17)*fm_base | F24: =(F17-E17)*fm_base | G24: =(G17-F17)*fm_base | H24: =(H17-G17)*fm_base | I24: =(I17-H17)*fm_base | J24: =(J17-I17)*fm_base | K24: =(K17-J17)*fm_base | L24: =(L17-K17)*fm_base
B25: SBC | C25: =C17*C15 | D25: =D17*D15 | E25: =E17*E15 | F25: =F17*F15 | G25: =G17*G15 | H25: =H17*H15 | I25: =I17*I15 | J25: =J17*J15 | ... L25: =L17*L15
B26: Partidas del paquete | C26: 0 | D26: 0 | E26: 0 | F26: 0 | G26: 0 | H26: 0 | I26: 0 | J26: 0 | K26: 0 | L26: 0
B27: FCFF | C27: =C21+C22-C23-C24-C26 | D27: =D21+D22-D23-D24-D26 | E27: =E21+E22-E23-E24-E26 | F27: =F21+F22-F23-F24-F26 | G27: =G21+G22-G23-G24-G26 | H27: =H21+H22-H23-H24-H26 | I27: =I21+I22-I23-I24-I26 | J27: =J21+J22-J23-J24-J26 | ... L27: =L21+L22-L23-L24-L26
B28: EBITDA | C28: =C18+C22 | D28: =D18+D22 | E28: =E18+E22 | F28: =F18+F22 | G28: =G18+G22 | H28: =H18+H22 | I28: =I18+I22 | J28: =J18+J22 | ... L28: =L18+L22
B29: Momento de descuento (años) | C29: =IF(mitad_de_anio=1,fraccion-fraccion_flujo/2,fraccion) | D29: =fraccion+1-IF(mitad_de_anio=1,0.5,0) | E29: =fraccion+2-IF(mitad_de_anio=1,0.5,0) | F29: =fraccion+3-IF(mitad_de_anio=1,0.5,0) | G29: =fraccion+4-IF(mitad_de_anio=1,0.5,0) | H29: =fraccion+5-IF(mitad_de_anio=1,0.5,0) | I29: =fraccion+6-IF(mitad_de_anio=1,0.5,0) | J29: =fraccion+7-IF(mitad_de_anio=1,0.5,0) | K29: =fraccion+8-IF(mitad_de_anio=1,0.5,0) | L29: =fraccion+9-IF(mitad_de_anio=1,0.5,0)
B30: Factor de descuento | C30: =(1+wacc_base)^(-C29) | D30: =(1+wacc_base)^(-D29) | E30: =(1+wacc_base)^(-E29) | F30: =(1+wacc_base)^(-F29) | G30: =(1+wacc_base)^(-G29) | H30: =(1+wacc_base)^(-H29) | I30: =(1+wacc_base)^(-I29) | J30: =(1+wacc_base)^(-J29) | ... L30: =(1+wacc_base)^(-L29)
B31: Parte del año que cuenta | C31: =fraccion_flujo | D31: 1 | E31: 1 | F31: 1 | G31: 1 | H31: 1 | I31: 1 | J31: 1 | K31: 1 | L31: 1
B32: Valor actual del FCFF | C32: =C27*C30*C31 | D32: =D27*D30*D31 | E32: =E27*E30*E31 | F32: =F27*F30*F31 | G32: =G27*G30*G31 | H32: =H27*H30*H31 | I32: =I27*I30*I31 | J32: =J27*J30*J31 | ... L32: =L27*L30*L31
A34: suma_va_base | B34: Suma del valor actual de los FCFF | C34: =SUM(C32:L32)
A35: vt_base | B35: Valor terminal (value_driver) | C35: =L21*(1+g_base)*(1-g_base/ronic_base)/(wacc_base-g_base)
A36: va_vt_base | B36: Valor actual del valor terminal | C36: =C35*(1+wacc_base)^(-(fraccion+10-1))
A37: ev_base | B37: Valor de empresa | C37: =C34+C36
A38: fondos_propios_base | B38: Fondos propios | C38: =C37+ajuste_puente
A39: acciones_valor_base | B39: Acciones del valor por acción (+ las que pagan la SBC con «dilución») | C39: =acciones_diluidas+(1-sbc_coste)*SUMPRODUCT(C25:L25,C31:L31)/precio
A40: valor_accion_base | B40: Valor por acción hoy (V₀) | C40: =C38/C39
A41: valor_h_base | B41: Valor por acción en el horizonte (V_h) | C41: =C40*(1+ke)^(horizonte_meses/12)-dpa_horizonte
B43: Contraste del valor terminal por los tres métodos
A44: vt_value_driver_base | B44: Value driver: NOPAT × (1 + g) × (1 − g / RONIC) / (WACC − g) | C44: =L21*(1+g_base)*(1-g_base/ronic_base)/(wacc_base-g_base)
...

Sheet Optimista
A1: Escenario optimista: fórmulas vivas del motor (05 §3–§7)
A2: wacc_opt | B2: WACC del escenario | C2: 0.10452873
A3: g_opt | B3: Crecimiento terminal (g) | C3: 0.025
A4: peso_opt | B4: Probabilidad | C4: 0.2
A5: ronic_opt | B5: RONIC | C5: 0.15
A6: multiplo_opt | B6: Múltiplo de salida
A7: fm_opt | B7: ΔFM / Δingresos | C7: 0.05
B9: Año | C9: Año 1 | D9: Año 2 | E9: Año 3 | F9: Año 4 | G9: Año 5 | H9: Año 6 | I9: Año 7 | J9: Año 8 | K9: Año 9 | L9: Año 10
B10: crecimiento | C10: 0.18 | D10: 0.16 | E10: 0.14 | F10: 0.12 | G10: 0.1 | H10: 0.085 | I10: 0.07 | J10: 0.055 | K10: 0.04 | L10: 0.025
B11: margen | C11: 0.03 | D11: 0.07 | E11: 0.11 | F11: 0.12 | G11: 0.13 | H11: 0.13 | I11: 0.13 | J11: 0.13 | K11: 0.13 | L11: 0.13
B12: impuesto | C12: 0.1 | D12: 0.16 | E12: 0.22 | F12: 0.22428571 | G12: 0.22857143 | H12: 0.23285714 | I12: 0.23714286 | J12: 0.24142857 | K12: 0.24571429 | L12: 0.25
B13: da | C13: 0.04 | D13: 0.04 | E13: 0.04 | F13: 0.04 | G13: 0.04 | H13: 0.04 | I13: 0.04 | J13: 0.04 | K13: 0.04 | L13: 0.04
B14: capex | C14: 0.035 | D14: 0.034444444 | E14: 0.033888889 | F14: 0.033333333 | G14: 0.032777778 | H14: 0.032222222 | I14: 0.031666667 | J14: 0.031111111 | K14: 0.030555556 | L14: 0.03
B15: sbc | C15: 0 | D15: 0 | E15: 0 | F15: 0 | G15: 0 | H15: 0 | I15: 0 | J15: 0 | K15: 0 | L15: 0
B17: Ingresos | C17: =ingresos_base*(1+C10) | D17: =C17*(1+D10) | E17: =D17*(1+E10) | F17: =E17*(1+F10) | G17: =F17*(1+G10) | H17: =G17*(1+H10) | I17: =H17*(1+I10) | J17: =I17*(1+J10) | K17: =J17*(1+K10) | L17: =K17*(1+L10)
B18: EBIT | C18: =C17*C11+(1-sbc_coste)*C25 | D18: =D17*D11+(1-sbc_coste)*D25 | E18: =E17*E11+(1-sbc_coste)*E25 | F18: =F17*F11+(1-sbc_coste)*F25 | G18: =G17*G11+(1-sbc_coste)*G25 | H18: =H17*H11+(1-sbc_coste)*H25 | I18: =I17*I11+(1-sbc_coste)*I25 | J18: =J17*J11+(1-sbc_coste)*J25 | ... L18: =L17*L11+(1-sbc_coste)*L25
B19: Bases imponibles negativas al inicio | C19: =bin_inicial | D19: =MAX(0,C19-MAX(C18,0))+MAX(-C18,0) | E19: =MAX(0,D19-MAX(D18,0))+MAX(-D18,0) | F19: =MAX(0,E19-MAX(E18,0))+MAX(-E18,0) | G19: =MAX(0,F19-MAX(F18,0))+MAX(-F18,0) | H19: =MAX(0,G19-MAX(G18,0))+MAX(-G18,0) | I19: =MAX(0,H19-MAX(H18,0))+MAX(-H18,0) | J19: =MAX(0,I19-MAX(I18,0))+MAX(-I18,0) | K19: =MAX(0,J19-MAX(J18,0))+MAX(-J18,0) | L19: =MAX(0,K19-MAX(K18,0))+MAX(-K18,0)
B20: Impuestos en caja | C20: =MAX(0,C18-C19)*C12 | D20: =MAX(0,D18-D19)*D12 | E20: =MAX(0,E18-E19)*E12 | F20: =MAX(0,F18-F19)*F12 | G20: =MAX(0,G18-G19)*G12 | H20: =MAX(0,H18-H19)*H12 | I20: =MAX(0,I18-I19)*I12 | J20: =MAX(0,J18-J19)*J12 | ... L20: =MAX(0,L18-L19)*L12
B21: NOPAT | C21: =C18-C20 | D21: =D18-D20 | E21: =E18-E20 | F21: =F18-F20 | G21: =G18-G20 | H21: =H18-H20 | I21: =I18-I20 | J21: =J18-J20 | ... L21: =L18-L20
B22: D&A | C22: =C17*C13 | D22: =D17*D13 | E22: =E17*E13 | F22: =F17*F13 | G22: =G17*G13 | H22: =H17*H13 | I22: =I17*I13 | J22: =J17*J13 | ... L22: =L17*L13
B23: Capex | C23: =C17*C14 | D23: =D17*D14 | E23: =E17*E14 | F23: =F17*F14 | G23: =G17*G14 | H23: =H17*H14 | I23: =I17*I14 | J23: =J17*J14 | ... L23: =L17*L14
B24: ΔFM | C24: =(C17-ingresos_base)*fm_opt | D24: =(D17-C17)*fm_opt | E24: =(E17-D17)*fm_opt | F24: =(F17-E17)*fm_opt | G24: =(G17-F17)*fm_opt | H24: =(H17-G17)*fm_opt | I24: =(I17-H17)*fm_opt | J24: =(J17-I17)*fm_opt | K24: =(K17-J17)*fm_opt | L24: =(L17-K17)*fm_opt
B25: SBC | C25: =C17*C15 | D25: =D17*D15 | E25: =E17*E15 | F25: =F17*F15 | G25: =G17*G15 | H25: =H17*H15 | I25: =I17*I15 | J25: =J17*J15 | ... L25: =L17*L15
B26: Partidas del paquete | C26: 0 | D26: 0 | E26: 0 | F26: 0 | G26: 0 | H26: 0 | I26: 0 | J26: 0 | K26: 0 | L26: 0
B27: FCFF | C27: =C21+C22-C23-C24-C26 | D27: =D21+D22-D23-D24-D26 | E27: =E21+E22-E23-E24-E26 | F27: =F21+F22-F23-F24-F26 | G27: =G21+G22-G23-G24-G26 | H27: =H21+H22-H23-H24-H26 | I27: =I21+I22-I23-I24-I26 | J27: =J21+J22-J23-J24-J26 | ... L27: =L21+L22-L23-L24-L26
B28: EBITDA | C28: =C18+C22 | D28: =D18+D22 | E28: =E18+E22 | F28: =F18+F22 | G28: =G18+G22 | H28: =H18+H22 | I28: =I18+I22 | J28: =J18+J22 | ... L28: =L18+L22
B29: Momento de descuento (años) | C29: =IF(mitad_de_anio=1,fraccion-fraccion_flujo/2,fraccion) | D29: =fraccion+1-IF(mitad_de_anio=1,0.5,0) | E29: =fraccion+2-IF(mitad_de_anio=1,0.5,0) | F29: =fraccion+3-IF(mitad_de_anio=1,0.5,0) | G29: =fraccion+4-IF(mitad_de_anio=1,0.5,0) | H29: =fraccion+5-IF(mitad_de_anio=1,0.5,0) | I29: =fraccion+6-IF(mitad_de_anio=1,0.5,0) | J29: =fraccion+7-IF(mitad_de_anio=1,0.5,0) | K29: =fraccion+8-IF(mitad_de_anio=1,0.5,0) | L29: =fraccion+9-IF(mitad_de_anio=1,0.5,0)
B30: Factor de descuento | C30: =(1+wacc_opt)^(-C29) | D30: =(1+wacc_opt)^(-D29) | E30: =(1+wacc_opt)^(-E29) | F30: =(1+wacc_opt)^(-F29) | G30: =(1+wacc_opt)^(-G29) | H30: =(1+wacc_opt)^(-H29) | I30: =(1+wacc_opt)^(-I29) | J30: =(1+wacc_opt)^(-J29) | ... L30: =(1+wacc_opt)^(-L29)
B31: Parte del año que cuenta | C31: =fraccion_flujo | D31: 1 | E31: 1 | F31: 1 | G31: 1 | H31: 1 | I31: 1 | J31: 1 | K31: 1 | L31: 1
B32: Valor actual del FCFF | C32: =C27*C30*C31 | D32: =D27*D30*D31 | E32: =E27*E30*E31 | F32: =F27*F30*F31 | G32: =G27*G30*G31 | H32: =H27*H30*H31 | I32: =I27*I30*I31 | J32: =J27*J30*J31 | ... L32: =L27*L30*L31
A34: suma_va_opt | B34: Suma del valor actual de los FCFF | C34: =SUM(C32:L32)
A35: vt_opt | B35: Valor terminal (value_driver) | C35: =L21*(1+g_opt)*(1-g_opt/ronic_opt)/(wacc_opt-g_opt)
A36: va_vt_opt | B36: Valor actual del valor terminal | C36: =C35*(1+wacc_opt)^(-(fraccion+10-1))
A37: ev_opt | B37: Valor de empresa | C37: =C34+C36
A38: fondos_propios_opt | B38: Fondos propios | C38: =C37+ajuste_puente
A39: acciones_valor_opt | B39: Acciones del valor por acción (+ las que pagan la SBC con «dilución») | C39: =acciones_diluidas+(1-sbc_coste)*SUMPRODUCT(C25:L25,C31:L31)/precio
A40: valor_accion_opt | B40: Valor por acción hoy (V₀) | C40: =C38/C39
A41: valor_h_opt | B41: Valor por acción en el horizonte (V_h) | C41: =C40*(1+ke)^(horizonte_meses/12)-dpa_horizonte
B43: Contraste del valor terminal por los tres métodos
A44: vt_value_driver_opt | B44: Value driver: NOPAT × (1 + g) × (1 − g / RONIC) / (WACC − g) | C44: =L21*(1+g_opt)*(1-g_opt/ronic_opt)/(wacc_opt-g_opt)
...

Sheet Sensibilidad
A1: V₀ del escenario base: WACC (filas) × g (columnas)
B2: 0.015 | C2: 0.0175 | D2: 0.02 | E2: 0.0225 | F2: 0.025
A3: 0.094528735 | B3: =IF($A3-B$2<=0,"",(SUMPRODUCT(Base!$C$27:$L$27,Base!$C$31:$L$31,(1+$A3)^(-Base!$C$29:$L$29))+Base!$L$21*(1+B$2)*(1-B$2/0.12)/($A3-B$2)*(1+$A3)^(-(fraccion+10-1))+ajuste_puente)/acciones_valor_base) | C3: =IF($A3-C$2<=0,"",(SUMPRODUCT(Base!$C$27:$L$27,Base!$C$31:$L$31,(1+$A3)^(-Base!$C$29:$L$29))+Base!$L$21*(1+C$2)*(1-C$2/0.12)/($A3-C$2)*(1+$A3)^(-(fraccion+10-1))+ajuste_puente)/acciones_valor_base) | D3: =IF($A3-D$2<=0,"",(SUMPRODUCT(Base!$C$27:$L$27,Base!$C$31:$L$31,(1+$A3)^(-Base!$C$29:$L$29))+Base!$L$21*(1+D$2)*(1-D$2/0.12)/($A3-D$2)*(1+$A3)^(-(fraccion+10-1))+ajuste_puente)/acciones_valor_base) | E3: =IF($A3-E$2<=0,"",(SUMPRODUCT(Base!$C$27:$L$27,Base!$C$31:$L$31,(1+$A3)^(-Base!$C$29:$L$29))+Base!$L$21*(1+E$2)*(1-E$2/0.12)/($A3-E$2)*(1+$A3)^(-(fraccion+10-1))+ajuste_puente)/acciones_valor_base) | F3: =IF($A3-F$2<=0,"",(SUMPRODUCT(Base!$C$27:$L$27,Base!$C$31:$L$31,(1+$A3)^(-Base!$C$29:$L$29))+Base!$L$21*(1+F$2)*(1-F$2/0.12)/($A3-F$2)*(1+$A3)^(-(fraccion+10-1))+ajuste_puente)/acciones_valor_base)
A4: 0.099528735 | B4: =IF($A4-B$2<=0,"",(SUMPRODUCT(Base!$C$27:$L$27,Base!$C$31:$L$31,(1+$A4)^(-Base!$C$29:$L$29))+Base!$L$21*(1+B$2)*(1-B$2/0.12)/($A4-B$2)*(1+$A4)^(-(fraccion+10-1))+ajuste_puente)/acciones_valor_base) | C4: =IF($A4-C$2<=0,"",(SUMPRODUCT(Base!$C$27:$L$27,Base!$C$31:$L$31,(1+$A4)^(-Base!$C$29:$L$29))+Base!$L$21*(1+C$2)*(1-C$2/0.12)/($A4-C$2)*(1+$A4)^(-(fraccion+10-1))+ajuste_puente)/acciones_valor_base) | D4: =IF($A4-D$2<=0,"",(SUMPRODUCT(Base!$C$27:$L$27,Base!$C$31:$L$31,(1+$A4)^(-Base!$C$29:$L$29))+Base!$L$21*(1+D$2)*(1-D$2/0.12)/($A4-D$2)*(1+$A4)^(-(fraccion+10-1))+ajuste_puente)/acciones_valor_base) | E4: =IF($A4-E$2<=0,"",(SUMPRODUCT(Base!$C$27:$L$27,Base!$C$31:$L$31,(1+$A4)^(-Base!$C$29:$L$29))+Base!$L$21*(1+E$2)*(1-E$2/0.12)/($A4-E$2)*(1+$A4)^(-(fraccion+10-1))+ajuste_puente)/acciones_valor_base) | F4: =IF($A4-F$2<=0,"",(SUMPRODUCT(Base!$C$27:$L$27,Base!$C$31:$L$31,(1+$A4)^(-Base!$C$29:$L$29))+Base!$L$21*(1+F$2)*(1-F$2/0.12)/($A4-F$2)*(1+$A4)^(-(fraccion+10-1))+ajuste_puente)/acciones_valor_base)
A5: 0.10452873 | B5: =IF($A5-B$2<=0,"",(SUMPRODUCT(Base!$C$27:$L$27,Base!$C$31:$L$31,(1+$A5)^(-Base!$C$29:$L$29))+Base!$L$21*(1+B$2)*(1-B$2/0.12)/($A5-B$2)*(1+$A5)^(-(fraccion+10-1))+ajuste_puente)/acciones_valor_base) | C5: =IF($A5-C$2<=0,"",(SUMPRODUCT(Base!$C$27:$L$27,Base!$C$31:$L$31,(1+$A5)^(-Base!$C$29:$L$29))+Base!$L$21*(1+C$2)*(1-C$2/0.12)/($A5-C$2)*(1+$A5)^(-(fraccion+10-1))+ajuste_puente)/acciones_valor_base) | D5: =IF($A5-D$2<=0,"",(SUMPRODUCT(Base!$C$27:$L$27,Base!$C$31:$L$31,(1+$A5)^(-Base!$C$29:$L$29))+Base!$L$21*(1+D$2)*(1-D$2/0.12)/($A5-D$2)*(1+$A5)^(-(fraccion+10-1))+ajuste_puente)/acciones_valor_base) | E5: =IF($A5-E$2<=0,"",(SUMPRODUCT(Base!$C$27:$L$27,Base!$C$31:$L$31,(1+$A5)^(-Base!$C$29:$L$29))+Base!$L$21*(1+E$2)*(1-E$2/0.12)/($A5-E$2)*(1+$A5)^(-(fraccion+10-1))+ajuste_puente)/acciones_valor_base) | F5: =IF($A5-F$2<=0,"",(SUMPRODUCT(Base!$C$27:$L$27,Base!$C$31:$L$31,(1+$A5)^(-Base!$C$29:$L$29))+Base!$L$21*(1+F$2)*(1-F$2/0.12)/($A5-F$2)*(1+$A5)^(-(fraccion+10-1))+ajuste_puente)/acciones_valor_base)
A6: 0.10952873 | B6: =IF($A6-B$2<=0,"",(SUMPRODUCT(Base!$C$27:$L$27,Base!$C$31:$L$31,(1+$A6)^(-Base!$C$29:$L$29))+Base!$L$21*(1+B$2)*(1-B$2/0.12)/($A6-B$2)*(1+$A6)^(-(fraccion+10-1))+ajuste_puente)/acciones_valor_base) | C6: =IF($A6-C$2<=0,"",(SUMPRODUCT(Base!$C$27:$L$27,Base!$C$31:$L$31,(1+$A6)^(-Base!$C$29:$L$29))+Base!$L$21*(1+C$2)*(1-C$2/0.12)/($A6-C$2)*(1+$A6)^(-(fraccion+10-1))+ajuste_puente)/acciones_valor_base) | D6: =IF($A6-D$2<=0,"",(SUMPRODUCT(Base!$C$27:$L$27,Base!$C$31:$L$31,(1+$A6)^(-Base!$C$29:$L$29))+Base!$L$21*(1+D$2)*(1-D$2/0.12)/($A6-D$2)*(1+$A6)^(-(fraccion+10-1))+ajuste_puente)/acciones_valor_base) | E6: =IF($A6-E$2<=0,"",(SUMPRODUCT(Base!$C$27:$L$27,Base!$C$31:$L$31,(1+$A6)^(-Base!$C$29:$L$29))+Base!$L$21*(1+E$2)*(1-E$2/0.12)/($A6-E$2)*(1+$A6)^(-(fraccion+10-1))+ajuste_puente)/acciones_valor_base) | F6: =IF($A6-F$2<=0,"",(SUMPRODUCT(Base!$C$27:$L$27,Base!$C$31:$L$31,(1+$A6)^(-Base!$C$29:$L$29))+Base!$L$21*(1+F$2)*(1-F$2/0.12)/($A6-F$2)*(1+$A6)^(-(fraccion+10-1))+ajuste_puente)/acciones_valor_base)
A7: 0.11452873 | B7: =IF($A7-B$2<=0,"",(SUMPRODUCT(Base!$C$27:$L$27,Base!$C$31:$L$31,(1+$A7)^(-Base!$C$29:$L$29))+Base!$L$21*(1+B$2)*(1-B$2/0.12)/($A7-B$2)*(1+$A7)^(-(fraccion+10-1))+ajuste_puente)/acciones_valor_base) | C7: =IF($A7-C$2<=0,"",(SUMPRODUCT(Base!$C$27:$L$27,Base!$C$31:$L$31,(1+$A7)^(-Base!$C$29:$L$29))+Base!$L$21*(1+C$2)*(1-C$2/0.12)/($A7-C$2)*(1+$A7)^(-(fraccion+10-1))+ajuste_puente)/acciones_valor_base) | D7: =IF($A7-D$2<=0,"",(SUMPRODUCT(Base!$C$27:$L$27,Base!$C$31:$L$31,(1+$A7)^(-Base!$C$29:$L$29))+Base!$L$21*(1+D$2)*(1-D$2/0.12)/($A7-D$2)*(1+$A7)^(-(fraccion+10-1))+ajuste_puente)/acciones_valor_base) | E7: =IF($A7-E$2<=0,"",(SUMPRODUCT(Base!$C$27:$L$27,Base!$C$31:$L$31,(1+$A7)^(-Base!$C$29:$L$29))+Base!$L$21*(1+E$2)*(1-E$2/0.12)/($A7-E$2)*(1+$A7)^(-(fraccion+10-1))+ajuste_puente)/acciones_valor_base) | F7: =IF($A7-F$2<=0,"",(SUMPRODUCT(Base!$C$27:$L$27,Base!$C$31:$L$31,(1+$A7)^(-Base!$C$29:$L$29))+Base!$L$21*(1+F$2)*(1-F$2/0.12)/($A7-F$2)*(1+$A7)^(-(fraccion+10-1))+ajuste_puente)/acciones_valor_base)

Sheet Reverse DCF
A1: DCF inverso: qué crecimiento constante del FCFF hace que V₀ del escenario base sea el precio | E1: Crecimiento constante del FCFF implícito | F1: =IFERROR(INDEX($A$4:$A$154,MATCH(precio,$B$4:$B$154,1))+(precio-INDEX($B$4:$B$154,MATCH(precio,$B$4:$B$154,1)))*(INDEX($A$4:$A$154,MATCH(precio,$B$4:$B$154,1)+1)-INDEX($A$4:$A$154,MATCH(precio,$B$4:$B$154,1)))/(INDEX($B$4:$B$154,MATCH(precio,$B$4:$B$154,1)+1)-INDEX($B$4:$B$154,MATCH(precio,$B$4:$B$154,1))),"fuera del rango")
A3: Crecimiento del FCFF | B3: V₀ (base) | C3: FCFF año 1 | D3: FCFF año 2 | E3: FCFF año 3 | F3: FCFF año 4 | G3: FCFF año 5 | H3: FCFF año 6 | I3: FCFF año 7 | J3: FCFF año 8 | K3: FCFF año 9 | L3: FCFF año 10
A4: -0.5 | B4: =(SUMPRODUCT(C4:L4,Base!$C$30:$L$30,Base!$C$31:$L$31)+L4*(1+g_base)/(wacc_base-g_base)*(1+wacc_base)^(-(fraccion+10-1))+ajuste_puente)/acciones_valor_base | C4: =Base!$C$27*(1+$A4)^0 | D4: =Base!$C$27*(1+$A4)^1 | E4: =Base!$C$27*(1+$A4)^2 | F4: =Base!$C$27*(1+$A4)^3 | G4: =Base!$C$27*(1+$A4)^4 | H4: =Base!$C$27*(1+$A4)^5 | I4: =Base!$C$27*(1+$A4)^6 | J4: =Base!$C$27*(1+$A4)^7 | K4: =Base!$C$27*(1+$A4)^8 | L4: =Base!$C$27*(1+$A4)^9
A5: -0.49 | B5: =(SUMPRODUCT(C5:L5,Base!$C$30:$L$30,Base!$C$31:$L$31)+L5*(1+g_base)/(wacc_base-g_base)*(1+wacc_base)^(-(fraccion+10-1))+ajuste_puente)/acciones_valor_base | C5: =Base!$C$27*(1+$A5)^0 | D5: =Base!$C$27*(1+$A5)^1 | E5: =Base!$C$27*(1+$A5)^2 | F5: =Base!$C$27*(1+$A5)^3 | G5: =Base!$C$27*(1+$A5)^4 | H5: =Base!$C$27*(1+$A5)^5 | I5: =Base!$C$27*(1+$A5)^6 | J5: =Base!$C$27*(1+$A5)^7 | K5: =Base!$C$27*(1+$A5)^8 | L5: =Base!$C$27*(1+$A5)^9
A6: -0.48 | B6: =(SUMPRODUCT(C6:L6,Base!$C$30:$L$30,Base!$C$31:$L$31)+L6*(1+g_base)/(wacc_base-g_base)*(1+wacc_base)^(-(fraccion+10-1))+ajuste_puente)/acciones_valor_base | C6: =Base!$C$27*(1+$A6)^0 | D6: =Base!$C$27*(1+$A6)^1 | E6: =Base!$C$27*(1+$A6)^2 | F6: =Base!$C$27*(1+$A6)^3 | G6: =Base!$C$27*(1+$A6)^4 | H6: =Base!$C$27*(1+$A6)^5 | I6: =Base!$C$27*(1+$A6)^6 | J6: =Base!$C$27*(1+$A6)^7 | K6: =Base!$C$27*(1+$A6)^8 | L6: =Base!$C$27*(1+$A6)^9
A7: -0.47 | B7: =(SUMPRODUCT(C7:L7,Base!$C$30:$L$30,Base!$C$31:$L$31)+L7*(1+g_base)/(wacc_base-g_base)*(1+wacc_base)^(-(fraccion+10-1))+ajuste_puente)/acciones_valor_base | C7: =Base!$C$27*(1+$A7)^0 | D7: =Base!$C$27*(1+$A7)^1 | E7: =Base!$C$27*(1+$A7)^2 | F7: =Base!$C$27*(1+$A7)^3 | G7: =Base!$C$27*(1+$A7)^4 | H7: =Base!$C$27*(1+$A7)^5 | I7: =Base!$C$27*(1+$A7)^6 | J7: =Base!$C$27*(1+$A7)^7 | K7: =Base!$C$27*(1+$A7)^8 | L7: =Base!$C$27*(1+$A7)^9
A8: -0.46 | B8: =(SUMPRODUCT(C8:L8,Base!$C$30:$L$30,Base!$C$31:$L$31)+L8*(1+g_base)/(wacc_base-g_base)*(1+wacc_base)^(-(fraccion+10-1))+ajuste_puente)/acciones_valor_base | C8: =Base!$C$27*(1+$A8)^0 | D8: =Base!$C$27*(1+$A8)^1 | E8: =Base!$C$27*(1+$A8)^2 | F8: =Base!$C$27*(1+$A8)^3 | G8: =Base!$C$27*(1+$A8)^4 | H8: =Base!$C$27*(1+$A8)^5 | I8: =Base!$C$27*(1+$A8)^6 | J8: =Base!$C$27*(1+$A8)^7 | K8: =Base!$C$27*(1+$A8)^8 | L8: =Base!$C$27*(1+$A8)^9
A9: -0.45 | B9: =(SUMPRODUCT(C9:L9,Base!$C$30:$L$30,Base!$C$31:$L$31)+L9*(1+g_base)/(wacc_base-g_base)*(1+wacc_base)^(-(fraccion+10-1))+ajuste_puente)/acciones_valor_base | C9: =Base!$C$27*(1+$A9)^0 | D9: =Base!$C$27*(1+$A9)^1 | E9: =Base!$C$27*(1+$A9)^2 | F9: =Base!$C$27*(1+$A9)^3 | G9: =Base!$C$27*(1+$A9)^4 | H9: =Base!$C$27*(1+$A9)^5 | I9: =Base!$C$27*(1+$A9)^6 | J9: =Base!$C$27*(1+$A9)^7 | K9: =Base!$C$27*(1+$A9)^8 | L9: =Base!$C$27*(1+$A9)^9
A10: -0.44 | B10: =(SUMPRODUCT(C10:L10,Base!$C$30:$L$30,Base!$C$31:$L$31)+L10*(1+g_base)/(wacc_base-g_base)*(1+wacc_base)^(-(fraccion+10-1))+ajuste_puente)/acciones_valor_base | C10: =Base!$C$27*(1+$A10)^0 | D10: =Base!$C$27*(1+$A10)^1 | E10: =Base!$C$27*(1+$A10)^2 | F10: =Base!$C$27*(1+$A10)^3 | G10: =Base!$C$27*(1+$A10)^4 | H10: =Base!$C$27*(1+$A10)^5 | I10: =Base!$C$27*(1+$A10)^6 | J10: =Base!$C$27*(1+$A10)^7 | K10: =Base!$C$27*(1+$A10)^8 | L10: =Base!$C$27*(1+$A10)^9
A11: -0.43 | B11: =(SUMPRODUCT(C11:L11,Base!$C$30:$L$30,Base!$C$31:$L$31)+L11*(1+g_base)/(wacc_base-g_base)*(1+wacc_base)^(-(fraccion+10-1))+ajuste_puente)/acciones_valor_base | C11: =Base!$C$27*(1+$A11)^0 | D11: =Base!$C$27*(1+$A11)^1 | E11: =Base!$C$27*(1+$A11)^2 | F11: =Base!$C$27*(1+$A11)^3 | G11: =Base!$C$27*(1+$A11)^4 | H11: =Base!$C$27*(1+$A11)^5 | I11: =Base!$C$27*(1+$A11)^6 | J11: =Base!$C$27*(1+$A11)^7 | K11: =Base!$C$27*(1+$A11)^8 | L11: =Base!$C$27*(1+$A11)^9
A12: -0.42 | B12: =(SUMPRODUCT(C12:L12,Base!$C$30:$L$30,Base!$C$31:$L$31)+L12*(1+g_base)/(wacc_base-g_base)*(1+wacc_base)^(-(fraccion+10-1))+ajuste_puente)/acciones_valor_base | C12: =Base!$C$27*(1+$A12)^0 | D12: =Base!$C$27*(1+$A12)^1 | E12: =Base!$C$27*(1+$A12)^2 | F12: =Base!$C$27*(1+$A12)^3 | G12: =Base!$C$27*(1+$A12)^4 | H12: =Base!$C$27*(1+$A12)^5 | I12: =Base!$C$27*(1+$A12)^6 | J12: =Base!$C$27*(1+$A12)^7 | K12: =Base!$C$27*(1+$A12)^8 | L12: =Base!$C$27*(1+$A12)^9
A13: -0.41 | B13: =(SUMPRODUCT(C13:L13,Base!$C$30:$L$30,Base!$C$31:$L$31)+L13*(1+g_base)/(wacc_base-g_base)*(1+wacc_base)^(-(fraccion+10-1))+ajuste_puente)/acciones_valor_base | C13: =Base!$C$27*(1+$A13)^0 | D13: =Base!$C$27*(1+$A13)^1 | E13: =Base!$C$27*(1+$A13)^2 | F13: =Base!$C$27*(1+$A13)^3 | G13: =Base!$C$27*(1+$A13)^4 | H13: =Base!$C$27*(1+$A13)^5 | I13: =Base!$C$27*(1+$A13)^6 | J13: =Base!$C$27*(1+$A13)^7 | K13: =Base!$C$27*(1+$A13)^8 | L13: =Base!$C$27*(1+$A13)^9
A14: -0.4 | B14: =(SUMPRODUCT(C14:L14,Base!$C$30:$L$30,Base!$C$31:$L$31)+L14*(1+g_base)/(wacc_base-g_base)*(1+wacc_base)^(-(fraccion+10-1))+ajuste_puente)/acciones_valor_base | C14: =Base!$C$27*(1+$A14)^0 | D14: =Base!$C$27*(1+$A14)^1 | E14: =Base!$C$27*(1+$A14)^2 | F14: =Base!$C$27*(1+$A14)^3 | G14: =Base!$C$27*(1+$A14)^4 | H14: =Base!$C$27*(1+$A14)^5 | I14: =Base!$C$27*(1+$A14)^6 | J14: =Base!$C$27*(1+$A14)^7 | K14: =Base!$C$27*(1+$A14)^8 | L14: =Base!$C$27*(1+$A14)^9
A15: -0.39 | B15: =(SUMPRODUCT(C15:L15,Base!$C$30:$L$30,Base!$C$31:$L$31)+L15*(1+g_base)/(wacc_base-g_base)*(1+wacc_base)^(-(fraccion+10-1))+ajuste_puente)/acciones_valor_base | C15: =Base!$C$27*(1+$A15)^0 | D15: =Base!$C$27*(1+$A15)^1 | E15: =Base!$C$27*(1+$A15)^2 | F15: =Base!$C$27*(1+$A15)^3 | G15: =Base!$C$27*(1+$A15)^4 | H15: =Base!$C$27*(1+$A15)^5 | I15: =Base!$C$27*(1+$A15)^6 | J15: =Base!$C$27*(1+$A15)^7 | K15: =Base!$C$27*(1+$A15)^8 | L15: =Base!$C$27*(1+$A15)^9
... A154: 1 | B154: =(SUMPRODUCT(C154:L154,Base!$C$30:$L$30,Base!$C$31:$L$31)+L154*(1+g_base)/(wacc_base-g_base)*(1+wacc_base)^(-(fraccion+10-1))+ajuste_puente)/acciones_valor_base | C154: =Base!$C$27*(1+$A154)^0 | D154: =Base!$C$27*(1+$A154)^1 | E154: =Base!$C$27*(1+$A154)^2 | F154: =Base!$C$27*(1+$A154)^3 | G154: =Base!$C$27*(1+$A154)^4 | H154: =Base!$C$27*(1+$A154)^5 | I154: =Base!$C$27*(1+$A154)^6 | J154: =Base!$C$27*(1+$A154)^7 | K154: =Base!$C$27*(1+$A154)^8 | L154: =Base!$C$27*(1+$A154)^9
