Workbook

Sheet 00 Panel del Analista
A1: PANEL DEL ANALISTA — TODOS LOS INPUTS DEL MODELO EN UN SOLO SITIO
A2: Rellena las celdas AZULES sobre fondo blanco y las AMARILLAS (hipótesis críticas). El resto del libro se recalcula solo. Para valorar OTRA compañía: sustituye la identificación, los tres estados históricos y los drivers; no hace falta tocar ninguna otra hoja.
A3: Las filas marcadas «calculado» no se rellenan: son totales que el libro deriva. Al terminar, comprueba el semáforo del final de esta hoja y la hoja '13 Checks'.
B5: Input | C5: Unidad | D5: Hist. −2 | E5: Hist. −1 | F5: Hist. base | G5: Año 1 | H5: Año 2 | I5: Año 3 | J5: Año 4 | K5: Año 5 | L5: Año 6 | M5: Año 7 | N5: Año 8 | O5: Año 9 | P5: Año 10
B7: 1. IDENTIFICACIÓN Y MERCADO
B8: Compañía | C8: Oracle Corporation
B9: Ticker y mercado | C9: ORCL — NYSE
B10: Moneda y unidades | C10: USD millones
B11: Fecha de valoración | C11: 22/09/2026
B12: Último ejercicio auditado | C12: FY2026A (cerrado 31/05/2026)
B13: PRECIO DE MERCADO ACTUAL (el único dato que el libro no puede deducir) | C13: 0
B14: Etiquetas de los ejercicios (se propagan a las cabeceras de todas las hojas) | C14: texto | D14: FY2024A | E14: FY2025A | F14: FY2026A | G14: FY2027E | H14: FY2028E | I14: FY2029E | J14: FY2030E | K14: FY2031E | L14: FY2032E | M14: FY2033E | N14: FY2034E | O14: FY2035E | P14: FY2036E
B16: 2. CUENTA DE RESULTADOS HISTÓRICA
B18: Cloud | C18: $M | D18: 19774 | E18: 24506 | F18: 33989
B19: Software (licencias y soporte) | C19: $M | D19: 24690 | E19: 24724 | F19: 24541
B20: Hardware | C20: $M | D20: 3066 | E20: 2936 | F20: 3084
B21: Servicios | C21: $M | D21: 5431 | E21: 5233 | F21: 5743
B22: Ingresos totales | C22: $M | D22: calculado
B24: Coste de cloud y software | C24: $M | D24: 9427 | E24: 11569 | F24: 17597
B25: Coste de hardware | C25: $M | D25: 891 | E25: 782 | F25: 868
B26: Coste de servicios | C26: $M | D26: 4825 | E26: 4576 | F26: 4556
B27: Coste total de los ingresos | C27: $M | D27: calculado
B28: Margen bruto (Gross Profit) | C28: $M | D28: calculado
B29: Gross Margin | C29: % | D29: calculado
B31: Ventas y marketing | C31: $M | D31: 8274 | E31: 8651 | F31: 8331
B32: Investigación y desarrollo | C32: $M | D32: 8915 | E32: 9860 | F32: 10272
B33: Generales y administración | C33: $M | D33: 1548 | E33: 1602 | F33: 1618
B34: Amortización de intangibles | C34: $M | D34: 3010 | E34: 2307 | F34: 1671
B35: Reestructuración y otros | C35: $M | D35: 718 | E35: 374 | F35: 1838
B36: Gastos operativos totales | C36: $M | D36: calculado
B37: EBIT (resultado operativo) reportado | C37: $M | D37: calculado
B38: EBIT Margin reportado | C38: % | D38: calculado
B40: Gasto por intereses | C40: $M | D40: 3514 | E40: 3578 | F40: 4599
B41: Resultado no operativo, neto | C41: $M | D41: -98 | E41: 60 | F41: 3547
B42: Beneficio antes de impuestos | C42: $M | D42: calculado
B43: Impuesto sobre sociedades | C43: $M | D43: 1274 | E43: 1717 | F43: 2467
B44: Tipo impositivo efectivo | C44: % | D44: calculado
B45: Beneficio neto | C45: $M | D45: calculado
B46: Dividendos de acciones preferentes | C46: $M | D46: 0 | E46: 0 | F46: 103
B47: Beneficio neto atribuible a ordinarias | C47: $M | D47: calculado
...

Sheet 01 Summary
A1: ORACLE CORPORATION (ORCL) — RESUMEN DE VALORACIÓN DCF
A2: Valoración condicional: el resultado depende íntegramente de las hipótesis explícitas de '02 Assumptions'. No es una predicción.
B3: ⚠ PULSA Ctrl+Alt+F9 AL ABRIR ESTE LIBRO. Estas zonas se escribieron con el motor de cálculo del complemento bloqueado y mostrarán CEROS hasta que se fuerce un recálculo completo: (1) hojas 09a/09b/09c de escenarios; (2) las 25 celdas de las rejillas de '08 Sensibilidad' D6:H46; (3) en esta hoja, la tabla de escenarios F16:H24, el bloque de Múltiplos y el bloque de Precio objetivo; (4) en '13 Checks', los contadores D5:D7 y los controles 70-78. Las fórmulas están escritas y verificadas sintácticamente; lo que falta es que Excel las evalúe. TRAS EL RECÁLCULO comprueba el control 73 de '13 Checks': si está en OK, la réplica del escenario Base coincide con el DCF y los tres escenarios son fiables.
B4: IDENTIFICACIÓN | E4: CÓMO USAR ESTE LIBRO
B5: Compañía | C5: ='00 Panel del Analista'!C8 -> 0 | E5: 1 | F5: Introducir el precio de mercado actual en C10. Es el ÚNICO dato que el libro no puede obtener por sí mismo. Hasta entonces el upside, el margen de seguridad y el Reverse DCF quedan en blanco por diseño.
B6: Ticker / mercado | C6: ='00 Panel del Analista'!C9 -> 0 | E6: 2 | F6: Actualizar y documentar los inputs de mercado del WACC en '07 WACC': tipo libre de riesgo, prima de riesgo, beta y coste marginal de la deuda. Los valores actuales son inputs del analista, NO datos verificados.
B7: Moneda y unidades | C7: ='00 Panel del Analista'!C10 -> 0 | E7: 3 | F7: Revisar las hipótesis en '02 Assumptions'. Las celdas amarillas son las que mueven el valor. Ninguna otra hoja contiene hipótesis.
B8: Fecha de valoración | C8: ='00 Panel del Analista'!C11 -> 0 | E8: 4 | F8: Cambiar el escenario en '09 Scenarios'!C4 (1=Bear, 2=Base, 3=Bull) y anotar los tres valores para construir el rango.
B9: Último ejercicio auditado | C9: ='00 Panel del Analista'!C12 -> 0 | E9: 5 | F9: Leer '08 Sensitivity' para ver qué variables explican el valor, y '10 Reverse DCF' para ver qué descuenta el precio.
B10: PRECIO DE MERCADO ACTUAL — INTRODUCIR AQUÍ | C10: ='00 Panel del Analista'!C13 -> 0 | E10: 6 | F10: Ejecutar la auditoría de '13 Checks' ANTES de usar cualquier resultado. Si algún control falla, el número no es utilizable.
E11: 7 | F11: Leer '11 Cross Check': un DCF aislado no es una conclusión. Y leer 'M4 Manual Errores' antes de defender el modelo ante otro analista.
B12: RESULTADO DE LA VALORACIÓN | E12: Si esta tabla o el bloque de Precio objetivo muestran ceros: Ctrl+Alt+F9.
B13: Escenario activo | C13: ='09 Escenarios'!C5 -> BASE | E13: LOS TRES ESCENARIOS, CALCULADOS SIMULTÁNEAMENTE
B14: Enterprise Value | C14: ='06 DCF'!F44 -> 608375.19 | E14: Ya NO es una instantánea: cada columna se calcula en su propia hoja ('09a', '09b', '09c'), independiente del interruptor de '09 Escenarios'!C4. Los deltas de cada escenario están en la matriz de '09 Escenarios' filas 9-17.
B15: (−) Deuda neta y otras reclamaciones | C15: ='06 DCF'!F53-'06 DCF'!F44 -> -111860.35 | E15: Métrica | F15: PESIMISTA | G15: BASE | H15: OPTIMISTA | I15: Unidad
B16: Equity Value | C16: ='06 DCF'!F53 -> 496514.84 | E16: Enterprise Value | F16: ='Escenario Pesimista'!$F$66 -> 0 | G16: ='Escenario Base'!$F$66 -> 0 | H16: ='Escenario Optimista'!$F$66 -> 0 | I16: $M
B17: Acciones diluidas | C17: ='06 DCF'!F54 -> 2934 | E17: Equity Value | F17: ='Escenario Pesimista'!$F$70 -> 0 | G17: ='Escenario Base'!$F$70 -> 0 | H17: ='Escenario Optimista'!$F$70 -> 0 | I17: $M
B18: VALOR INTRÍNSECO POR ACCIÓN | C18: ='06 DCF'!F55 -> 169.22796 | E18: Valor intrínseco por acción | F18: ='Escenario Pesimista'!$F$72 -> 0 | G18: ='Escenario Base'!$F$72 -> 0 | H18: ='Escenario Optimista'!$F$72 -> 0 | I18: $/acc
B19: Upside / (Downside) sobre el precio actual | C19: =IF($C$10<=0,"◄ introducir el precio en C10",'06 DCF'!F57) -> ◄ introducir el precio en C10 | E19: WACC | F19: ='Escenario Pesimista'!$P$52 -> 0 | G19: ='Escenario Base'!$P$52 -> 0 | H19: ='Escenario Optimista'!$P$52 -> 0 | I19: %
B20: Margen de seguridad implícito | C20: =IF($C$10<=0,"◄ introducir el precio en C10",'06 DCF'!F58) -> ◄ introducir el precio en C10 | E20: Crecimiento terminal g | F20: ='Escenario Pesimista'!$P$53 -> 0 | G20: ='Escenario Base'!$P$53 -> 0 | H20: ='Escenario Optimista'!$P$53 -> 0 | I20: %
E21: Valor terminal / EV | F21: ='Escenario Pesimista'!$F$67 -> 0 | G21: ='Escenario Base'!$F$67 -> 0 | H21: ='Escenario Optimista'!$F$67 -> 0 | I21: %
B22: RANGO DE VALORACIÓN POR ESCENARIO | E22: Múltiplo de salida implícito | F22: ='Escenario Pesimista'!$F$68 -> 0 | G22: ='Escenario Base'!$F$68 -> 0 | H22: ='Escenario Optimista'!$F$68 -> 0 | I22: x
B23: Nota | C23: Ver la instantánea de los tres escenarios en E13:I21 → | E23: Ingresos FY2036E | F23: ='Escenario Pesimista'!$F$75 -> 0 | G23: ='Escenario Base'!$F$75 -> 0 | H23: ='Escenario Optimista'!$F$75 -> 0 | I23: $M
E24: Upside / (Downside) | F24: ='Escenario Pesimista'!$F$74 -> 0 | G24: ='Escenario Base'!$F$74 -> 0 | H24: ='Escenario Optimista'!$F$74 -> 0 | I24: %
B25: PARÁMETROS CLAVE | E25: CHECK: el escenario Base debe reproducir '06 DCF' | G25: ='Escenario Base'!$F$82 -> 0
B26: WACC | C26: ='07 WACC'!C38 -> 0.087495 | E26: CHECK: ordenación Pesimista < Base < Optimista | G26: =IF(AND($F$18<$G$18,$G$18<$H$18),"OK","FALLO: los escenarios no están ordenados") -> 0
B27: Crecimiento terminal g | C27: ='06 DCF'!F26 -> 0.03
B28: ROIC terminal | C28: ='06 DCF'!F27 -> 0.24
B29: Margen WACC − g | C29: ='07 WACC'!C43 -> 0.057495
B30: Valor terminal / Enterprise Value | C30: ='06 DCF'!F45 -> 0.66008837
B31: Múltiplo de salida implícito (VT / EBITDA FY2036) | C31: ='06 DCF'!F62 -> 9.5110381
B32: EV / EBITDA FY2026A implícito | C32: ='06 DCF'!F71 -> 19.168668
B33: EV / Ingresos FY2026A implícito | C33: ='06 DCF'!F72 -> 9.0321005
B35: SITUACIÓN DE PARTIDA (FY2026A REPORTADO)
B36: Ingresos | C36: ='03 Historical'!F11 -> 67357
B37: Crecimiento de ingresos | C37: ='03 Historical'!F121 -> 0.17348734
B38: EBIT normalizado | C38: ='03 Historical'!F127 -> 22444
B39: Margen EBIT normalizado | C39: ='03 Historical'!F128 -> 0.33320961
B40: Capex | C40: ='03 Historical'!F129 -> 55663
B41: Capex / Ingresos | C41: ='03 Historical'!F130 -> 0.82638775
...

Sheet 02 Assumptions
A1: HIPÓTESIS CENTRALIZADAS — ORACLE CORPORATION (ORCL)
A2: AZUL = input del analista. NEGRO = fórmula. VERDE = enlace a otra hoja. GRIS = dato histórico reportado. AMARILLO = hipótesis crítica. Ninguna otra hoja debe contener hipótesis: todas viven aquí.
B4: Hipótesis | C4: Unidad | D4: ='00 Panel del Analista'!D14 -> 0 | E4: ='00 Panel del Analista'!E14 -> 0 | F4: ='00 Panel del Analista'!F14 -> 0 | G4: ='00 Panel del Analista'!G14 -> 0 | H4: ='00 Panel del Analista'!H14 -> 0 | I4: ='00 Panel del Analista'!I14 -> 0 | J4: ='00 Panel del Analista'!J14 -> 0 | K4: ='00 Panel del Analista'!K14 -> 0 | ... P4: ='00 Panel del Analista'!P14 -> 0 | Q4: Peso del delta de escenario
B6: PANEL DE CONTROL
B7: Escenario activo (1=Bear, 2=Base, 3=Bull) | C7: ='09 Escenarios'!C4 -> 2
B8: Nombre del escenario activo | C8: ='09 Escenarios'!C5 -> BASE
B9: Fecha de valoración | C9: ='00 Panel del Analista'!C11 -> 0
B10: Moneda y unidades | C10: ='00 Panel del Analista'!C10 -> 0
B11: Años de forecast explícito | C11: ='00 Panel del Analista'!D186 -> 0
B12: Convención de descuento (1=fin de año, 2=mitad de año) | C12: ='00 Panel del Analista'!D187 -> 0
B13: Método de valor terminal (1=Gordon, 2=Múltiplo de salida) | C13: ='00 Panel del Analista'!D188 -> 0
B14: Tratamiento de leases operativos | C14: OPERATIVO — coste en EBIT, pasivo fuera de la deuda neta
B15: Tratamiento del SBC | C15: GASTO REAL — no se readiciona, no se aplica dilución adicional
B16: Año base del forecast | C16: ='00 Panel del Analista'!C12 -> 0
B18: INGRESOS — CRECIMIENTO POR SEGMENTO (driver: conversión del RPO de 638.000 en ingresos)
B19: Cloud — crecimiento (vector Base) | C19: % | G19: ='00 Panel del Analista'!G165 -> 0 | H19: ='00 Panel del Analista'!H165 -> 0 | I19: ='00 Panel del Analista'!I165 -> 0 | J19: ='00 Panel del Analista'!J165 -> 0 | K19: ='00 Panel del Analista'!K165 -> 0 | L19: ='00 Panel del Analista'!L165 -> 0 | M19: ='00 Panel del Analista'!M165 -> 0 | N19: ='00 Panel del Analista'!N165 -> 0 | ... P19: ='00 Panel del Analista'!P165 -> 0
B20: Cloud — crecimiento ACTIVO (Base × multiplicador de escenario) | C20: % | G20: =G19*'09 Escenarios'!$G$9+$C$104 -> 0.5 | H20: =H19*'09 Escenarios'!$G$9+$C$104 -> 0.38 | I20: =I19*'09 Escenarios'!$G$9+$C$104 -> 0.28 | J20: =J19*'09 Escenarios'!$G$9+$C$104 -> 0.21 | K20: =K19*'09 Escenarios'!$G$9+$C$104 -> 0.16 | L20: =L19*'09 Escenarios'!$G$9+$C$104 -> 0.12 | M20: =M19*'09 Escenarios'!$G$9+$C$104 -> 0.09 | N20: =N19*'09 Escenarios'!$G$9+$C$104 -> 0.07 | ... P20: =P19*'09 Escenarios'!$G$9+$C$104 -> 0.04
B21: Software — crecimiento (vector Base) | C21: % | G21: ='00 Panel del Analista'!G166 -> 0 | H21: ='00 Panel del Analista'!H166 -> 0 | I21: ='00 Panel del Analista'!I166 -> 0 | J21: ='00 Panel del Analista'!J166 -> 0 | K21: ='00 Panel del Analista'!K166 -> 0 | L21: ='00 Panel del Analista'!L166 -> 0 | M21: ='00 Panel del Analista'!M166 -> 0 | N21: ='00 Panel del Analista'!N166 -> 0 | ... P21: ='00 Panel del Analista'!P166 -> 0
B22: Software — crecimiento ACTIVO | C22: % | G22: =G21+'09 Escenarios'!$G$10+$C$104 -> 0 | H22: =H21+'09 Escenarios'!$G$10+$C$104 -> -0.01 | I22: =I21+'09 Escenarios'!$G$10+$C$104 -> -0.01 | J22: =J21+'09 Escenarios'!$G$10+$C$104 -> 0 | K22: =K21+'09 Escenarios'!$G$10+$C$104 -> 0 | L22: =L21+'09 Escenarios'!$G$10+$C$104 -> 0.01 | M22: =M21+'09 Escenarios'!$G$10+$C$104 -> 0.01 | N22: =N21+'09 Escenarios'!$G$10+$C$104 -> 0.01 | ... P22: =P21+'09 Escenarios'!$G$10+$C$104 -> 0.01
B23: Hardware — crecimiento (vector Base) | C23: % | G23: ='00 Panel del Analista'!G167 -> 0 | H23: ='00 Panel del Analista'!H167 -> 0 | I23: ='00 Panel del Analista'!I167 -> 0 | J23: ='00 Panel del Analista'!J167 -> 0 | K23: ='00 Panel del Analista'!K167 -> 0 | L23: ='00 Panel del Analista'!L167 -> 0 | M23: ='00 Panel del Analista'!M167 -> 0 | N23: ='00 Panel del Analista'!N167 -> 0 | ... P23: ='00 Panel del Analista'!P167 -> 0
B24: Hardware — crecimiento ACTIVO | C24: % | G24: =G23+'09 Escenarios'!$G$10+$C$104 -> -0.02 | H24: =H23+'09 Escenarios'!$G$10+$C$104 -> -0.02 | I24: =I23+'09 Escenarios'!$G$10+$C$104 -> -0.01 | J24: =J23+'09 Escenarios'!$G$10+$C$104 -> -0.01 | K24: =K23+'09 Escenarios'!$G$10+$C$104 -> 0 | L24: =L23+'09 Escenarios'!$G$10+$C$104 -> 0 | M24: =M23+'09 Escenarios'!$G$10+$C$104 -> 0 | N24: =N23+'09 Escenarios'!$G$10+$C$104 -> 0 | ... P24: =P23+'09 Escenarios'!$G$10+$C$104 -> 0
B25: Servicios — crecimiento (vector Base) | C25: % | G25: ='00 Panel del Analista'!G168 -> 0 | H25: ='00 Panel del Analista'!H168 -> 0 | I25: ='00 Panel del Analista'!I168 -> 0 | J25: ='00 Panel del Analista'!J168 -> 0 | K25: ='00 Panel del Analista'!K168 -> 0 | L25: ='00 Panel del Analista'!L168 -> 0 | M25: ='00 Panel del Analista'!M168 -> 0 | N25: ='00 Panel del Analista'!N168 -> 0 | ... P25: ='00 Panel del Analista'!P168 -> 0
B26: Servicios — crecimiento ACTIVO | C26: % | G26: =G25+'09 Escenarios'!$G$10+$C$104 -> 0.08 | H26: =H25+'09 Escenarios'!$G$10+$C$104 -> 0.07 | I26: =I25+'09 Escenarios'!$G$10+$C$104 -> 0.06 | J26: =J25+'09 Escenarios'!$G$10+$C$104 -> 0.05 | K26: =K25+'09 Escenarios'!$G$10+$C$104 -> 0.04 | L26: =L25+'09 Escenarios'!$G$10+$C$104 -> 0.03 | M26: =M25+'09 Escenarios'!$G$10+$C$104 -> 0.03 | N26: =N25+'09 Escenarios'!$G$10+$C$104 -> 0.03 | ... P26: =P25+'09 Escenarios'!$G$10+$C$104 -> 0.03
B28: MÁRGENES Y ESTRUCTURA DE COSTES
B29: Gross Margin (vector Base) | C29: % | G29: ='00 Panel del Analista'!G169 -> 0 | H29: ='00 Panel del Analista'!H169 -> 0 | I29: ='00 Panel del Analista'!I169 -> 0 | J29: ='00 Panel del Analista'!J169 -> 0 | K29: ='00 Panel del Analista'!K169 -> 0 | L29: ='00 Panel del Analista'!L169 -> 0 | M29: ='00 Panel del Analista'!M169 -> 0 | N29: ='00 Panel del Analista'!N169 -> 0 | ... P29: ='00 Panel del Analista'!P169 -> 0
B30: Gross Margin ACTIVO | C30: % | G30: =G29+'09 Escenarios'!$G$11 -> 0.61 | H30: =H29+'09 Escenarios'!$G$11 -> 0.58 | I30: =I29+'09 Escenarios'!$G$11 -> 0.565 | J30: =J29+'09 Escenarios'!$G$11 -> 0.56 | K30: =K29+'09 Escenarios'!$G$11 -> 0.56 | L30: =L29+'09 Escenarios'!$G$11 -> 0.565 | M30: =M29+'09 Escenarios'!$G$11 -> 0.57 | N30: =N29+'09 Escenarios'!$G$11 -> 0.575 | ... P30: =P29+'09 Escenarios'!$G$11 -> 0.58
B31: Ventas y marketing / Ingresos (Base) | C31: % | G31: ='00 Panel del Analista'!G170 -> 0 | H31: ='00 Panel del Analista'!H170 -> 0 | I31: ='00 Panel del Analista'!I170 -> 0 | J31: ='00 Panel del Analista'!J170 -> 0 | K31: ='00 Panel del Analista'!K170 -> 0 | L31: ='00 Panel del Analista'!L170 -> 0 | M31: ='00 Panel del Analista'!M170 -> 0 | N31: ='00 Panel del Analista'!N170 -> 0 | ... P31: ='00 Panel del Analista'!P170 -> 0
B32: Ventas y marketing / Ingresos ACTIVO | C32: % | G32: =G31+'09 Escenarios'!$G$12*$Q$32 -> 0.12 | H32: =H31+'09 Escenarios'!$G$12*$Q$32 -> 0.113 | I32: =I31+'09 Escenarios'!$G$12*$Q$32 -> 0.108 | J32: =J31+'09 Escenarios'!$G$12*$Q$32 -> 0.104 | K32: =K31+'09 Escenarios'!$G$12*$Q$32 -> 0.101 | L32: =L31+'09 Escenarios'!$G$12*$Q$32 -> 0.099 | M32: =M31+'09 Escenarios'!$G$12*$Q$32 -> 0.098 | N32: =N31+'09 Escenarios'!$G$12*$Q$32 -> 0.097 | ... P32: =P31+'09 Escenarios'!$G$12*$Q$32 -> 0.097 | Q32: ='00 Panel del Analista'!D202 -> 0
B33: I+D / Ingresos (Base) | C33: % | G33: ='00 Panel del Analista'!G171 -> 0 | H33: ='00 Panel del Analista'!H171 -> 0 | I33: ='00 Panel del Analista'!I171 -> 0 | J33: ='00 Panel del Analista'!J171 -> 0 | K33: ='00 Panel del Analista'!K171 -> 0 | L33: ='00 Panel del Analista'!L171 -> 0 | M33: ='00 Panel del Analista'!M171 -> 0 | N33: ='00 Panel del Analista'!N171 -> 0 | ... P33: ='00 Panel del Analista'!P171 -> 0
B34: I+D / Ingresos ACTIVO | C34: % | G34: =G33+'09 Escenarios'!$G$12*$Q$34 -> 0.145 | H34: =H33+'09 Escenarios'!$G$12*$Q$34 -> 0.14 | I34: =I33+'09 Escenarios'!$G$12*$Q$34 -> 0.136 | J34: =J33+'09 Escenarios'!$G$12*$Q$34 -> 0.133 | K34: =K33+'09 Escenarios'!$G$12*$Q$34 -> 0.131 | L34: =L33+'09 Escenarios'!$G$12*$Q$34 -> 0.13 | M34: =M33+'09 Escenarios'!$G$12*$Q$34 -> 0.129 | N34: =N33+'09 Escenarios'!$G$12*$Q$34 -> 0.128 | ... P34: =P33+'09 Escenarios'!$G$12*$Q$34 -> 0.128 | Q34: ='00 Panel del Analista'!D203 -> 0
B35: G&A / Ingresos (Base) | C35: % | G35: ='00 Panel del Analista'!G172 -> 0 | H35: ='00 Panel del Analista'!H172 -> 0 | I35: ='00 Panel del Analista'!I172 -> 0 | J35: ='00 Panel del Analista'!J172 -> 0 | K35: ='00 Panel del Analista'!K172 -> 0 | L35: ='00 Panel del Analista'!L172 -> 0 | M35: ='00 Panel del Analista'!M172 -> 0 | N35: ='00 Panel del Analista'!N172 -> 0 | ... P35: ='00 Panel del Analista'!P172 -> 0
B36: G&A / Ingresos ACTIVO | C36: % | G36: =G35+'09 Escenarios'!$G$12*$Q$36 -> 0.022 | H36: =H35+'09 Escenarios'!$G$12*$Q$36 -> 0.021 | I36: =I35+'09 Escenarios'!$G$12*$Q$36 -> 0.02 | J36: =J35+'09 Escenarios'!$G$12*$Q$36 -> 0.019 | K36: =K35+'09 Escenarios'!$G$12*$Q$36 -> 0.019 | L36: =L35+'09 Escenarios'!$G$12*$Q$36 -> 0.018 | M36: =M35+'09 Escenarios'!$G$12*$Q$36 -> 0.018 | N36: =N35+'09 Escenarios'!$G$12*$Q$36 -> 0.018 | ... P36: =P35+'09 Escenarios'!$G$12*$Q$36 -> 0.018 | Q36: ='00 Panel del Analista'!D204 -> 0
B37: Amortización de intangibles adquiridos (calendario) | C37: $M | G37: ='00 Panel del Analista'!G173 -> 0 | H37: ='00 Panel del Analista'!H173 -> 0 | I37: ='00 Panel del Analista'!I173 -> 0 | J37: ='00 Panel del Analista'!J173 -> 0 | K37: ='00 Panel del Analista'!K173 -> 0 | L37: ='00 Panel del Analista'!L173 -> 0 | M37: ='00 Panel del Analista'!M173 -> 0 | N37: ='00 Panel del Analista'!N173 -> 0 | ... P37: ='00 Panel del Analista'!P173 -> 0
B38: Reestructuración normalizada | C38: $M | G38: ='00 Panel del Analista'!G174 -> 0 | H38: ='00 Panel del Analista'!H174 -> 0 | I38: ='00 Panel del Analista'!I174 -> 0 | J38: ='00 Panel del Analista'!J174 -> 0 | K38: ='00 Panel del Analista'!K174 -> 0 | L38: ='00 Panel del Analista'!L174 -> 0 | M38: ='00 Panel del Analista'!M174 -> 0 | N38: ='00 Panel del Analista'!N174 -> 0 | ... P38: ='00 Panel del Analista'!P174 -> 0
B40: CAPEX Y DEPRECIACIÓN
B41: Capex / Ingresos (vector Base) | C41: % | G41: ='00 Panel del Analista'!G175 -> 0 | H41: ='00 Panel del Analista'!H175 -> 0 | I41: ='00 Panel del Analista'!I175 -> 0 | J41: ='00 Panel del Analista'!J175 -> 0 | K41: ='00 Panel del Analista'!K175 -> 0 | L41: ='00 Panel del Analista'!L175 -> 0 | M41: ='00 Panel del Analista'!M175 -> 0 | N41: ='00 Panel del Analista'!N175 -> 0 | ... P41: ='00 Panel del Analista'!P175 -> 0
B42: Capex / Ingresos ACTIVO | C42: % | G42: =G41*'09 Escenarios'!$G$13 -> 0.6 | H42: =H41*'09 Escenarios'!$G$13 -> 0.4 | I42: =I41*'09 Escenarios'!$G$13 -> 0.28 | J42: =J41*'09 Escenarios'!$G$13 -> 0.21 | K42: =K41*'09 Escenarios'!$G$13 -> 0.16 | L42: =L41*'09 Escenarios'!$G$13 -> 0.14 | M42: =M41*'09 Escenarios'!$G$13 -> 0.13 | N42: =N41*'09 Escenarios'!$G$13 -> 0.125 | ... P42: =P41*'09 Escenarios'!$G$13 -> 0.118
B43: Vida útil media del PP&E | C43: ='00 Panel del Analista'!D189 -> 0
B44: Vida útil implícita en FY2026 (check de calibración) | C44: años | F44: =('03 Historical'!E48+'03 Historical'!F129/2)/'03 Historical'!F79 -> 9.3602912
B46: CIRCULANTE OPERATIVO (drivers, no % de ingresos genérico)
...

Sheet 03 Historical
A1: ESTADOS FINANCIEROS HISTÓRICOS — ORACLE CORPORATION (ORCL)
A2: USD millones salvo indicación. Ejercicio fiscal cerrado el 31 de mayo. Fuente: Form 10-K FY2026 (SEC). Datos reportados sin ajustar.
B4: Partida | C4: Unidad | D4: ='00 Panel del Analista'!D14 -> 0 | E4: ='00 Panel del Analista'!E14 -> 0 | F4: ='00 Panel del Analista'!F14 -> 0 | G4: ='00 Panel del Analista'!G14 -> 0 | H4: ='00 Panel del Analista'!H14 -> 0 | I4: ='00 Panel del Analista'!I14 -> 0 | J4: ='00 Panel del Analista'!J14 -> 0 | K4: ='00 Panel del Analista'!K14 -> 0 | ... P4: ='00 Panel del Analista'!P14 -> 0
B6: CUENTA DE RESULTADOS
B7: Cloud | C7: $M | D7: ='00 Panel del Analista'!D18 -> 0 | E7: ='00 Panel del Analista'!E18 -> 0 | F7: ='00 Panel del Analista'!F18 -> 0
B8: Software (licencias y soporte) | C8: $M | D8: ='00 Panel del Analista'!D19 -> 0 | E8: ='00 Panel del Analista'!E19 -> 0 | F8: ='00 Panel del Analista'!F19 -> 0
B9: Hardware | C9: $M | D9: ='00 Panel del Analista'!D20 -> 0 | E9: ='00 Panel del Analista'!E20 -> 0 | F9: ='00 Panel del Analista'!F20 -> 0
B10: Servicios | C10: $M | D10: ='00 Panel del Analista'!D21 -> 0 | E10: ='00 Panel del Analista'!E21 -> 0 | F10: ='00 Panel del Analista'!F21 -> 0
B11: Ingresos totales | C11: $M | D11: =SUM(D7:D10) -> 52961 | E11: =SUM(E7:E10) -> 57399 | F11: =SUM(F7:F10) -> 67357
B13: Coste de cloud y software | C13: $M | D13: ='00 Panel del Analista'!D24 -> 0 | E13: ='00 Panel del Analista'!E24 -> 0 | F13: ='00 Panel del Analista'!F24 -> 0
B14: Coste de hardware | C14: $M | D14: ='00 Panel del Analista'!D25 -> 0 | E14: ='00 Panel del Analista'!E25 -> 0 | F14: ='00 Panel del Analista'!F25 -> 0
B15: Coste de servicios | C15: $M | D15: ='00 Panel del Analista'!D26 -> 0 | E15: ='00 Panel del Analista'!E26 -> 0 | F15: ='00 Panel del Analista'!F26 -> 0
B16: Coste total de los ingresos | C16: $M | D16: =SUM(D13:D15) -> 15143 | E16: =SUM(E13:E15) -> 16927 | F16: =SUM(F13:F15) -> 23021
B17: Margen bruto (Gross Profit) | C17: $M | D17: =D11-D16 -> 37818 | E17: =E11-E16 -> 40472 | F17: =F11-F16 -> 44336
B18: Gross Margin | C18: % | D18: =D17/D11 -> 0.71407262 | E18: =E17/E11 -> 0.70509939 | F18: =F17/F11 -> 0.65822409
B20: Ventas y marketing | C20: $M | D20: ='00 Panel del Analista'!D31 -> 0 | E20: ='00 Panel del Analista'!E31 -> 0 | F20: ='00 Panel del Analista'!F31 -> 0
B21: Investigación y desarrollo | C21: $M | D21: ='00 Panel del Analista'!D32 -> 0 | E21: ='00 Panel del Analista'!E32 -> 0 | F21: ='00 Panel del Analista'!F32 -> 0
B22: Generales y administración | C22: $M | D22: ='00 Panel del Analista'!D33 -> 0 | E22: ='00 Panel del Analista'!E33 -> 0 | F22: ='00 Panel del Analista'!F33 -> 0
B23: Amortización de intangibles | C23: $M | D23: ='00 Panel del Analista'!D34 -> 0 | E23: ='00 Panel del Analista'!E34 -> 0 | F23: ='00 Panel del Analista'!F34 -> 0
B24: Reestructuración y otros | C24: $M | D24: ='00 Panel del Analista'!D35 -> 0 | E24: ='00 Panel del Analista'!E35 -> 0 | F24: ='00 Panel del Analista'!F35 -> 0
B25: Gastos operativos totales | C25: $M | D25: =D16+SUM(D20:D24) -> 37608 | E25: =E16+SUM(E20:E24) -> 39721 | F25: =F16+SUM(F20:F24) -> 46751
B26: EBIT (resultado operativo) reportado | C26: $M | D26: =D11-D25 -> 15353 | E26: =E11-E25 -> 17678 | F26: =F11-F25 -> 20606
B27: EBIT Margin reportado | C27: % | D27: =D26/D11 -> 0.28989256 | E27: =E26/E11 -> 0.30798446 | F27: =F26/F11 -> 0.30592218
B29: Gasto por intereses | C29: $M | D29: ='00 Panel del Analista'!D40 -> 0 | E29: ='00 Panel del Analista'!E40 -> 0 | F29: ='00 Panel del Analista'!F40 -> 0
B30: Resultado no operativo, neto | C30: $M | D30: ='00 Panel del Analista'!D41 -> 0 | E30: ='00 Panel del Analista'!E41 -> 0 | F30: ='00 Panel del Analista'!F41 -> 0
B31: Beneficio antes de impuestos | C31: $M | D31: =D26-D29+D30 -> 11741 | E31: =E26-E29+E30 -> 14160 | F31: =F26-F29+F30 -> 19554
B32: Impuesto sobre sociedades | C32: $M | D32: ='00 Panel del Analista'!D43 -> 0 | E32: ='00 Panel del Analista'!E43 -> 0 | F32: ='00 Panel del Analista'!F43 -> 0
B33: Tipo impositivo efectivo | C33: % | D33: =D32/D31 -> 0.10850864 | E33: =E32/E31 -> 0.12125706 | F33: =F32/F31 -> 0.12616344
B34: Beneficio neto | C34: $M | D34: =D31-D32 -> 10467 | E34: =E31-E32 -> 12443 | F34: =F31-F32 -> 17087
B35: Dividendos de acciones preferentes | C35: $M | D35: ='00 Panel del Analista'!D46 -> 0 | E35: ='00 Panel del Analista'!E46 -> 0 | F35: ='00 Panel del Analista'!F46 -> 0
B36: Beneficio neto atribuible a ordinarias | C36: $M | D36: =D34-D35 -> 10467 | E36: =E34-E35 -> 12443 | F36: =F34-F35 -> 16984
B37: BPA básico | C37: $/acc | D37: ='00 Panel del Analista'!D48 -> 0 | E37: ='00 Panel del Analista'!E48 -> 0 | F37: ='00 Panel del Analista'!F48 -> 0
B38: BPA diluido | C38: $/acc | D38: ='00 Panel del Analista'!D49 -> 0 | E38: ='00 Panel del Analista'!E49 -> 0 | F38: ='00 Panel del Analista'!F49 -> 0
B39: Acciones medias básicas | C39: M acc | D39: ='00 Panel del Analista'!D50 -> 0 | E39: ='00 Panel del Analista'!E50 -> 0 | F39: ='00 Panel del Analista'!F50 -> 0
B40: Acciones medias diluidas | C40: M acc | D40: ='00 Panel del Analista'!D51 -> 0 | E40: ='00 Panel del Analista'!E51 -> 0 | F40: ='00 Panel del Analista'!F51 -> 0
B42: BALANCE (a cierre de ejercicio)
B43: Caja y equivalentes | C43: $M | E43: ='00 Panel del Analista'!E54 -> 0 | F43: ='00 Panel del Analista'!F54 -> 0
B44: Valores negociables | C44: $M | E44: ='00 Panel del Analista'!E55 -> 0 | F44: ='00 Panel del Analista'!F55 -> 0
B45: Clientes, neto | C45: $M | E45: ='00 Panel del Analista'!E56 -> 0 | F45: ='00 Panel del Analista'!F56 -> 0
B46: Gastos anticipados y otros activos corrientes | C46: $M | E46: ='00 Panel del Analista'!E57 -> 0 | F46: ='00 Panel del Analista'!F57 -> 0
...

Sheet 04 Operating Model
A1: MODELO OPERATIVO FY2027E–FY2036E — ORACLE CORPORATION
A2: USD millones. Toda hipótesis procede de '02 Assumptions'. Esta hoja NO contiene hipótesis propias. Verde = enlace; negro = fórmula.
B4: Partida | C4: Unidad | D4: ='00 Panel del Analista'!D14 -> 0 | E4: ='00 Panel del Analista'!E14 -> 0 | F4: ='00 Panel del Analista'!F14 -> 0 | G4: ='00 Panel del Analista'!G14 -> 0 | H4: ='00 Panel del Analista'!H14 -> 0 | I4: ='00 Panel del Analista'!I14 -> 0 | J4: ='00 Panel del Analista'!J14 -> 0 | K4: ='00 Panel del Analista'!K14 -> 0 | ... P4: ='00 Panel del Analista'!P14 -> 0
B6: INGRESOS POR SEGMENTO
B7: Cloud | C7: $M | D7: ='03 Historical'!D7 -> 19774 | E7: ='03 Historical'!E7 -> 24506 | F7: ='03 Historical'!F7 -> 33989 | G7: =F7*(1+'02 Assumptions'!G20) -> 50983.5 | H7: =G7*(1+'02 Assumptions'!H20) -> 70357.23 | I7: =H7*(1+'02 Assumptions'!I20) -> 90057.254 | J7: =I7*(1+'02 Assumptions'!J20) -> 108969.28 | K7: =J7*(1+'02 Assumptions'!K20) -> 126404.36 | L7: =K7*(1+'02 Assumptions'!L20) -> 141572.89 | M7: =L7*(1+'02 Assumptions'!M20) -> 154314.45 | N7: =M7*(1+'02 Assumptions'!N20) -> 165116.46 | ... P7: =O7*(1+'02 Assumptions'!P20) -> 180307.17
B8: Software (licencias y soporte) | C8: $M | D8: ='03 Historical'!D8 -> 24690 | E8: ='03 Historical'!E8 -> 24724 | F8: ='03 Historical'!F8 -> 24541 | G8: =F8*(1+'02 Assumptions'!G22) -> 24541 | H8: =G8*(1+'02 Assumptions'!H22) -> 24295.59 | I8: =H8*(1+'02 Assumptions'!I22) -> 24052.634 | J8: =I8*(1+'02 Assumptions'!J22) -> 24052.634 | K8: =J8*(1+'02 Assumptions'!K22) -> 24052.634 | L8: =K8*(1+'02 Assumptions'!L22) -> 24293.16 | M8: =L8*(1+'02 Assumptions'!M22) -> 24536.092 | N8: =M8*(1+'02 Assumptions'!N22) -> 24781.453 | ... P8: =O8*(1+'02 Assumptions'!P22) -> 25279.56
B9: Hardware | C9: $M | D9: ='03 Historical'!D9 -> 3066 | E9: ='03 Historical'!E9 -> 2936 | F9: ='03 Historical'!F9 -> 3084 | G9: =F9*(1+'02 Assumptions'!G24) -> 3022.32 | H9: =G9*(1+'02 Assumptions'!H24) -> 2961.8736 | I9: =H9*(1+'02 Assumptions'!I24) -> 2932.2549 | J9: =I9*(1+'02 Assumptions'!J24) -> 2902.9323 | K9: =J9*(1+'02 Assumptions'!K24) -> 2902.9323 | L9: =K9*(1+'02 Assumptions'!L24) -> 2902.9323 | M9: =L9*(1+'02 Assumptions'!M24) -> 2902.9323 | N9: =M9*(1+'02 Assumptions'!N24) -> 2902.9323 | ... P9: =O9*(1+'02 Assumptions'!P24) -> 2902.9323
B10: Servicios | C10: $M | D10: ='03 Historical'!D10 -> 5431 | E10: ='03 Historical'!E10 -> 5233 | F10: ='03 Historical'!F10 -> 5743 | G10: =F10*(1+'02 Assumptions'!G26) -> 6202.44 | H10: =G10*(1+'02 Assumptions'!H26) -> 6636.6108 | I10: =H10*(1+'02 Assumptions'!I26) -> 7034.8074 | J10: =I10*(1+'02 Assumptions'!J26) -> 7386.5478 | K10: =J10*(1+'02 Assumptions'!K26) -> 7682.0097 | L10: =K10*(1+'02 Assumptions'!L26) -> 7912.47 | M10: =L10*(1+'02 Assumptions'!M26) -> 8149.8441 | N10: =M10*(1+'02 Assumptions'!N26) -> 8394.3394 | ... P10: =O10*(1+'02 Assumptions'!P26) -> 8905.5547
B11: INGRESOS TOTALES | C11: $M | D11: =SUM(D7:D10) -> 52961 | E11: =SUM(E7:E10) -> 57399 | F11: =SUM(F7:F10) -> 67357 | G11: =SUM(G7:G10) -> 84749.26 | H11: =SUM(H7:H10) -> 104251.3 | I11: =SUM(I7:I10) -> 124076.95 | J11: =SUM(J7:J10) -> 143311.39 | K11: =SUM(K7:K10) -> 161041.94 | ... P11: =SUM(P7:P10) -> 217395.22
B12: Crecimiento de ingresos | C12: % | E12: =E11/D11-1 -> 0.083797511 | F12: =F11/E11-1 -> 0.17348734 | G12: =G11/F11-1 -> 0.25821013 | H12: =H11/G11-1 -> 0.23011463 | I12: =I11/H11-1 -> 0.19017169 | J12: =J11/I11-1 -> 0.15502026 | K12: =K11/J11-1 -> 0.12372043 | L12: =L11/K11-1 -> 0.097114517 | ... P12: =P11/O11-1 -> 0.035458661
B13: Mix: Cloud / ingresos totales | C13: % | D13: =D7/D11 -> 0.37336908 | E13: =E7/E11 -> 0.42694124 | F13: =F7/F11 -> 0.50460977 | G13: =G7/G11 -> 0.60158047 | H13: =H7/H11 -> 0.67488105 | I13: =I7/I11 -> 0.72581776 | J13: =J7/J11 -> 0.76036717 | K13: =K7/K11 -> 0.7849158 | ... P13: =P7/P11 -> 0.82939805
B15: MARGEN BRUTO
B16: Gross Margin | C16: % | D16: ='03 Historical'!D18 -> 0.71407262 | E16: ='03 Historical'!E18 -> 0.70509939 | F16: ='03 Historical'!F18 -> 0.65822409 | G16: ='02 Assumptions'!G30 -> 0.61 | H16: ='02 Assumptions'!H30 -> 0.58 | I16: ='02 Assumptions'!I30 -> 0.565 | J16: ='02 Assumptions'!J30 -> 0.56 | K16: ='02 Assumptions'!K30 -> 0.56 | L16: ='02 Assumptions'!L30 -> 0.565 | M16: ='02 Assumptions'!M30 -> 0.57 | N16: ='02 Assumptions'!N30 -> 0.575 | ... P16: ='02 Assumptions'!P30 -> 0.58
B17: Margen bruto (Gross Profit) | C17: $M | D17: ='03 Historical'!D17 -> 37818 | E17: ='03 Historical'!E17 -> 40472 | F17: ='03 Historical'!F17 -> 44336 | G17: =G11*G16 -> 51697.049 | H17: =H11*H16 -> 60465.757 | I17: =I11*I16 -> 70103.477 | J17: =J11*J16 -> 80254.38 | K17: =K11*K16 -> 90183.486 | L17: =L11*L16 -> 99825.018 | M17: =M11*M16 -> 108244.89 | N17: =N11*N16 -> 115687.23 | ... P17: =P11*P16 -> 126089.23
B18: Coste de los ingresos | C18: $M | D18: ='03 Historical'!D16 -> 15143 | E18: ='03 Historical'!E16 -> 16927 | F18: ='03 Historical'!F16 -> 23021 | G18: =G11-G17 -> 33052.211 | H18: =H11-H17 -> 43785.548 | I18: =I11-I17 -> 53973.474 | J18: =J11-J17 -> 63057.013 | K18: =K11-K17 -> 70858.453 | L18: =L11-L17 -> 76856.43 | M18: =M11-M17 -> 81658.425 | N18: =N11-N17 -> 85507.952 | ... P18: =P11-P17 -> 91305.992
B20: GASTOS OPERATIVOS (por debajo del margen bruto)
B21: Ventas y marketing | C21: $M | D21: ='03 Historical'!D20 -> 8274 | E21: ='03 Historical'!E20 -> 8651 | F21: ='03 Historical'!F20 -> 8331 | G21: =G11*'02 Assumptions'!G32 -> 10169.911 | H21: =H11*'02 Assumptions'!H32 -> 11780.397 | I21: =I11*'02 Assumptions'!I32 -> 13400.311 | J21: =J11*'02 Assumptions'!J32 -> 14904.385 | K21: =K11*'02 Assumptions'!K32 -> 16265.236 | L21: =L11*'02 Assumptions'!L32 -> 17491.463 | M21: =M11*'02 Assumptions'!M32 -> 18610.525 | N21: =N11*'02 Assumptions'!N32 -> 19515.933 | ... P21: =P11*'02 Assumptions'!P32 -> 21087.336
B22: Investigación y desarrollo | C22: $M | D22: ='03 Historical'!D21 -> 8915 | E22: ='03 Historical'!E21 -> 9860 | F22: ='03 Historical'!F21 -> 10272 | G22: =G11*'02 Assumptions'!G34 -> 12288.643 | H22: =H11*'02 Assumptions'!H34 -> 14595.183 | I22: =I11*'02 Assumptions'!I34 -> 16874.465 | J22: =J11*'02 Assumptions'!J34 -> 19060.415 | K22: =K11*'02 Assumptions'!K34 -> 21096.494 | L22: =L11*'02 Assumptions'!L34 -> 22968.588 | M22: =M11*'02 Assumptions'!M34 -> 24497.527 | N22: =N11*'02 Assumptions'!N34 -> 25752.983 | ... P22: =P11*'02 Assumptions'!P34 -> 27826.588
B23: Generales y administración | C23: $M | D23: ='03 Historical'!D22 -> 1548 | E23: ='03 Historical'!E22 -> 1602 | F23: ='03 Historical'!F22 -> 1618 | G23: =G11*'02 Assumptions'!G36 -> 1864.4837 | H23: =H11*'02 Assumptions'!H36 -> 2189.2774 | I23: =I11*'02 Assumptions'!I36 -> 2481.539 | J23: =J11*'02 Assumptions'!J36 -> 2722.9164 | K23: =K11*'02 Assumptions'!K36 -> 3059.7968 | L23: =L11*'02 Assumptions'!L36 -> 3180.2661 | M23: =M11*'02 Assumptions'!M36 -> 3418.2597 | N23: =N11*'02 Assumptions'!N36 -> 3621.5133 | ... P23: =P11*'02 Assumptions'!P36 -> 3913.1139
B24: Amortización de intangibles adquiridos | C24: $M | D24: ='03 Historical'!D23 -> 3010 | E24: ='03 Historical'!E23 -> 2307 | F24: ='03 Historical'!F23 -> 1671 | G24: ='02 Assumptions'!G37 -> 1300 | H24: ='02 Assumptions'!H37 -> 1000 | I24: ='02 Assumptions'!I37 -> 750 | J24: ='02 Assumptions'!J37 -> 550 | K24: ='02 Assumptions'!K37 -> 400 | L24: ='02 Assumptions'!L37 -> 300 | M24: ='02 Assumptions'!M37 -> 220 | N24: ='02 Assumptions'!N37 -> 160 | ... P24: ='02 Assumptions'!P37 -> 90
B25: Reestructuración (normalizada) | C25: $M | D25: ='03 Historical'!D24 -> 718 | E25: ='03 Historical'!E24 -> 374 | F25: ='03 Historical'!F24 -> 1838 | G25: ='02 Assumptions'!G38 -> 600 | H25: ='02 Assumptions'!H38 -> 450 | I25: ='02 Assumptions'!I38 -> 350 | J25: ='02 Assumptions'!J38 -> 300 | K25: ='02 Assumptions'!K38 -> 250 | L25: ='02 Assumptions'!L38 -> 250 | M25: ='02 Assumptions'!M38 -> 250 | N25: ='02 Assumptions'!N38 -> 250 | ... P25: ='02 Assumptions'!P38 -> 250
B26: Total gastos operativos | C26: $M | D26: =SUM(D21:D25) -> 22465 | E26: =SUM(E21:E25) -> 22794 | F26: =SUM(F21:F25) -> 23730 | G26: =SUM(G21:G25) -> 26223.038 | H26: =SUM(H21:H25) -> 30014.857 | I26: =SUM(I21:I25) -> 33856.315 | J26: =SUM(J21:J25) -> 37537.716 | K26: =SUM(K21:K25) -> 41071.527 | ... P26: =SUM(P21:P25) -> 53167.038
B27: EBIT reportado | C27: $M | D27: =D17-D26 -> 15353 | E27: =E17-E26 -> 17678 | F27: =F17-F26 -> 20606 | G27: =G17-G26 -> 25474.011 | H27: =H17-H26 -> 30450.899 | I27: =I17-I26 -> 36247.162 | J27: =J17-J26 -> 42716.663 | K27: =K17-K26 -> 49111.959 | ... P27: =P17-P26 -> 72922.188
B28: EBIT Margin reportado | C28: % | D28: =D27/D11 -> 0.28989256 | E28: =E27/E11 -> 0.30798446 | F28: =F27/F11 -> 0.30592218 | G28: =G27/G11 -> 0.30058093 | H28: =H27/H11 -> 0.2920913 | I28: =I27/I11 -> 0.29213453 | J28: =J27/J11 -> 0.29806886 | K28: =K27/K11 -> 0.30496378 | ... P28: =P27/P11 -> 0.33543603
B29: EBIT NORMALIZADO (excluye reestructuración) | C29: $M | D29: =D27+D25 -> 16071 | E29: =E27+E25 -> 18052 | F29: =F27+F25 -> 22444 | G29: =G27+G25 -> 26074.011 | H29: =H27+H25 -> 30900.899 | I29: =I27+I25 -> 36597.162 | J29: =J27+J25 -> 43016.663 | K29: =K27+K25 -> 49361.959 | ... P29: =P27+P25 -> 73172.188
B30: Margen EBIT normalizado | C30: % | D30: =D29/D11 -> 0.30344971 | E30: =E29/E11 -> 0.31450025 | F30: =F29/F11 -> 0.33320961 | G30: =G29/G11 -> 0.30766063 | H30: =H29/H11 -> 0.29640779 | I30: =I29/I11 -> 0.29495536 | J30: =J29/J11 -> 0.3001622 | K30: =K29/K11 -> 0.30651617 | ... P30: =P29/P11 -> 0.33658601
B32: CAPEX Y DEPRECIACIÓN — ROLL-FORWARD DE PP&E
B33: PP&E neto inicial | C33: $M | F33: ='03 Historical'!E48 -> 43522 | G33: =F37 -> 99957 | H33: =G37 -> 135133.83 | I33: =H37 -> 157336.34 | J33: =I37 -> 170239.5 | K33: =J37 -> 177173.99 | L33: =K37 -> 179183.53 | M33: =L37 -> 179975.03 | N33: =M37 -> 180622.62 | ... P33: =O37 -> 182539.01
B34: Capex | C34: $M | D34: ='03 Historical'!D129 -> 6866 | E34: ='03 Historical'!E129 -> 21215 | F34: ='03 Historical'!F129 -> 55663 | G34: =G11*'02 Assumptions'!G42 -> 50849.556 | H34: =H11*'02 Assumptions'!H42 -> 41700.522 | I34: =I11*'02 Assumptions'!I42 -> 34741.546 | J34: =J11*'02 Assumptions'!J42 -> 30095.392 | K34: =K11*'02 Assumptions'!K42 -> 25766.71 | L34: =L11*'02 Assumptions'!L42 -> 24735.403 | M34: =M11*'02 Assumptions'!M42 -> 24687.431 | N34: =N11*'02 Assumptions'!N42 -> 25149.398 | ... P34: =P11*'02 Assumptions'!P42 -> 25652.636
B35: Capex / Ingresos | C35: % | D35: =D34/D11 -> 0.12964257 | E35: =E34/E11 -> 0.36960574 | F35: =F34/F11 -> 0.82638775 | G35: =G34/G11 -> 0.6 | H35: =H34/H11 -> 0.4 | I35: =I34/I11 -> 0.28 | J35: =J34/J11 -> 0.21 | K35: =K34/K11 -> 0.16 | ... P35: =P34/P11 -> 0.118
B36: Depreciación = (PP&E inicial + Capex/2) / vida útil | C36: $M | D36: ='03 Historical'!D79 -> 3129 | E36: ='03 Historical'!E79 -> 3867 | F36: ='03 Historical'!F79 -> 7623 | G36: =(G33+G34/2)/'02 Assumptions'!$C$43 -> 15672.722 | H36: =(H33+H34/2)/'02 Assumptions'!$C$43 -> 19498.012 | I36: =(I33+I34/2)/'02 Assumptions'!$C$43 -> 21838.39 | J36: =(J33+J34/2)/'02 Assumptions'!$C$43 -> 23160.9 | K36: =(K33+K34/2)/'02 Assumptions'!$C$43 -> 23757.169 | L36: =(L33+L34/2)/'02 Assumptions'!$C$43 -> 23943.905 | M36: =(M33+M34/2)/'02 Assumptions'!$C$43 -> 24039.844 | N36: =(N33+N34/2)/'02 Assumptions'!$C$43 -> 24149.665 | ... P36: =(P33+P34/2)/'02 Assumptions'!$C$43 -> 24420.666
B37: PP&E neto final | C37: $M | E37: ='03 Historical'!E48 -> 43522 | F37: ='03 Historical'!F48 -> 99957 | G37: =G33+G34-G36 -> 135133.83 | H37: =H33+H34-H36 -> 157336.34 | I37: =I33+I34-I36 -> 170239.5 | J37: =J33+J34-J36 -> 177173.99 | K37: =K33+K34-K36 -> 179183.53 | L37: =L33+L34-L36 -> 179975.03 | M37: =M33+M34-M36 -> 180622.62 | N37: =N33+N34-N36 -> 181622.35 | ... P37: =P33+P34-P36 -> 183770.98
B38: D&A total (depreciación + amortización de intangibles) | C38: $M | D38: =D36+D24 -> 6139 | E38: =E36+E24 -> 6174 | F38: =F36+F24 -> 9294 | G38: =G36+G24 -> 16972.722 | H38: =H36+H24 -> 20498.012 | I38: =I36+I24 -> 22588.39 | J38: =J36+J24 -> 23710.9 | K38: =K36+K24 -> 24157.169 | ... P38: =P36+P24 -> 24510.666
B39: EBITDA (EBIT normalizado + D&A) | C39: $M | D39: =D29+D38 -> 22210 | E39: =E29+E38 -> 24226 | F39: =F29+F38 -> 31738 | G39: =G29+G38 -> 43046.733 | H39: =H29+H38 -> 51398.911 | I39: =I29+I38 -> 59185.552 | J39: =J29+J38 -> 66727.563 | K39: =K29+K38 -> 73519.127 | ... P39: =P29+P38 -> 97682.854
B40: EBITDA Margin | C40: % | D40: =D39/D11 -> 0.41936519 | E40: =E39/E11 -> 0.4220631 | F40: =F39/F11 -> 0.47119082 | G40: =G39/G11 -> 0.50793049 | H40: =H39/H11 -> 0.49302895 | I40: =I39/I11 -> 0.47700682 | J40: =J39/J11 -> 0.46561241 | K40: =K39/K11 -> 0.45652163 | ... P40: =P39/P11 -> 0.44933304
B41: Capex / D&A | C41: x | D41: =D34/D38 -> 1.1184232 | E41: =E34/E38 -> 3.436184 | F41: =F34/F38 -> 5.9891328 | G41: =G34/G38 -> 2.9959576 | H41: =H34/H38 -> 2.0343691 | I41: =I34/I38 -> 1.5380267 | J41: =J34/J38 -> 1.269264 | K41: =K34/K38 -> 1.0666279 | ... P41: =P34/P38 -> 1.0465907
B43: CIRCULANTE OPERATIVO (drivers: DSO, proveedores sobre coste+capex, ingresos diferidos)
B44: Clientes (AR) | C44: $M | E44: ='03 Historical'!E45 -> 8558 | F44: ='03 Historical'!F45 -> 10385 | G44: ='02 Assumptions'!G48/365*G11 -> 13002.626 | H44: ='02 Assumptions'!H48/365*H11 -> 15709.101 | I44: ='02 Assumptions'!I48/365*I11 -> 18356.59 | J44: ='02 Assumptions'!J48/365*J11 -> 20809.599 | K44: ='02 Assumptions'!K48/365*K11 -> 22942.961 | L44: ='02 Assumptions'!L48/365*L11 -> 25171.056 | M44: ='02 Assumptions'!M48/365*M11 -> 27054.719 | N44: ='02 Assumptions'!N48/365*N11 -> 28663.423 | ... P44: ='02 Assumptions'!P48/365*P11 -> 30971.374
B45: Otros activos corrientes | C45: $M | E45: ='03 Historical'!E46 -> 4818 | F45: ='03 Historical'!F46 -> 4288 | G45: =G11*'02 Assumptions'!G51 -> 5254.4541 | H45: =H11*'02 Assumptions'!H51 -> 6255.0783 | I45: =I11*'02 Assumptions'!I51 -> 7320.5401 | J45: =J11*'02 Assumptions'!J51 -> 8312.0607 | K45: =K11*'02 Assumptions'!K51 -> 9340.4324 | L45: =L11*'02 Assumptions'!L51 -> 10247.524 | M45: =M11*'02 Assumptions'!M51 -> 11014.392 | N45: =N11*'02 Assumptions'!N51 -> 11669.321 | ... P45: =P11*'02 Assumptions'!P51 -> 12608.923
B46: Proveedores | C46: $M | E46: ='03 Historical'!E57 -> 5113 | F46: ='03 Historical'!F57 -> 10977 | G46: =(G18+G34)*'02 Assumptions'!G49 -> 11326.739 | H46: =(H18+H34)*'02 Assumptions'!H49 -> 11540.619 | I46: =(I18+I34)*'02 Assumptions'!I49 -> 11976.528 | J46: =(J18+J34)*'02 Assumptions'!J49 -> 12575.575 | K46: =(K18+K34)*'02 Assumptions'!K49 -> 13044.397 | L46: =(L18+L34)*'02 Assumptions'!L49 -> 13714.897 | M46: =(M18+M34)*'02 Assumptions'!M49 -> 14356.691 | N46: =(N18+N34)*'02 Assumptions'!N49 -> 14938.742 | ... P46: =(P18+P34)*'02 Assumptions'!P49 -> 15789.415
...

Sheet 05 Three Statement
A1: MODELO DE TRES ESTADOS INTEGRADO FY2027E–FY2036E — ORACLE CORPORATION
A2: Sirve para verificar la CONSISTENCIA CONTABLE del forecast (cuadre de balance y de caja). NO alimenta el DCF: el DCF es un FCFF construido sobre '04 Operating Model'.
B4: Partida | C4: Unidad | D4: ='00 Panel del Analista'!D14 -> 0 | E4: ='00 Panel del Analista'!E14 -> 0 | F4: ='00 Panel del Analista'!F14 -> 0 | G4: ='00 Panel del Analista'!G14 -> 0 | H4: ='00 Panel del Analista'!H14 -> 0 | I4: ='00 Panel del Analista'!I14 -> 0 | J4: ='00 Panel del Analista'!J14 -> 0 | K4: ='00 Panel del Analista'!K14 -> 0 | ... P4: ='00 Panel del Analista'!P14 -> 0
B6: CUENTA DE RESULTADOS
B7: Ingresos | C7: $M | G7: ='04 Operating Model'!G11 -> 84749.26 | H7: ='04 Operating Model'!H11 -> 104251.3 | I7: ='04 Operating Model'!I11 -> 124076.95 | J7: ='04 Operating Model'!J11 -> 143311.39 | K7: ='04 Operating Model'!K11 -> 161041.94 | L7: ='04 Operating Model'!L11 -> 176681.45 | M7: ='04 Operating Model'!M11 -> 189903.31 | N7: ='04 Operating Model'!N11 -> 201195.18 | ... P7: ='04 Operating Model'!P11 -> 217395.22
B8: Coste de los ingresos | C8: $M | G8: ='04 Operating Model'!G18 -> 33052.211 | H8: ='04 Operating Model'!H18 -> 43785.548 | I8: ='04 Operating Model'!I18 -> 53973.474 | J8: ='04 Operating Model'!J18 -> 63057.013 | K8: ='04 Operating Model'!K18 -> 70858.453 | L8: ='04 Operating Model'!L18 -> 76856.43 | M8: ='04 Operating Model'!M18 -> 81658.425 | N8: ='04 Operating Model'!N18 -> 85507.952 | ... P8: ='04 Operating Model'!P18 -> 91305.992
B9: Margen bruto | C9: $M | G9: =G7-G8 -> 51697.049 | H9: =H7-H8 -> 60465.757 | I9: =I7-I8 -> 70103.477 | J9: =J7-J8 -> 80254.38 | K9: =K7-K8 -> 90183.486 | L9: =L7-L8 -> 99825.018 | M9: =M7-M8 -> 108244.89 | N9: =N7-N8 -> 115687.23 | ... P9: =P7-P8 -> 126089.23
B10: Gastos operativos | C10: $M | G10: ='04 Operating Model'!G26 -> 26223.038 | H10: ='04 Operating Model'!H26 -> 30014.857 | I10: ='04 Operating Model'!I26 -> 33856.315 | J10: ='04 Operating Model'!J26 -> 37537.716 | K10: ='04 Operating Model'!K26 -> 41071.527 | L10: ='04 Operating Model'!L26 -> 44190.318 | M10: ='04 Operating Model'!M26 -> 46996.312 | N10: ='04 Operating Model'!N26 -> 49300.429 | ... P10: ='04 Operating Model'!P26 -> 53167.038
B11: EBIT reportado | C11: $M | G11: =G9-G10 -> 25474.011 | H11: =H9-H10 -> 30450.899 | I11: =I9-I10 -> 36247.162 | J11: =J9-J10 -> 42716.663 | K11: =K9-K10 -> 49111.959 | L11: =L9-L10 -> 55634.701 | M11: =M9-M10 -> 61248.577 | N11: =N9-N10 -> 66386.8 | ... P11: =P9-P10 -> 72922.188
B12: (−) Gasto por intereses | C12: $M | G12: =G26 -> 5829.345 | H12: =H26 -> 5499.2874 | I12: =I26 -> 5290.2393 | J12: =J26 -> 4817.0895 | K12: =K26 -> 3957.3876 | L12: =L26 -> 2681.3036 | M12: =M26 -> 1055.9943 | N12: =N26 -> 0 | ... P12: =P26 -> 0
B13: (+) Resultado no operativo, neto (no proyectado) | C13: $M | G13: =0 -> 0 | H13: =0 -> 0 | I13: =0 -> 0 | J13: =0 -> 0 | K13: =0 -> 0 | L13: =0 -> 0 | M13: =0 -> 0 | N13: =0 -> 0 | ... P13: =0 -> 0
B14: Beneficio antes de impuestos | C14: $M | G14: =G11-G12+G13 -> 19644.666 | H14: =H11-H12+H13 -> 24951.612 | I14: =I11-I12+I13 -> 30956.923 | J14: =J11-J12+J13 -> 37899.574 | K14: =K11-K12+K13 -> 45154.571 | L14: =L11-L12+L13 -> 52953.397 | M14: =M11-M12+M13 -> 60192.583 | N14: =N11-N12+N13 -> 66386.8 | ... P14: =P11-P12+P13 -> 72922.188
B15: (−) Impuestos | C15: $M | G15: =G14*'04 Operating Model'!G55 -> 2750.2532 | H15: =H14*'04 Operating Model'!H55 -> 3742.7418 | I15: =I14*'04 Operating Model'!I55 -> 4953.1077 | J15: =J14*'04 Operating Model'!J55 -> 6442.9275 | K15: =K14*'04 Operating Model'!K55 -> 8127.8228 | L15: =L14*'04 Operating Model'!L55 -> 10061.145 | M15: =M14*'04 Operating Model'!M55 -> 11436.591 | N15: =N14*'04 Operating Model'!N55 -> 12613.492 | ... P15: =P14*'04 Operating Model'!P55 -> 13855.216
B16: BENEFICIO NETO | C16: $M | G16: =G14-G15 -> 16894.413 | H16: =H14-H15 -> 21208.87 | I16: =I14-I15 -> 26003.815 | J16: =J14-J15 -> 31456.646 | K16: =K14-K15 -> 37026.749 | L16: =L14-L15 -> 42892.252 | M16: =M14-M15 -> 48755.992 | N16: =N14-N15 -> 53773.308 | ... P16: =P14-P15 -> 59066.973
B17: (−) Dividendos de preferentes | C17: $M | G17: =G93 -> 322.01 | H17: =H93 -> 322.01 | I17: =I93 -> 322.01 | J17: =J93 -> 322.01 | K17: =K93 -> 322.01 | L17: =L93 -> 322.01 | M17: =M93 -> 322.01 | N17: =N93 -> 322.01 | ... P17: =P93 -> 322.01
B18: Beneficio atribuible a ordinarias | C18: $M | G18: =G16-G17 -> 16572.403 | H18: =H16-H17 -> 20886.86 | I18: =I16-I17 -> 25681.805 | J18: =J16-J17 -> 31134.636 | K18: =K16-K17 -> 36704.739 | L18: =L16-L17 -> 42570.242 | M18: =M16-M17 -> 48433.982 | N18: =N16-N17 -> 53451.298 | ... P18: =P16-P17 -> 58744.963
B20: ESQUEMA DE DEUDA (interés sobre deuda inicial: sin circularidad)
B21: Deuda inicial | C21: $M | G21: =F24 -> 129541 | H21: =G24 -> 122206.39 | I21: =H24 -> 117560.87 | J21: =I24 -> 107046.43 | K21: =J24 -> 87941.947 | L21: =K24 -> 59584.524 | M21: =L24 -> 23466.54 | N21: =M24 -> 0 | ... P21: =O24 -> 0
B22: (+) Nueva deuda emitida | C22: $M | G22: =G32 -> 0 | H22: =H32 -> 0 | I22: =I32 -> 0 | J22: =J32 -> 0 | K22: =K32 -> 0 | L22: =L32 -> 0 | M22: =M32 -> 0 | N22: =N32 -> 0 | ... P22: =P32 -> 0
B23: (−) Repago de deuda | C23: $M | G23: =G34 -> 7334.614 | H23: =H34 -> 4645.512 | I23: =I34 -> 10514.44 | J23: =J34 -> 19104.487 | K23: =K34 -> 28357.423 | L23: =L34 -> 36117.984 | M23: =M34 -> 23466.54 | N23: =N34 -> 0 | ... P23: =P34 -> 0
B24: Deuda final | C24: $M | F24: ='02 Assumptions'!$C$70 -> 129541 | G24: =G21+G22-G23 -> 122206.39 | H24: =H21+H22-H23 -> 117560.87 | I24: =I21+I22-I23 -> 107046.43 | J24: =J21+J22-J23 -> 87941.947 | K24: =K21+K22-K23 -> 59584.524 | L24: =L21+L22-L23 -> 23466.54 | M24: =M21+M22-M23 -> 0 | N24: =N21+N22-N23 -> 0 | ... P24: =P21+P22-P23 -> 0
B25: Tipo de interés medio | C25: % | G25: ='02 Assumptions'!$C$98 -> 0.045 | H25: ='02 Assumptions'!$C$98 -> 0.045 | I25: ='02 Assumptions'!$C$98 -> 0.045 | J25: ='02 Assumptions'!$C$98 -> 0.045 | K25: ='02 Assumptions'!$C$98 -> 0.045 | L25: ='02 Assumptions'!$C$98 -> 0.045 | M25: ='02 Assumptions'!$C$98 -> 0.045 | N25: ='02 Assumptions'!$C$98 -> 0.045 | ... P25: ='02 Assumptions'!$C$98 -> 0.045
B26: Gasto por intereses = deuda inicial × tipo | C26: $M | G26: =G21*G25 -> 5829.345 | H26: =H21*H25 -> 5499.2874 | I26: =I21*I25 -> 5290.2393 | J26: =J21*J25 -> 4817.0895 | K26: =K21*K25 -> 3957.3876 | L26: =L21*L25 -> 2681.3036 | M26: =M21*M25 -> 1055.9943 | N26: =N21*N25 -> 0 | ... P26: =P21*P25 -> 0
B28: POLÍTICA DE FINANCIACIÓN (determina caja y deuda)
B29: Caja inicial | C29: $M | G29: =F35 -> 31289 | H29: =G35 -> 8605.8529 | I29: =H35 -> 6209.2815 | J29: =I35 -> 12375.594 | K29: =J35 -> 21254.158 | L29: =K35 -> 30773.052 | M29: =L35 -> 38768.205 | N29: =M35 -> 64719.352 | ... P29: =O35 -> 173644.9
B30: Caja preliminar = inicial + CFO + CFI − dividendos − recompras | C30: $M | G30: =G29+G77+G79-G82-G83-G84 -> 15940.467 | H30: =H29+H77+H79-H82-H83-H84 -> 10854.794 | I30: =I29+I77+I79-I82-I83-I84 -> 22890.035 | J30: =J29+J77+J79-J82-J83-J84 -> 40358.645 | K30: =K29+K77+K79-K82-K83-K84 -> 59130.476 | L30: =L29+L77+L79-L82-L83-L84 -> 74886.189 | M30: =M29+M77+M79-M82-M83-M84 -> 88185.892 | N30: =N29+N77+N79-N82-N83-N84 -> 118005.52 | ... P30: =P29+P77+P79-P82-P83-P84 -> 229761.98
B31: Caja mínima requerida | C31: $M | G31: ='02 Assumptions'!$C$68*G7 -> 1271.2389 | H31: ='02 Assumptions'!$C$68*H7 -> 1563.7696 | I31: ='02 Assumptions'!$C$68*I7 -> 1861.1543 | J31: ='02 Assumptions'!$C$68*J7 -> 2149.6709 | K31: ='02 Assumptions'!$C$68*K7 -> 2415.6291 | L31: ='02 Assumptions'!$C$68*L7 -> 2650.2217 | M31: ='02 Assumptions'!$C$68*M7 -> 2848.5497 | N31: ='02 Assumptions'!$C$68*N7 -> 3017.9277 | ... P31: ='02 Assumptions'!$C$68*P7 -> 3260.9283
B32: Nueva deuda necesaria = MAX(0; mínima − preliminar) | C32: $M | G32: =MAX(0,G31-G30) -> 0 | H32: =MAX(0,H31-H30) -> 0 | I32: =MAX(0,I31-I30) -> 0 | J32: =MAX(0,J31-J30) -> 0 | K32: =MAX(0,K31-K30) -> 0 | L32: =MAX(0,L31-L30) -> 0 | M32: =MAX(0,M31-M30) -> 0 | N32: =MAX(0,N31-N30) -> 0 | ... P32: =MAX(0,P31-P30) -> 0
B33: Excedente sobre la caja mínima | C33: $M | G33: =MAX(0,G30-G31) -> 14669.228 | H33: =MAX(0,H30-H31) -> 9291.0239 | I33: =MAX(0,I30-I31) -> 21028.88 | J33: =MAX(0,J30-J31) -> 38208.974 | K33: =MAX(0,K30-K31) -> 56714.847 | L33: =MAX(0,L30-L31) -> 72235.967 | M33: =MAX(0,M30-M31) -> 85337.342 | N33: =MAX(0,N30-N31) -> 114987.59 | ... P33: =MAX(0,P30-P31) -> 226501.05
B34: Repago efectivo = MIN(deuda inicial; excedente × %) | C34: $M | G34: =MIN(G21,G33*'02 Assumptions'!$C$97) -> 7334.614 | H34: =MIN(H21,H33*'02 Assumptions'!$C$97) -> 4645.512 | I34: =MIN(I21,I33*'02 Assumptions'!$C$97) -> 10514.44 | J34: =MIN(J21,J33*'02 Assumptions'!$C$97) -> 19104.487 | K34: =MIN(K21,K33*'02 Assumptions'!$C$97) -> 28357.423 | L34: =MIN(L21,L33*'02 Assumptions'!$C$97) -> 36117.984 | M34: =MIN(M21,M33*'02 Assumptions'!$C$97) -> 23466.54 | N34: =MIN(N21,N33*'02 Assumptions'!$C$97) -> 0 | ... P34: =MIN(P21,P33*'02 Assumptions'!$C$97) -> 0
B35: Caja final | C35: $M | F35: ='02 Assumptions'!$C$72 -> 31289 | G35: =G30+G32-G34 -> 8605.8529 | H35: =H30+H32-H34 -> 6209.2815 | I35: =I30+I32-I34 -> 12375.594 | J35: =J30+J32-J34 -> 21254.158 | K35: =K30+K32-K34 -> 30773.052 | L35: =L30+L32-L34 -> 38768.205 | M35: =M30+M32-M34 -> 64719.352 | N35: =N30+N32-N34 -> 118005.52 | ... P35: =P30+P32-P34 -> 229761.98
B37: BALANCE
B38: Caja y equivalentes | C38: $M | G38: =G35 -> 8605.8529 | H38: =H35 -> 6209.2815 | I38: =I35 -> 12375.594 | J38: =J35 -> 21254.158 | K38: =K35 -> 30773.052 | L38: =L35 -> 38768.205 | M38: =M35 -> 64719.352 | N38: =N35 -> 118005.52 | ... P38: =P35 -> 229761.98
B39: Valores negociables | C39: $M | G39: ='02 Assumptions'!$C$73 -> 605 | H39: ='02 Assumptions'!$C$73 -> 605 | I39: ='02 Assumptions'!$C$73 -> 605 | J39: ='02 Assumptions'!$C$73 -> 605 | K39: ='02 Assumptions'!$C$73 -> 605 | L39: ='02 Assumptions'!$C$73 -> 605 | M39: ='02 Assumptions'!$C$73 -> 605 | N39: ='02 Assumptions'!$C$73 -> 605 | ... P39: ='02 Assumptions'!$C$73 -> 605
B40: Clientes (AR) | C40: $M | G40: ='04 Operating Model'!G44 -> 13002.626 | H40: ='04 Operating Model'!H44 -> 15709.101 | I40: ='04 Operating Model'!I44 -> 18356.59 | J40: ='04 Operating Model'!J44 -> 20809.599 | K40: ='04 Operating Model'!K44 -> 22942.961 | L40: ='04 Operating Model'!L44 -> 25171.056 | M40: ='04 Operating Model'!M44 -> 27054.719 | N40: ='04 Operating Model'!N44 -> 28663.423 | ... P40: ='04 Operating Model'!P44 -> 30971.374
B41: Otros activos corrientes | C41: $M | G41: ='04 Operating Model'!G45 -> 5254.4541 | H41: ='04 Operating Model'!H45 -> 6255.0783 | I41: ='04 Operating Model'!I45 -> 7320.5401 | J41: ='04 Operating Model'!J45 -> 8312.0607 | K41: ='04 Operating Model'!K45 -> 9340.4324 | L41: ='04 Operating Model'!L45 -> 10247.524 | M41: ='04 Operating Model'!M45 -> 11014.392 | N41: ='04 Operating Model'!N45 -> 11669.321 | ... P41: ='04 Operating Model'!P45 -> 12608.923
B42: PP&E neto | C42: $M | G42: ='04 Operating Model'!G37 -> 135133.83 | H42: ='04 Operating Model'!H37 -> 157336.34 | I42: ='04 Operating Model'!I37 -> 170239.5 | J42: ='04 Operating Model'!J37 -> 177173.99 | K42: ='04 Operating Model'!K37 -> 179183.53 | L42: ='04 Operating Model'!L37 -> 179975.03 | M42: ='04 Operating Model'!M37 -> 180622.62 | N42: ='04 Operating Model'!N37 -> 181622.35 | ... P42: ='04 Operating Model'!P37 -> 183770.98
B43: ROU — leases operativos | C43: $M | G43: ='03 Historical'!$F$49 -> 29690 | H43: ='03 Historical'!$F$49 -> 29690 | I43: ='03 Historical'!$F$49 -> 29690 | J43: ='03 Historical'!$F$49 -> 29690 | K43: ='03 Historical'!$F$49 -> 29690 | L43: ='03 Historical'!$F$49 -> 29690 | M43: ='03 Historical'!$F$49 -> 29690 | N43: ='03 Historical'!$F$49 -> 29690 | ... P43: ='03 Historical'!$F$49 -> 29690
B44: Fondo de comercio | C44: $M | G44: ='03 Historical'!$F$50 -> 62261 | H44: ='03 Historical'!$F$50 -> 62261 | I44: ='03 Historical'!$F$50 -> 62261 | J44: ='03 Historical'!$F$50 -> 62261 | K44: ='03 Historical'!$F$50 -> 62261 | L44: ='03 Historical'!$F$50 -> 62261 | M44: ='03 Historical'!$F$50 -> 62261 | N44: ='03 Historical'!$F$50 -> 62261 | ... P44: ='03 Historical'!$F$50 -> 62261
B45: Intangibles adquiridos, neto | C45: $M | F45: ='02 Assumptions'!$C$101 -> 4890 | G45: =F45-'04 Operating Model'!G24 -> 3590 | H45: =G45-'04 Operating Model'!H24 -> 2590 | I45: =H45-'04 Operating Model'!I24 -> 1840 | J45: =I45-'04 Operating Model'!J24 -> 1290 | K45: =J45-'04 Operating Model'!K24 -> 890 | L45: =K45-'04 Operating Model'!L24 -> 590 | M45: =L45-'04 Operating Model'!M24 -> 370 | N45: =M45-'04 Operating Model'!N24 -> 210 | ... P45: =O45-'04 Operating Model'!P24 -> 0
...

Sheet 06 DCF
A1: DCF — FREE CASH FLOW TO FIRM — ORACLE CORPORATION (ORCL) | R1: =1+1 -> 0
A2: USD millones. FCFF descontado al WACC. Ningún resultado está introducido a mano: todo se calcula desde '02 Assumptions', '04 Operating Model' y '07 WACC'.
B4: Partida | C4: Unidad | D4: ='00 Panel del Analista'!D14 -> 0 | E4: ='00 Panel del Analista'!E14 -> 0 | F4: ='00 Panel del Analista'!F14 -> 0 | G4: ='00 Panel del Analista'!G14 -> 0 | H4: ='00 Panel del Analista'!H14 -> 0 | I4: ='00 Panel del Analista'!I14 -> 0 | J4: ='00 Panel del Analista'!J14 -> 0 | K4: ='00 Panel del Analista'!K14 -> 0 | ... P4: ='00 Panel del Analista'!P14 -> 0
B6: CÁLCULO DEL FREE CASH FLOW TO FIRM (FCFF)
B7: EBIT normalizado | C7: $M | D7: ='04 Operating Model'!D29 -> 16071 | E7: ='04 Operating Model'!E29 -> 18052 | F7: ='04 Operating Model'!F29 -> 22444 | G7: ='04 Operating Model'!G29 -> 26074.011 | H7: ='04 Operating Model'!H29 -> 30900.899 | I7: ='04 Operating Model'!I29 -> 36597.162 | J7: ='04 Operating Model'!J29 -> 43016.663 | K7: ='04 Operating Model'!K29 -> 49361.959 | ... P7: ='04 Operating Model'!P29 -> 73172.188
B8: Tipo impositivo de caja | C8: % | G8: ='04 Operating Model'!G55 -> 0.14 | H8: ='04 Operating Model'!H55 -> 0.15 | I8: ='04 Operating Model'!I55 -> 0.16 | J8: ='04 Operating Model'!J55 -> 0.17 | K8: ='04 Operating Model'!K55 -> 0.18 | L8: ='04 Operating Model'!L55 -> 0.19 | M8: ='04 Operating Model'!M55 -> 0.19 | N8: ='04 Operating Model'!N55 -> 0.19 | ... P8: ='04 Operating Model'!P55 -> 0.19
B9: (−) Impuestos sobre el EBIT normalizado | C9: $M | G9: =-G7*G8 -> -3650.3615 | H9: =-H7*H8 -> -4635.1349 | I9: =-I7*I8 -> -5855.546 | J9: =-J7*J8 -> -7312.8327 | K9: =-K7*K8 -> -8885.1526 | L9: =-L7*L8 -> -10618.093 | M9: =-M7*M8 -> -11684.73 | N9: =-N7*N8 -> -12660.992 | ... P9: =-P7*P8 -> -13902.716
B10: NOPAT | C10: $M | G10: =G7+G9 -> 22423.649 | H10: =H7+H9 -> 26265.764 | I10: =I7+I9 -> 30741.616 | J10: =J7+J9 -> 35703.83 | K10: =K7+K9 -> 40476.806 | L10: =L7+L9 -> 45266.608 | M10: =M7+M9 -> 49813.847 | N10: =N7+N9 -> 53975.808 | ... P10: =P7+P9 -> 59269.473
B11: (+) D&A | C11: $M | G11: ='04 Operating Model'!G38 -> 16972.722 | H11: ='04 Operating Model'!H38 -> 20498.012 | I11: ='04 Operating Model'!I38 -> 22588.39 | J11: ='04 Operating Model'!J38 -> 23710.9 | K11: ='04 Operating Model'!K38 -> 24157.169 | L11: ='04 Operating Model'!L38 -> 24243.905 | M11: ='04 Operating Model'!M38 -> 24259.844 | N11: ='04 Operating Model'!N38 -> 24309.665 | ... P11: ='04 Operating Model'!P38 -> 24510.666
B12: (−) Capex | C12: $M | G12: =-'04 Operating Model'!G34 -> -50849.556 | H12: =-'04 Operating Model'!H34 -> -41700.522 | I12: =-'04 Operating Model'!I34 -> -34741.546 | J12: =-'04 Operating Model'!J34 -> -30095.392 | K12: =-'04 Operating Model'!K34 -> -25766.71 | L12: =-'04 Operating Model'!L34 -> -24735.403 | M12: =-'04 Operating Model'!M34 -> -24687.431 | N12: =-'04 Operating Model'!N34 -> -25149.398 | ... P12: =-'04 Operating Model'!P34 -> -25652.636
B13: (−) Variación del capital circulante neto | C13: $M | G13: =-'04 Operating Model'!G51 -> 2273.4096 | H13: =-'04 Operating Model'!H51 -> 2329.71 | I13: =-'04 Operating Model'!I51 -> 2501.1331 | J13: =-'04 Operating Model'!J51 -> 2364.0617 | K13: =-'04 Operating Model'!K51 -> 1943.69 | L13: =-'04 Operating Model'!L51 -> 1500.1551 | M13: =-'04 Operating Model'!M51 -> 1454.2209 | N13: =-'04 Operating Model'!N51 -> 1326.1726 | ... P13: =-'04 Operating Model'!P51 -> 1225.0019
B14: (−) Coste en caja de reestructuración (readido al EBIT normalizado) | C14: $M | G14: =-'02 Assumptions'!G38 -> -600 | H14: =-'02 Assumptions'!H38 -> -450 | I14: =-'02 Assumptions'!I38 -> -350 | J14: =-'02 Assumptions'!J38 -> -300 | K14: =-'02 Assumptions'!K38 -> -250 | L14: =-'02 Assumptions'!L38 -> -250 | M14: =-'02 Assumptions'!M38 -> -250 | N14: =-'02 Assumptions'!N38 -> -250 | ... P14: =-'02 Assumptions'!P38 -> -250
B15: FCFF | C15: $M | G15: =SUM(G10:G14) -> -9779.7747 | H15: =SUM(H10:H14) -> 6942.9643 | I15: =SUM(I10:I14) -> 20739.593 | J15: =SUM(J10:J14) -> 31383.399 | K15: =SUM(K10:K14) -> 40560.955 | L15: =SUM(L10:L14) -> 46025.264 | M15: =SUM(M10:M14) -> 50590.481 | N15: =SUM(N10:N14) -> 54212.248 | ... P15: =SUM(P10:P14) -> 59102.504
B16: Margen FCFF sobre ingresos | C16: % | G16: =G15/'04 Operating Model'!G11 -> -0.11539658 | H16: =H15/'04 Operating Model'!H11 -> 0.066598345 | I16: =I15/'04 Operating Model'!I11 -> 0.16715105 | J16: =J15/'04 Operating Model'!J11 -> 0.21898747 | K16: =K15/'04 Operating Model'!K11 -> 0.25186579 | L16: =L15/'04 Operating Model'!L11 -> 0.26049857 | M16: =M15/'04 Operating Model'!M11 -> 0.26640125 | N16: =N15/'04 Operating Model'!N11 -> 0.26945103 | ... P16: =P15/'04 Operating Model'!P11 -> 0.27186663
B17: Conversión FCFF / EBITDA | C17: % | G17: =G15/'04 Operating Model'!G39 -> -0.22718971 | H17: =H15/'04 Operating Model'!H39 -> 0.13507999 | I17: =I15/'04 Operating Model'!I39 -> 0.35041648 | J17: =J15/'04 Operating Model'!J39 -> 0.47032138 | K17: =K15/'04 Operating Model'!K39 -> 0.55170615 | L17: =L15/'04 Operating Model'!L39 -> 0.57439243 | M17: =M15/'04 Operating Model'!M39 -> 0.58991853 | N17: =N15/'04 Operating Model'!N39 -> 0.59608967 | ... P17: =P15/'04 Operating Model'!P39 -> 0.60504482
B19: DESCUENTO
B20: Periodo de descuento t (convención de '02 Assumptions'!C12) | C20: años | G20: =COLUMNS($G20:G20)-IF('02 Assumptions'!$C$12=2,0.5,0) -> 0.5 | H20: =COLUMNS($G20:H20)-IF('02 Assumptions'!$C$12=2,0.5,0) -> 1.5 | I20: =COLUMNS($G20:I20)-IF('02 Assumptions'!$C$12=2,0.5,0) -> 2.5 | J20: =COLUMNS($G20:J20)-IF('02 Assumptions'!$C$12=2,0.5,0) -> 3.5 | K20: =COLUMNS($G20:K20)-IF('02 Assumptions'!$C$12=2,0.5,0) -> 4.5 | L20: =COLUMNS($G20:L20)-IF('02 Assumptions'!$C$12=2,0.5,0) -> 5.5 | M20: =COLUMNS($G20:M20)-IF('02 Assumptions'!$C$12=2,0.5,0) -> 6.5 | N20: =COLUMNS($G20:N20)-IF('02 Assumptions'!$C$12=2,0.5,0) -> 7.5 | ... P20: =COLUMNS($G20:P20)-IF('02 Assumptions'!$C$12=2,0.5,0) -> 9.5
B21: WACC | C21: % | G21: ='07 WACC'!$C$38 -> 0.087495 | H21: ='07 WACC'!$C$38 -> 0.087495 | I21: ='07 WACC'!$C$38 -> 0.087495 | J21: ='07 WACC'!$C$38 -> 0.087495 | K21: ='07 WACC'!$C$38 -> 0.087495 | L21: ='07 WACC'!$C$38 -> 0.087495 | M21: ='07 WACC'!$C$38 -> 0.087495 | N21: ='07 WACC'!$C$38 -> 0.087495 | ... P21: ='07 WACC'!$C$38 -> 0.087495
