Workbook

Sheet 00 Panel del Analista
A1: PANEL DEL ANALISTA — TODOS LOS INPUTS DEL MODELO EN UN SOLO SITIO
A2: Rellena las celdas AZULES sobre fondo blanco y las AMARILLAS (hipótesis críticas). El resto del libro se recalcula solo. Para valorar OTRA compañía: sustituye la identificación, los tres estados históricos y los drivers; no hace falta tocar ninguna otra hoja.
A3: Las filas marcadas «calculado» no se rellenan: son totales que el libro deriva. Al terminar, comprueba el semáforo del final de esta hoja y la hoja '13 Checks'.
B5: Input | C5: Unidad | D5: Hist. −2 | E5: Hist. −1 | F5: Hist. base | G5: Año 1 | H5: Año 2 | I5: Año 3 | J5: Año 4 | K5: Año 5 | L5: Año 6 | M5: Año 7 | N5: Año 8 | O5: Año 9 | P5: Año 10
B7: 1. IDENTIFICACIÓN Y MERCADO
B8: Compañía | C8: QUALCOMM Incorporated
B9: Ticker y mercado | C9: QCOM — Nasdaq
B10: Moneda y unidades | C10: USD millones
B11: Fecha de valoración | C11: =DATE(2026,9,23) -> 46288
B12: Último ejercicio auditado | C12: FY2025A auditado (cerrado 28/09/2025); base del forecast FY2026E = 9M real + guía Q4
B13: PRECIO DE MERCADO ACTUAL (el único dato que el libro no puede deducir) | C13: 198.27
B14: Etiquetas de los ejercicios (se propagan a las cabeceras de todas las hojas) | C14: texto | D14: FY2024A | E14: FY2025A | F14: FY2026E | G14: FY2027E | H14: FY2028E | I14: FY2029E | J14: FY2030E | K14: FY2031E | L14: FY2032E | M14: FY2033E | N14: FY2034E | O14: FY2035E | P14: FY2036E
B16: 2. CUENTA DE RESULTADOS HISTÓRICA
B18: QCT IoT + Data Center y otros no reportables | C18: $M | D18: 5617 | E18: 6809 | F18: =5244+353+(1806+109) -> 7512
B19: QCT Handsets | C19: $M | D19: 24863 | E19: 27793 | F19: =18934+5200 -> 24134
B20: QTL Licencias (incl. ingresos no asignados) | C20: $M | D20: 5572 | E20: 5725 | F20: =4252+1300 -> 5552
B21: QCT Automoción | C21: $M | D21: 2910 | E21: 3957 | F21: =4015+1685 -> 5700
B22: Ingresos totales | C22: $M | D22: calculado
B24: Coste de los ingresos (excl. amortización de intangibles) | C24: $M | D24: 16749 | E24: 19417 | F24: =(15138+4752)-331 -> 19559
B25: (no aplica — coste único en QCOM) | C25: $M | D25: 0 | E25: 0 | F25: 0
B26: (no aplica — coste único en QCOM) | C26: $M | D26: 0 | E26: 0 | F26: 0
B27: Coste total de los ingresos | C27: $M | D27: calculado
B28: Margen bruto (Gross Profit) | C28: $M | D28: calculado
B29: Gross Margin | C29: % | D29: calculado
B31: Ventas, generales y administración (SG&A) | C31: $M | D31: 2759 | E31: 3110 | F31: =2738+980 -> 3718
B32: Investigación y desarrollo | C32: $M | D32: 8893 | E32: 9042 | F32: =7523+2620 -> 10143
B33: Generales y administración (incluido en SG&A) | C33: $M | D33: 0 | E33: 0 | F33: 0
B34: Amortización de intangibles adquiridos (reclasificada desde coste de ingresos) | C34: $M | D34: 311 | E34: 321 | F34: 331
B35: Otros gastos operativos (reestructuración, deterioros y otros) | C35: $M | D35: 179 | E35: 39 | F35: =97+0 -> 97
B36: Gastos operativos totales | C36: $M | D36: calculado
B37: EBIT (resultado operativo) reportado | C37: $M | D37: calculado
B38: EBIT Margin reportado | C38: % | D38: calculado
B40: Gasto por intereses | C40: $M | D40: 697 | E40: 664 | F40: =519+175 -> 694
B41: Resultado de inversiones y otros, neto (incl. QSI) | C41: $M | D41: 962 | E41: 972 | F41: =1458+85 -> 1543
B42: Beneficio antes de impuestos | C42: $M | D42: calculado
B43: Impuesto sobre sociedades | C43: $M | D43: 226 | E43: 7122 | F43: =-4136+232 -> -3904
B44: Tipo impositivo efectivo | C44: % | D44: calculado
B45: Beneficio neto | C45: $M | D45: calculado
B46: Dividendos de acciones preferentes | C46: $M | D46: 0 | E46: 0 | F46: 0
B47: Beneficio neto atribuible a ordinarias | C47: $M | D47: calculado
...

Sheet 01 Summary
A1: QUALCOMM INCORPORATED (QCOM) — RESUMEN DE VALORACIÓN DCF
A2: Valoración condicional: el resultado depende íntegramente de las hipótesis explícitas de '02 Assumptions'. No es una predicción.
B3: ⚠ PULSA Ctrl+Alt+F9 AL ABRIR ESTE LIBRO. Estas zonas se escribieron con el motor de cálculo del complemento bloqueado y mostrarán CEROS hasta que se fuerce un recálculo completo: (1) hojas 09a/09b/09c de escenarios; (2) las 25 celdas de las rejillas de '08 Sensibilidad' D6:H46; (3) en esta hoja, la tabla de escenarios F16:H24, el bloque de Múltiplos y el bloque de Precio objetivo; (4) en '13 Checks', los contadores D5:D7 y los controles 70-78. Las fórmulas están escritas y verificadas sintácticamente; lo que falta es que Excel las evalúe. TRAS EL RECÁLCULO comprueba el control 73 de '13 Checks': si está en OK, la réplica del escenario Base coincide con el DCF y los tres escenarios son fiables.
B4: IDENTIFICACIÓN | E4: CÓMO USAR ESTE LIBRO
B5: Compañía | C5: ='00 Panel del Analista'!C8 -> QUALCOMM Incorporated | E5: 1 | F5: Introducir el precio de mercado actual en C10. Es el ÚNICO dato que el libro no puede obtener por sí mismo. Hasta entonces el upside, el margen de seguridad y el Reverse DCF quedan en blanco por diseño.
B6: Ticker / mercado | C6: ='00 Panel del Analista'!C9 -> QCOM — Nasdaq | E6: 2 | F6: Actualizar y documentar los inputs de mercado del WACC en '07 WACC': tipo libre de riesgo, prima de riesgo, beta y coste marginal de la deuda. Los valores actuales son inputs del analista, NO datos verificados.
B7: Moneda y unidades | C7: ='00 Panel del Analista'!C10 -> USD millones | E7: 3 | F7: Revisar las hipótesis en '02 Assumptions'. Las celdas amarillas son las que mueven el valor. Ninguna otra hoja contiene hipótesis.
B8: Fecha de valoración | C8: ='00 Panel del Analista'!C11 -> 46288 | E8: 4 | F8: Cambiar el escenario en '09 Scenarios'!C4 (1=Bear, 2=Base, 3=Bull) y anotar los tres valores para construir el rango.
B9: Último ejercicio auditado | C9: ='00 Panel del Analista'!C12 -> FY2025A auditado (cerrado 28/09/2025); base del forecast FY2026E = 9M real + guía Q4 | E9: 5 | F9: Leer '08 Sensitivity' para ver qué variables explican el valor, y '10 Reverse DCF' para ver qué descuenta el precio.
B10: PRECIO DE MERCADO ACTUAL — INTRODUCIR AQUÍ | C10: ='00 Panel del Analista'!C13 -> 198.27 | E10: 6 | F10: Ejecutar la auditoría de '13 Checks' ANTES de usar cualquier resultado. Si algún control falla, el número no es utilizable.
E11: 7 | F11: Leer '11 Cross Check': un DCF aislado no es una conclusión. Y leer 'M4 Manual Errores' antes de defender el modelo ante otro analista.
B12: RESULTADO DE LA VALORACIÓN | E12: Si esta tabla o el bloque de Precio objetivo muestran ceros: Ctrl+Alt+F9.
B13: Escenario activo | C13: ='09 Escenarios'!C5 -> BASE | E13: LOS TRES ESCENARIOS, CALCULADOS SIMULTÁNEAMENTE
B14: Enterprise Value | C14: ='06 DCF'!F44 -> 149457.62 | E14: Ya NO es una instantánea: cada columna se calcula en su propia hoja ('09a', '09b', '09c'), independiente del interruptor de '09 Escenarios'!C4. Los deltas de cada escenario están en la matriz de '09 Escenarios' filas 9-17.
B15: (−) Deuda neta y otras reclamaciones | C15: ='06 DCF'!F53-'06 DCF'!F44 -> -6444.96 | E15: Métrica | F15: PESIMISTA | G15: BASE | H15: OPTIMISTA | I15: Unidad
B16: Equity Value | C16: ='06 DCF'!F53 -> 143012.66 | E16: Enterprise Value | F16: ='Escenario Pesimista'!$F$66 -> 95059.825 | G16: ='Escenario Base'!$F$66 -> 149457.62 | H16: ='Escenario Optimista'!$F$66 -> 216184.32 | I16: $M
B17: Acciones diluidas | C17: ='06 DCF'!F54 -> 1085.7 | E17: Equity Value | F17: ='Escenario Pesimista'!$F$70 -> 88614.865 | G17: ='Escenario Base'!$F$70 -> 143012.66 | H17: ='Escenario Optimista'!$F$70 -> 209739.36 | I17: $M
B18: VALOR INTRÍNSECO POR ACCIÓN | C18: ='06 DCF'!F55 -> 131.72392 | E18: Valor intrínseco por acción | F18: ='Escenario Pesimista'!$F$72 -> 81.620029 | G18: ='Escenario Base'!$F$72 -> 131.72392 | H18: ='Escenario Optimista'!$F$72 -> 193.18353 | I18: $/acc
B19: Upside / (Downside) sobre el precio actual | C19: =IF($C$10<=0,"◄ introducir el precio en C10",'06 DCF'!F57) -> -0.33563362 | E19: WACC | F19: ='Escenario Pesimista'!$P$52 -> 0.12540544 | G19: ='Escenario Base'!$P$52 -> 0.11540544 | H19: ='Escenario Optimista'!$P$52 -> 0.11040544 | I19: %
B20: Margen de seguridad implícito | C20: =IF($C$10<=0,"◄ introducir el precio en C10",'06 DCF'!F58) -> -0.50519356 | E20: Crecimiento terminal g | F20: ='Escenario Pesimista'!$P$53 -> 0.0225 | G20: ='Escenario Base'!$P$53 -> 0.03 | H20: ='Escenario Optimista'!$P$53 -> 0.035 | I20: %
E21: Valor terminal / EV | F21: ='Escenario Pesimista'!$F$67 -> 0.38859779 | G21: ='Escenario Base'!$F$67 -> 0.46198292 | H21: ='Escenario Optimista'!$F$67 -> 0.51577143 | I21: %
B22: RANGO DE VALORACIÓN POR ESCENARIO | E22: Múltiplo de salida implícito | F22: ='Escenario Pesimista'!$F$68 -> 6.6289132 | G22: ='Escenario Base'!$F$68 -> 8.2480732 | H22: ='Escenario Optimista'!$F$68 -> 9.4614903 | I22: x
B23: Nota | C23: Ver la instantánea de los tres escenarios en E13:I21 → | E23: Ingresos FY2036E | F23: ='Escenario Pesimista'!$F$75 -> 63665.185 | G23: ='Escenario Base'!$F$75 -> 81883.255 | H23: ='Escenario Optimista'!$F$75 -> 102631.85 | I23: $M
E24: Upside / (Downside) | F24: ='Escenario Pesimista'!$F$74 -> -0.58833898 | G24: ='Escenario Base'!$F$74 -> -0.33563362 | H24: ='Escenario Optimista'!$F$74 -> -0.025654246 | I24: %
B25: PARÁMETROS CLAVE | E25: CHECK: el escenario Base debe reproducir '06 DCF' | G25: ='Escenario Base'!$F$82 -> OK
B26: WACC | C26: ='07 WACC'!C38 -> 0.11540544 | E26: CHECK: ordenación Pesimista < Base < Optimista | G26: =IF(AND($F$18<$G$18,$G$18<$H$18),"OK","FALLO: los escenarios no están ordenados") -> OK
B27: Crecimiento terminal g | C27: ='06 DCF'!F26 -> 0.03
B28: ROIC terminal | C28: ='06 DCF'!F27 -> 0.3
B29: Margen WACC − g | C29: ='07 WACC'!C43 -> 0.085405443
B30: Valor terminal / Enterprise Value | C30: ='06 DCF'!F45 -> 0.46198292
B31: Múltiplo de salida implícito (VT / EBITDA FY2036) | C31: ='06 DCF'!F62 -> 8.2480732
B32: EV / EBITDA FY2026E implícito | C32: ='06 DCF'!F71 -> 13.903466
B33: EV / Ingresos FY2026E implícito | C33: ='06 DCF'!F72 -> 3.4840231
B35: SITUACIÓN DE PARTIDA (FY2026E = 9M REPORTADO + GUÍA Q4)
B36: Ingresos | C36: ='03 Historical'!F11 -> 42898
B37: Crecimiento de ingresos | C37: ='03 Historical'!F121 -> -0.031297986
B38: EBIT normalizado | C38: ='03 Historical'!F127 -> 9147
B39: Margen EBIT normalizado | C39: ='03 Historical'!F128 -> 0.21322672
B40: Capex | C40: ='03 Historical'!F129 -> 2104
B41: Capex / Ingresos | C41: ='03 Historical'!F130 -> 0.049046576
...

Sheet 02 Assumptions
A1: HIPÓTESIS CENTRALIZADAS — QUALCOMM INCORPORATED (QCOM)
A2: AZUL = input del analista. NEGRO = fórmula. VERDE = enlace a otra hoja. GRIS = dato histórico reportado. AMARILLO = hipótesis crítica. Ninguna otra hoja debe contener hipótesis: todas viven aquí.
B4: Hipótesis | C4: Unidad | D4: ='00 Panel del Analista'!D14 -> FY2024A | E4: ='00 Panel del Analista'!E14 -> FY2025A | F4: ='00 Panel del Analista'!F14 -> FY2026E | G4: ='00 Panel del Analista'!G14 -> FY2027E | H4: ='00 Panel del Analista'!H14 -> FY2028E | I4: ='00 Panel del Analista'!I14 -> FY2029E | J4: ='00 Panel del Analista'!J14 -> FY2030E | K4: ='00 Panel del Analista'!K14 -> FY2031E | ... P4: ='00 Panel del Analista'!P14 -> FY2036E | Q4: Peso del delta de escenario
B6: PANEL DE CONTROL
B7: Escenario activo (1=Bear, 2=Base, 3=Bull) | C7: ='09 Escenarios'!C4 -> 2
B8: Nombre del escenario activo | C8: ='09 Escenarios'!C5 -> BASE
B9: Fecha de valoración | C9: ='00 Panel del Analista'!C11 -> 46288
B10: Moneda y unidades | C10: ='00 Panel del Analista'!C10 -> USD millones
B11: Años de forecast explícito | C11: ='00 Panel del Analista'!D186 -> 10
B12: Convención de descuento (1=fin de año, 2=mitad de año) | C12: ='00 Panel del Analista'!D187 -> 2
B13: Método de valor terminal (1=Gordon, 2=Múltiplo de salida) | C13: ='00 Panel del Analista'!D188 -> 1
B14: Tratamiento de leases operativos | C14: OPERATIVO — coste en EBIT, pasivo fuera de la deuda neta
B15: Tratamiento del SBC | C15: GASTO REAL — no se readiciona, no se aplica dilución adicional
B16: Año base del forecast | C16: ='00 Panel del Analista'!C12 -> FY2025A auditado (cerrado 28/09/2025); base del forecast FY2026E = 9M real + guía Q4
B18: INGRESOS — CRECIMIENTO POR SEGMENTO (driver: salida de Apple en Handsets, rampa de Data Center y diversificación en Auto/IoT)
B19: IoT + Data Center — crecimiento (vector Base) | C19: % | G19: ='00 Panel del Analista'!G165 -> 0.6 | H19: ='00 Panel del Analista'!H165 -> 0.33 | I19: ='00 Panel del Analista'!I165 -> 0.22 | J19: ='00 Panel del Analista'!J165 -> 0.15 | K19: ='00 Panel del Analista'!K165 -> 0.12 | L19: ='00 Panel del Analista'!L165 -> 0.1 | M19: ='00 Panel del Analista'!M165 -> 0.08 | N19: ='00 Panel del Analista'!N165 -> 0.06 | ... P19: ='00 Panel del Analista'!P165 -> 0.04
B20: IoT + Data Center — crecimiento ACTIVO (Base × multiplicador de escenario) | C20: % | G20: =G19*'09 Escenarios'!$G$9+$C$104 -> 0.6 | H20: =H19*'09 Escenarios'!$G$9+$C$104 -> 0.33 | I20: =I19*'09 Escenarios'!$G$9+$C$104 -> 0.22 | J20: =J19*'09 Escenarios'!$G$9+$C$104 -> 0.15 | K20: =K19*'09 Escenarios'!$G$9+$C$104 -> 0.12 | L20: =L19*'09 Escenarios'!$G$9+$C$104 -> 0.1 | M20: =M19*'09 Escenarios'!$G$9+$C$104 -> 0.08 | N20: =N19*'09 Escenarios'!$G$9+$C$104 -> 0.06 | ... P20: =P19*'09 Escenarios'!$G$9+$C$104 -> 0.04
B21: QCT Handsets — crecimiento (vector Base) | C21: % | G21: ='00 Panel del Analista'!G166 -> -0.15 | H21: ='00 Panel del Analista'!H166 -> 0.02 | I21: ='00 Panel del Analista'!I166 -> 0.03 | J21: ='00 Panel del Analista'!J166 -> 0.02 | K21: ='00 Panel del Analista'!K166 -> 0.02 | L21: ='00 Panel del Analista'!L166 -> 0.02 | M21: ='00 Panel del Analista'!M166 -> 0.02 | N21: ='00 Panel del Analista'!N166 -> 0.02 | ... P21: ='00 Panel del Analista'!P166 -> 0.025
B22: QCT Handsets — crecimiento ACTIVO | C22: % | G22: =G21+'09 Escenarios'!$G$10+$C$104 -> -0.15 | H22: =H21+'09 Escenarios'!$G$10+$C$104 -> 0.02 | I22: =I21+'09 Escenarios'!$G$10+$C$104 -> 0.03 | J22: =J21+'09 Escenarios'!$G$10+$C$104 -> 0.02 | K22: =K21+'09 Escenarios'!$G$10+$C$104 -> 0.02 | L22: =L21+'09 Escenarios'!$G$10+$C$104 -> 0.02 | M22: =M21+'09 Escenarios'!$G$10+$C$104 -> 0.02 | N22: =N21+'09 Escenarios'!$G$10+$C$104 -> 0.02 | ... P22: =P21+'09 Escenarios'!$G$10+$C$104 -> 0.025
B23: QTL Licencias — crecimiento (vector Base) | C23: % | G23: ='00 Panel del Analista'!G167 -> -0.02 | H23: ='00 Panel del Analista'!H167 -> -0.02 | I23: ='00 Panel del Analista'!I167 -> 0 | J23: ='00 Panel del Analista'!J167 -> 0.01 | K23: ='00 Panel del Analista'!K167 -> 0.01 | L23: ='00 Panel del Analista'!L167 -> 0.01 | M23: ='00 Panel del Analista'!M167 -> 0.015 | N23: ='00 Panel del Analista'!N167 -> 0.015 | ... P23: ='00 Panel del Analista'!P167 -> 0.02
B24: QTL Licencias — crecimiento ACTIVO | C24: % | G24: =G23+'09 Escenarios'!$G$10+$C$104 -> -0.02 | H24: =H23+'09 Escenarios'!$G$10+$C$104 -> -0.02 | I24: =I23+'09 Escenarios'!$G$10+$C$104 -> 0 | J24: =J23+'09 Escenarios'!$G$10+$C$104 -> 0.01 | K24: =K23+'09 Escenarios'!$G$10+$C$104 -> 0.01 | L24: =L23+'09 Escenarios'!$G$10+$C$104 -> 0.01 | M24: =M23+'09 Escenarios'!$G$10+$C$104 -> 0.015 | N24: =N23+'09 Escenarios'!$G$10+$C$104 -> 0.015 | ... P24: =P23+'09 Escenarios'!$G$10+$C$104 -> 0.02
B25: QCT Automoción — crecimiento (vector Base) | C25: % | G25: ='00 Panel del Analista'!G168 -> 0.22 | H25: ='00 Panel del Analista'!H168 -> 0.17 | I25: ='00 Panel del Analista'!I168 -> 0.15 | J25: ='00 Panel del Analista'!J168 -> 0.13 | K25: ='00 Panel del Analista'!K168 -> 0.11 | L25: ='00 Panel del Analista'!L168 -> 0.09 | M25: ='00 Panel del Analista'!M168 -> 0.08 | N25: ='00 Panel del Analista'!N168 -> 0.07 | ... P25: ='00 Panel del Analista'!P168 -> 0.05
B26: QCT Automoción — crecimiento ACTIVO | C26: % | G26: =G25+'09 Escenarios'!$G$10+$C$104 -> 0.22 | H26: =H25+'09 Escenarios'!$G$10+$C$104 -> 0.17 | I26: =I25+'09 Escenarios'!$G$10+$C$104 -> 0.15 | J26: =J25+'09 Escenarios'!$G$10+$C$104 -> 0.13 | K26: =K25+'09 Escenarios'!$G$10+$C$104 -> 0.11 | L26: =L25+'09 Escenarios'!$G$10+$C$104 -> 0.09 | M26: =M25+'09 Escenarios'!$G$10+$C$104 -> 0.08 | N26: =N25+'09 Escenarios'!$G$10+$C$104 -> 0.07 | ... P26: =P25+'09 Escenarios'!$G$10+$C$104 -> 0.05
B28: MÁRGENES Y ESTRUCTURA DE COSTES
B29: Gross Margin (vector Base) | C29: % | G29: ='00 Panel del Analista'!G169 -> 0.545 | H29: ='00 Panel del Analista'!H169 -> 0.55 | I29: ='00 Panel del Analista'!I169 -> 0.555 | J29: ='00 Panel del Analista'!J169 -> 0.555 | K29: ='00 Panel del Analista'!K169 -> 0.555 | L29: ='00 Panel del Analista'!L169 -> 0.555 | M29: ='00 Panel del Analista'!M169 -> 0.555 | N29: ='00 Panel del Analista'!N169 -> 0.555 | ... P29: ='00 Panel del Analista'!P169 -> 0.555
B30: Gross Margin ACTIVO | C30: % | G30: =G29+'09 Escenarios'!$G$11 -> 0.545 | H30: =H29+'09 Escenarios'!$G$11 -> 0.55 | I30: =I29+'09 Escenarios'!$G$11 -> 0.555 | J30: =J29+'09 Escenarios'!$G$11 -> 0.555 | K30: =K29+'09 Escenarios'!$G$11 -> 0.555 | L30: =L29+'09 Escenarios'!$G$11 -> 0.555 | M30: =M29+'09 Escenarios'!$G$11 -> 0.555 | N30: =N29+'09 Escenarios'!$G$11 -> 0.555 | ... P30: =P29+'09 Escenarios'!$G$11 -> 0.555
B31: SG&A / Ingresos (Base) | C31: % | G31: ='00 Panel del Analista'!G170 -> 0.085 | H31: ='00 Panel del Analista'!H170 -> 0.08 | I31: ='00 Panel del Analista'!I170 -> 0.077 | J31: ='00 Panel del Analista'!J170 -> 0.075 | K31: ='00 Panel del Analista'!K170 -> 0.073 | L31: ='00 Panel del Analista'!L170 -> 0.072 | M31: ='00 Panel del Analista'!M170 -> 0.071 | N31: ='00 Panel del Analista'!N170 -> 0.071 | ... P31: ='00 Panel del Analista'!P170 -> 0.071
B32: SG&A / Ingresos ACTIVO | C32: % | G32: =G31+'09 Escenarios'!$G$12*$Q$32 -> 0.085 | H32: =H31+'09 Escenarios'!$G$12*$Q$32 -> 0.08 | I32: =I31+'09 Escenarios'!$G$12*$Q$32 -> 0.077 | J32: =J31+'09 Escenarios'!$G$12*$Q$32 -> 0.075 | K32: =K31+'09 Escenarios'!$G$12*$Q$32 -> 0.073 | L32: =L31+'09 Escenarios'!$G$12*$Q$32 -> 0.072 | M32: =M31+'09 Escenarios'!$G$12*$Q$32 -> 0.071 | N32: =N31+'09 Escenarios'!$G$12*$Q$32 -> 0.071 | ... P32: =P31+'09 Escenarios'!$G$12*$Q$32 -> 0.071 | Q32: ='00 Panel del Analista'!D202 -> 0.4
B33: I+D / Ingresos (Base) | C33: % | G33: ='00 Panel del Analista'!G171 -> 0.235 | H33: ='00 Panel del Analista'!H171 -> 0.225 | I33: ='00 Panel del Analista'!I171 -> 0.215 | J33: ='00 Panel del Analista'!J171 -> 0.21 | K33: ='00 Panel del Analista'!K171 -> 0.207 | L33: ='00 Panel del Analista'!L171 -> 0.205 | M33: ='00 Panel del Analista'!M171 -> 0.205 | N33: ='00 Panel del Analista'!N171 -> 0.205 | ... P33: ='00 Panel del Analista'!P171 -> 0.205
B34: I+D / Ingresos ACTIVO | C34: % | G34: =G33+'09 Escenarios'!$G$12*$Q$34 -> 0.235 | H34: =H33+'09 Escenarios'!$G$12*$Q$34 -> 0.225 | I34: =I33+'09 Escenarios'!$G$12*$Q$34 -> 0.215 | J34: =J33+'09 Escenarios'!$G$12*$Q$34 -> 0.21 | K34: =K33+'09 Escenarios'!$G$12*$Q$34 -> 0.207 | L34: =L33+'09 Escenarios'!$G$12*$Q$34 -> 0.205 | M34: =M33+'09 Escenarios'!$G$12*$Q$34 -> 0.205 | N34: =N33+'09 Escenarios'!$G$12*$Q$34 -> 0.205 | ... P34: =P33+'09 Escenarios'!$G$12*$Q$34 -> 0.205 | Q34: ='00 Panel del Analista'!D203 -> 0.6
B35: G&A / Ingresos (Base) — incluido en SG&A | C35: % | G35: ='00 Panel del Analista'!G172 -> 0 | H35: ='00 Panel del Analista'!H172 -> 0 | I35: ='00 Panel del Analista'!I172 -> 0 | J35: ='00 Panel del Analista'!J172 -> 0 | K35: ='00 Panel del Analista'!K172 -> 0 | L35: ='00 Panel del Analista'!L172 -> 0 | M35: ='00 Panel del Analista'!M172 -> 0 | N35: ='00 Panel del Analista'!N172 -> 0 | ... P35: ='00 Panel del Analista'!P172 -> 0
B36: G&A / Ingresos ACTIVO — incluido en SG&A | C36: % | G36: =G35+'09 Escenarios'!$G$12*$Q$36 -> 0 | H36: =H35+'09 Escenarios'!$G$12*$Q$36 -> 0 | I36: =I35+'09 Escenarios'!$G$12*$Q$36 -> 0 | J36: =J35+'09 Escenarios'!$G$12*$Q$36 -> 0 | K36: =K35+'09 Escenarios'!$G$12*$Q$36 -> 0 | L36: =L35+'09 Escenarios'!$G$12*$Q$36 -> 0 | M36: =M35+'09 Escenarios'!$G$12*$Q$36 -> 0 | N36: =N35+'09 Escenarios'!$G$12*$Q$36 -> 0 | ... P36: =P35+'09 Escenarios'!$G$12*$Q$36 -> 0 | Q36: ='00 Panel del Analista'!D204 -> 0
B37: Amortización de intangibles adquiridos (calendario) | C37: $M | G37: ='00 Panel del Analista'!G173 -> 430 | H37: ='00 Panel del Analista'!H173 -> 350 | I37: ='00 Panel del Analista'!I173 -> 280 | J37: ='00 Panel del Analista'!J173 -> 210 | K37: ='00 Panel del Analista'!K173 -> 140 | L37: ='00 Panel del Analista'!L173 -> 100 | M37: ='00 Panel del Analista'!M173 -> 0 | N37: ='00 Panel del Analista'!N173 -> 0 | ... P37: ='00 Panel del Analista'!P173 -> 0
B38: Otros gastos operativos normalizados (reestructuración, deterioros) | C38: $M | G38: ='00 Panel del Analista'!G174 -> 100 | H38: ='00 Panel del Analista'!H174 -> 100 | I38: ='00 Panel del Analista'!I174 -> 100 | J38: ='00 Panel del Analista'!J174 -> 100 | K38: ='00 Panel del Analista'!K174 -> 100 | L38: ='00 Panel del Analista'!L174 -> 100 | M38: ='00 Panel del Analista'!M174 -> 100 | N38: ='00 Panel del Analista'!N174 -> 100 | ... P38: ='00 Panel del Analista'!P174 -> 100
B40: CAPEX Y DEPRECIACIÓN
B41: Capex / Ingresos (vector Base) | C41: % | G41: ='00 Panel del Analista'!G175 -> 0.045 | H41: ='00 Panel del Analista'!H175 -> 0.038 | I41: ='00 Panel del Analista'!I175 -> 0.034 | J41: ='00 Panel del Analista'!J175 -> 0.03 | K41: ='00 Panel del Analista'!K175 -> 0.03 | L41: ='00 Panel del Analista'!L175 -> 0.03 | M41: ='00 Panel del Analista'!M175 -> 0.03 | N41: ='00 Panel del Analista'!N175 -> 0.03 | ... P41: ='00 Panel del Analista'!P175 -> 0.03
B42: Capex / Ingresos ACTIVO | C42: % | G42: =G41*'09 Escenarios'!$G$13 -> 0.045 | H42: =H41*'09 Escenarios'!$G$13 -> 0.038 | I42: =I41*'09 Escenarios'!$G$13 -> 0.034 | J42: =J41*'09 Escenarios'!$G$13 -> 0.03 | K42: =K41*'09 Escenarios'!$G$13 -> 0.03 | L42: =L41*'09 Escenarios'!$G$13 -> 0.03 | M42: =M41*'09 Escenarios'!$G$13 -> 0.03 | N42: =N41*'09 Escenarios'!$G$13 -> 0.03 | ... P42: =P41*'09 Escenarios'!$G$13 -> 0.03
B43: Vida útil media del PP&E | C43: ='00 Panel del Analista'!D189 -> 4.5
B44: Vida útil implícita en FY2026 (check de calibración) | C44: años | F44: =('03 Historical'!E48+'03 Historical'!F129/2)/'03 Historical'!F79 -> 4.5153342
B46: CIRCULANTE OPERATIVO (drivers, no % de ingresos genérico)
...

Sheet 03 Historical
A1: ESTADOS FINANCIEROS HISTÓRICOS — QUALCOMM INCORPORATED (QCOM)
A2: USD millones salvo indicación. Ejercicio fiscal cerrado el último domingo de septiembre. Fuentes: Form 10-K FY2025 (auditado) y Form 10-Q Q3 FY2026. FY2026E = 9 meses reportados + guía Q4 (estimación). Balance F = 28/06/2026.
B4: Partida | C4: Unidad | D4: ='00 Panel del Analista'!D14 -> FY2024A | E4: ='00 Panel del Analista'!E14 -> FY2025A | F4: ='00 Panel del Analista'!F14 -> FY2026E | G4: ='00 Panel del Analista'!G14 -> FY2027E | H4: ='00 Panel del Analista'!H14 -> FY2028E | I4: ='00 Panel del Analista'!I14 -> FY2029E | J4: ='00 Panel del Analista'!J14 -> FY2030E | K4: ='00 Panel del Analista'!K14 -> FY2031E | ... P4: ='00 Panel del Analista'!P14 -> FY2036E
B6: CUENTA DE RESULTADOS
B7: ='00 Panel del Analista'!B18 -> QCT IoT + Data Center y otros no reportables | C7: $M | D7: ='00 Panel del Analista'!D18 -> 5617 | E7: ='00 Panel del Analista'!E18 -> 6809 | F7: ='00 Panel del Analista'!F18 -> 7512
B8: ='00 Panel del Analista'!B19 -> QCT Handsets | C8: $M | D8: ='00 Panel del Analista'!D19 -> 24863 | E8: ='00 Panel del Analista'!E19 -> 27793 | F8: ='00 Panel del Analista'!F19 -> 24134
B9: ='00 Panel del Analista'!B20 -> QTL Licencias (incl. ingresos no asignados) | C9: $M | D9: ='00 Panel del Analista'!D20 -> 5572 | E9: ='00 Panel del Analista'!E20 -> 5725 | F9: ='00 Panel del Analista'!F20 -> 5552
B10: ='00 Panel del Analista'!B21 -> QCT Automoción | C10: $M | D10: ='00 Panel del Analista'!D21 -> 2910 | E10: ='00 Panel del Analista'!E21 -> 3957 | F10: ='00 Panel del Analista'!F21 -> 5700
B11: Ingresos totales | C11: $M | D11: =SUM(D7:D10) -> 38962 | E11: =SUM(E7:E10) -> 44284 | F11: =SUM(F7:F10) -> 42898
B13: ='00 Panel del Analista'!B24 -> Coste de los ingresos (excl. amortización de intangibles) | C13: $M | D13: ='00 Panel del Analista'!D24 -> 16749 | E13: ='00 Panel del Analista'!E24 -> 19417 | F13: ='00 Panel del Analista'!F24 -> 19559
B14: ='00 Panel del Analista'!B25 -> (no aplica — coste único en QCOM) | C14: $M | D14: ='00 Panel del Analista'!D25 -> 0 | E14: ='00 Panel del Analista'!E25 -> 0 | F14: ='00 Panel del Analista'!F25 -> 0
B15: ='00 Panel del Analista'!B26 -> (no aplica — coste único en QCOM) | C15: $M | D15: ='00 Panel del Analista'!D26 -> 0 | E15: ='00 Panel del Analista'!E26 -> 0 | F15: ='00 Panel del Analista'!F26 -> 0
B16: Coste total de los ingresos | C16: $M | D16: =SUM(D13:D15) -> 16749 | E16: =SUM(E13:E15) -> 19417 | F16: =SUM(F13:F15) -> 19559
B17: Margen bruto (Gross Profit) | C17: $M | D17: =D11-D16 -> 22213 | E17: =E11-E16 -> 24867 | F17: =F11-F16 -> 23339
B18: Gross Margin | C18: % | D18: =D17/D11 -> 0.5701196 | E18: =E17/E11 -> 0.56153464 | F18: =F17/F11 -> 0.544058
B20: ='00 Panel del Analista'!B31 -> Ventas, generales y administración (SG&A) | C20: $M | D20: ='00 Panel del Analista'!D31 -> 2759 | E20: ='00 Panel del Analista'!E31 -> 3110 | F20: ='00 Panel del Analista'!F31 -> 3718
B21: ='00 Panel del Analista'!B32 -> Investigación y desarrollo | C21: $M | D21: ='00 Panel del Analista'!D32 -> 8893 | E21: ='00 Panel del Analista'!E32 -> 9042 | F21: ='00 Panel del Analista'!F32 -> 10143
B22: ='00 Panel del Analista'!B33 -> Generales y administración (incluido en SG&A) | C22: $M | D22: ='00 Panel del Analista'!D33 -> 0 | E22: ='00 Panel del Analista'!E33 -> 0 | F22: ='00 Panel del Analista'!F33 -> 0
B23: ='00 Panel del Analista'!B34 -> Amortización de intangibles adquiridos (reclasificada desde coste de ingresos) | C23: $M | D23: ='00 Panel del Analista'!D34 -> 311 | E23: ='00 Panel del Analista'!E34 -> 321 | F23: ='00 Panel del Analista'!F34 -> 331
B24: ='00 Panel del Analista'!B35 -> Otros gastos operativos (reestructuración, deterioros y otros) | C24: $M | D24: ='00 Panel del Analista'!D35 -> 179 | E24: ='00 Panel del Analista'!E35 -> 39 | F24: ='00 Panel del Analista'!F35 -> 97
B25: Gastos operativos totales | C25: $M | D25: =D16+SUM(D20:D24) -> 28891 | E25: =E16+SUM(E20:E24) -> 31929 | F25: =F16+SUM(F20:F24) -> 33848
B26: EBIT (resultado operativo) reportado | C26: $M | D26: =D11-D25 -> 10071 | E26: =E11-E25 -> 12355 | F26: =F11-F25 -> 9050
B27: EBIT Margin reportado | C27: % | D27: =D26/D11 -> 0.25848262 | E27: =E26/E11 -> 0.27899467 | F27: =F26/F11 -> 0.21096555
B29: Gasto por intereses | C29: $M | D29: ='00 Panel del Analista'!D40 -> 697 | E29: ='00 Panel del Analista'!E40 -> 664 | F29: ='00 Panel del Analista'!F40 -> 694
B30: Resultado no operativo, neto | C30: $M | D30: ='00 Panel del Analista'!D41 -> 962 | E30: ='00 Panel del Analista'!E41 -> 972 | F30: ='00 Panel del Analista'!F41 -> 1543
B31: Beneficio antes de impuestos | C31: $M | D31: =D26-D29+D30 -> 10336 | E31: =E26-E29+E30 -> 12663 | F31: =F26-F29+F30 -> 9899
B32: Impuesto sobre sociedades | C32: $M | D32: ='00 Panel del Analista'!D43 -> 226 | E32: ='00 Panel del Analista'!E43 -> 7122 | F32: ='00 Panel del Analista'!F43 -> -3904
B33: Tipo impositivo efectivo | C33: % | D33: =D32/D31 -> 0.021865325 | E33: =E32/E31 -> 0.56242597 | F33: =F32/F31 -> -0.39438327
B34: Beneficio neto | C34: $M | D34: =D31-D32 -> 10110 | E34: =E31-E32 -> 5541 | F34: =F31-F32 -> 13803
B35: Dividendos de acciones preferentes | C35: $M | D35: ='00 Panel del Analista'!D46 -> 0 | E35: ='00 Panel del Analista'!E46 -> 0 | F35: ='00 Panel del Analista'!F46 -> 0
B36: Beneficio neto atribuible a ordinarias | C36: $M | D36: =D34-D35 -> 10110 | E36: =E34-E35 -> 5541 | F36: =F34-F35 -> 13803
B37: BPA básico | C37: $/acc | D37: ='00 Panel del Analista'!D48 -> 9.06 | E37: ='00 Panel del Analista'!E48 -> 5.05 | F37: ='00 Panel del Analista'!F48 -> 12.960563
B38: BPA diluido | C38: $/acc | D38: ='00 Panel del Analista'!D49 -> 8.94 | E38: ='00 Panel del Analista'!E49 -> 5.01 | F38: ='00 Panel del Analista'!F49 -> 12.84
B39: Acciones medias básicas | C39: M acc | D39: ='00 Panel del Analista'!D50 -> 1116 | E39: ='00 Panel del Analista'!E50 -> 1096 | F39: ='00 Panel del Analista'!F50 -> 1065
B40: Acciones medias diluidas | C40: M acc | D40: ='00 Panel del Analista'!D51 -> 1130 | E40: ='00 Panel del Analista'!E51 -> 1105 | F40: ='00 Panel del Analista'!F51 -> 1075
B42: BALANCE (a cierre de ejercicio)
B43: Caja y equivalentes | C43: $M | E43: ='00 Panel del Analista'!E54 -> 7843 | F43: ='00 Panel del Analista'!F54 -> 4533
B44: Valores negociables | C44: $M | E44: ='00 Panel del Analista'!E55 -> 4635 | F44: ='00 Panel del Analista'!F55 -> 3771
B45: Clientes, neto | C45: $M | E45: ='00 Panel del Analista'!E56 -> 4315 | F45: ='00 Panel del Analista'!F56 -> 4668
B46: Gastos anticipados y otros activos corrientes | C46: $M | E46: ='00 Panel del Analista'!E57 -> 8961 | F46: ='00 Panel del Analista'!F57 -> 10032
...

Sheet 04 Operating Model
A1: MODELO OPERATIVO FY2027E–FY2036E — QUALCOMM INCORPORATED
A2: USD millones. Toda hipótesis procede de '02 Assumptions'. Esta hoja NO contiene hipótesis propias. Verde = enlace; negro = fórmula.
B4: Partida | C4: Unidad | D4: ='00 Panel del Analista'!D14 -> FY2024A | E4: ='00 Panel del Analista'!E14 -> FY2025A | F4: ='00 Panel del Analista'!F14 -> FY2026E | G4: ='00 Panel del Analista'!G14 -> FY2027E | H4: ='00 Panel del Analista'!H14 -> FY2028E | I4: ='00 Panel del Analista'!I14 -> FY2029E | J4: ='00 Panel del Analista'!J14 -> FY2030E | K4: ='00 Panel del Analista'!K14 -> FY2031E | ... P4: ='00 Panel del Analista'!P14 -> FY2036E
B6: INGRESOS POR SEGMENTO
B7: ='00 Panel del Analista'!B18 -> QCT IoT + Data Center y otros no reportables | C7: $M | D7: ='03 Historical'!D7 -> 5617 | E7: ='03 Historical'!E7 -> 6809 | F7: ='03 Historical'!F7 -> 7512 | G7: =F7*(1+'02 Assumptions'!G20) -> 12019.2 | H7: =G7*(1+'02 Assumptions'!H20) -> 15985.536 | I7: =H7*(1+'02 Assumptions'!I20) -> 19502.354 | J7: =I7*(1+'02 Assumptions'!J20) -> 22427.707 | K7: =J7*(1+'02 Assumptions'!K20) -> 25119.032 | L7: =K7*(1+'02 Assumptions'!L20) -> 27630.935 | M7: =L7*(1+'02 Assumptions'!M20) -> 29841.41 | N7: =M7*(1+'02 Assumptions'!N20) -> 31631.894 | ... P7: =O7*(1+'02 Assumptions'!P20) -> 34542.029
B8: ='00 Panel del Analista'!B19 -> QCT Handsets | C8: $M | D8: ='03 Historical'!D8 -> 24863 | E8: ='03 Historical'!E8 -> 27793 | F8: ='03 Historical'!F8 -> 24134 | G8: =F8*(1+'02 Assumptions'!G22) -> 20513.9 | H8: =G8*(1+'02 Assumptions'!H22) -> 20924.178 | I8: =H8*(1+'02 Assumptions'!I22) -> 21551.903 | J8: =I8*(1+'02 Assumptions'!J22) -> 21982.941 | K8: =J8*(1+'02 Assumptions'!K22) -> 22422.6 | L8: =K8*(1+'02 Assumptions'!L22) -> 22871.052 | M8: =L8*(1+'02 Assumptions'!M22) -> 23328.473 | N8: =M8*(1+'02 Assumptions'!N22) -> 23795.043 | ... P8: =O8*(1+'02 Assumptions'!P22) -> 24999.667
B9: ='00 Panel del Analista'!B20 -> QTL Licencias (incl. ingresos no asignados) | C9: $M | D9: ='03 Historical'!D9 -> 5572 | E9: ='03 Historical'!E9 -> 5725 | F9: ='03 Historical'!F9 -> 5552 | G9: =F9*(1+'02 Assumptions'!G24) -> 5440.96 | H9: =G9*(1+'02 Assumptions'!H24) -> 5332.1408 | I9: =H9*(1+'02 Assumptions'!I24) -> 5332.1408 | J9: =I9*(1+'02 Assumptions'!J24) -> 5385.4622 | K9: =J9*(1+'02 Assumptions'!K24) -> 5439.3168 | L9: =K9*(1+'02 Assumptions'!L24) -> 5493.71 | M9: =L9*(1+'02 Assumptions'!M24) -> 5576.1156 | N9: =M9*(1+'02 Assumptions'!N24) -> 5659.7574 | ... P9: =O9*(1+'02 Assumptions'!P24) -> 5888.4116
B10: ='00 Panel del Analista'!B21 -> QCT Automoción | C10: $M | D10: ='03 Historical'!D10 -> 2910 | E10: ='03 Historical'!E10 -> 3957 | F10: ='03 Historical'!F10 -> 5700 | G10: =F10*(1+'02 Assumptions'!G26) -> 6954 | H10: =G10*(1+'02 Assumptions'!H26) -> 8136.18 | I10: =H10*(1+'02 Assumptions'!I26) -> 9356.607 | J10: =I10*(1+'02 Assumptions'!J26) -> 10572.966 | K10: =J10*(1+'02 Assumptions'!K26) -> 11735.992 | L10: =K10*(1+'02 Assumptions'!L26) -> 12792.231 | M10: =L10*(1+'02 Assumptions'!M26) -> 13815.61 | N10: =M10*(1+'02 Assumptions'!N26) -> 14782.703 | ... P10: =O10*(1+'02 Assumptions'!P26) -> 16453.148
B11: INGRESOS TOTALES | C11: $M | D11: =SUM(D7:D10) -> 38962 | E11: =SUM(E7:E10) -> 44284 | F11: =SUM(F7:F10) -> 42898 | G11: =SUM(G7:G10) -> 44928.06 | H11: =SUM(H7:H10) -> 50378.035 | I11: =SUM(I7:I10) -> 55743.005 | J11: =SUM(J7:J10) -> 60369.077 | K11: =SUM(K7:K10) -> 64716.941 | ... P11: =SUM(P7:P10) -> 81883.255
B12: Crecimiento de ingresos | C12: % | E12: =E11/D11-1 -> 0.13659463 | F12: =F11/E11-1 -> -0.031297986 | G12: =G11/F11-1 -> 0.047322952 | H12: =H11/G11-1 -> 0.12130448 | I12: =I11/H11-1 -> 0.10649423 | J12: =J11/I11-1 -> 0.082989273 | K12: =K11/J11-1 -> 0.072021386 | L12: =L11/K11-1 -> 0.062904513 | ... P12: =P11/O11-1 -> 0.03589339
B13: Mix: IoT + Data Center / ingresos totales | C13: % | D13: =D7/D11 -> 0.14416611 | E13: =E7/E11 -> 0.15375756 | F13: =F7/F11 -> 0.17511306 | G13: =G7/G11 -> 0.26752101 | H13: =H7/H11 -> 0.31731162 | I13: =I7/I11 -> 0.3498619 | J13: =J7/J11 -> 0.37150986 | K13: =K7/K11 -> 0.38813688 | ... P13: =P7/P11 -> 0.42184484
B15: MARGEN BRUTO
B16: Gross Margin | C16: % | D16: ='03 Historical'!D18 -> 0.5701196 | E16: ='03 Historical'!E18 -> 0.56153464 | F16: ='03 Historical'!F18 -> 0.544058 | G16: ='02 Assumptions'!G30 -> 0.545 | H16: ='02 Assumptions'!H30 -> 0.55 | I16: ='02 Assumptions'!I30 -> 0.555 | J16: ='02 Assumptions'!J30 -> 0.555 | K16: ='02 Assumptions'!K30 -> 0.555 | L16: ='02 Assumptions'!L30 -> 0.555 | M16: ='02 Assumptions'!M30 -> 0.555 | N16: ='02 Assumptions'!N30 -> 0.555 | ... P16: ='02 Assumptions'!P30 -> 0.555
B17: Margen bruto (Gross Profit) | C17: $M | D17: ='03 Historical'!D17 -> 22213 | E17: ='03 Historical'!E17 -> 24867 | F17: ='03 Historical'!F17 -> 23339 | G17: =G11*G16 -> 24485.793 | H17: =H11*H16 -> 27707.919 | I17: =I11*I16 -> 30937.368 | J17: =J11*J16 -> 33504.837 | K17: =K11*K16 -> 35917.902 | L17: =L11*L16 -> 38177.3 | M17: =M11*M16 -> 40271.693 | N17: =N11*N16 -> 42107.515 | ... P17: =P11*P16 -> 45445.207
B18: Coste de los ingresos | C18: $M | D18: ='03 Historical'!D16 -> 16749 | E18: ='03 Historical'!E16 -> 19417 | F18: ='03 Historical'!F16 -> 19559 | G18: =G11-G17 -> 20442.267 | H18: =H11-H17 -> 22670.116 | I18: =I11-I17 -> 24805.637 | J18: =J11-J17 -> 26864.239 | K18: =K11-K17 -> 28799.039 | L18: =L11-L17 -> 30610.628 | M18: =M11-M17 -> 32289.916 | N18: =N11-N17 -> 33761.882 | ... P18: =P11-P17 -> 36438.049
B20: GASTOS OPERATIVOS (por debajo del margen bruto)
B21: ='00 Panel del Analista'!B31 -> Ventas, generales y administración (SG&A) | C21: $M | D21: ='03 Historical'!D20 -> 2759 | E21: ='03 Historical'!E20 -> 3110 | F21: ='03 Historical'!F20 -> 3718 | G21: =G11*'02 Assumptions'!G32 -> 3818.8851 | H21: =H11*'02 Assumptions'!H32 -> 4030.2428 | I21: =I11*'02 Assumptions'!I32 -> 4292.2114 | J21: =J11*'02 Assumptions'!J32 -> 4527.6807 | K21: =K11*'02 Assumptions'!K32 -> 4724.3367 | L21: =L11*'02 Assumptions'!L32 -> 4952.7309 | M21: =M11*'02 Assumptions'!M32 -> 5151.8742 | N21: =N11*'02 Assumptions'!N32 -> 5386.7272 | ... P21: =P11*'02 Assumptions'!P32 -> 5813.7111
B22: ='00 Panel del Analista'!B32 -> Investigación y desarrollo | C22: $M | D22: ='03 Historical'!D21 -> 8893 | E22: ='03 Historical'!E21 -> 9042 | F22: ='03 Historical'!F21 -> 10143 | G22: =G11*'02 Assumptions'!G34 -> 10558.094 | H22: =H11*'02 Assumptions'!H34 -> 11335.058 | I22: =I11*'02 Assumptions'!I34 -> 11984.746 | J22: =J11*'02 Assumptions'!J34 -> 12677.506 | K22: =K11*'02 Assumptions'!K34 -> 13396.407 | L22: =L11*'02 Assumptions'!L34 -> 14101.525 | M22: =M11*'02 Assumptions'!M34 -> 14875.13 | N22: =N11*'02 Assumptions'!N34 -> 15553.226 | ... P22: =P11*'02 Assumptions'!P34 -> 16786.067
B23: ='00 Panel del Analista'!B33 -> Generales y administración (incluido en SG&A) | C23: $M | D23: ='03 Historical'!D22 -> 0 | E23: ='03 Historical'!E22 -> 0 | F23: ='03 Historical'!F22 -> 0 | G23: =G11*'02 Assumptions'!G36 -> 0 | H23: =H11*'02 Assumptions'!H36 -> 0 | I23: =I11*'02 Assumptions'!I36 -> 0 | J23: =J11*'02 Assumptions'!J36 -> 0 | K23: =K11*'02 Assumptions'!K36 -> 0 | L23: =L11*'02 Assumptions'!L36 -> 0 | M23: =M11*'02 Assumptions'!M36 -> 0 | N23: =N11*'02 Assumptions'!N36 -> 0 | ... P23: =P11*'02 Assumptions'!P36 -> 0
B24: ='00 Panel del Analista'!B34 -> Amortización de intangibles adquiridos (reclasificada desde coste de ingresos) | C24: $M | D24: ='03 Historical'!D23 -> 311 | E24: ='03 Historical'!E23 -> 321 | F24: ='03 Historical'!F23 -> 331 | G24: ='02 Assumptions'!G37 -> 430 | H24: ='02 Assumptions'!H37 -> 350 | I24: ='02 Assumptions'!I37 -> 280 | J24: ='02 Assumptions'!J37 -> 210 | K24: ='02 Assumptions'!K37 -> 140 | L24: ='02 Assumptions'!L37 -> 100 | M24: ='02 Assumptions'!M37 -> 0 | N24: ='02 Assumptions'!N37 -> 0 | ... P24: ='02 Assumptions'!P37 -> 0
B25: ='00 Panel del Analista'!B35 -> Otros gastos operativos (reestructuración, deterioros y otros) | C25: $M | D25: ='03 Historical'!D24 -> 179 | E25: ='03 Historical'!E24 -> 39 | F25: ='03 Historical'!F24 -> 97 | G25: ='02 Assumptions'!G38 -> 100 | H25: ='02 Assumptions'!H38 -> 100 | I25: ='02 Assumptions'!I38 -> 100 | J25: ='02 Assumptions'!J38 -> 100 | K25: ='02 Assumptions'!K38 -> 100 | L25: ='02 Assumptions'!L38 -> 100 | M25: ='02 Assumptions'!M38 -> 100 | N25: ='02 Assumptions'!N38 -> 100 | ... P25: ='02 Assumptions'!P38 -> 100
B26: Total gastos operativos | C26: $M | D26: =SUM(D21:D25) -> 12142 | E26: =SUM(E21:E25) -> 12512 | F26: =SUM(F21:F25) -> 14289 | G26: =SUM(G21:G25) -> 14906.979 | H26: =SUM(H21:H25) -> 15815.301 | I26: =SUM(I21:I25) -> 16656.957 | J26: =SUM(J21:J25) -> 17515.187 | K26: =SUM(K21:K25) -> 18360.744 | ... P26: =SUM(P21:P25) -> 22699.778
B27: EBIT reportado | C27: $M | D27: =D17-D26 -> 10071 | E27: =E17-E26 -> 12355 | F27: =F17-F26 -> 9050 | G27: =G17-G26 -> 9578.8135 | H27: =H17-H26 -> 11892.619 | I27: =I17-I26 -> 14280.41 | J27: =J17-J26 -> 15989.651 | K27: =K17-K26 -> 17557.159 | ... P27: =P17-P26 -> 22745.428
B28: EBIT Margin reportado | C28: % | D28: =D27/D11 -> 0.25848262 | E28: =E27/E11 -> 0.27899467 | F28: =F27/F11 -> 0.21096555 | G28: =G27/G11 -> 0.21320336 | H28: =H27/H11 -> 0.23606754 | I28: =I27/I11 -> 0.256183 | J28: =J27/J11 -> 0.26486492 | K28: =K27/K11 -> 0.27129154 | ... P28: =P27/P11 -> 0.27777875
B29: EBIT NORMALIZADO (excluye reestructuración) | C29: $M | D29: =D27+D25 -> 10250 | E29: =E27+E25 -> 12394 | F29: =F27+F25 -> 9147 | G29: =G27+G25 -> 9678.8135 | H29: =H27+H25 -> 11992.619 | I29: =I27+I25 -> 14380.41 | J29: =J27+J25 -> 16089.651 | K29: =K27+K25 -> 17657.159 | ... P29: =P27+P25 -> 22845.428
B30: Margen EBIT normalizado | C30: % | D30: =D29/D11 -> 0.26307684 | E30: =E29/E11 -> 0.27987535 | F30: =F29/F11 -> 0.21322672 | G30: =G29/G11 -> 0.21542914 | H30: =H29/H11 -> 0.23805253 | I30: =I29/I11 -> 0.25797695 | J30: =J29/J11 -> 0.2665214 | K30: =K29/K11 -> 0.27283673 | ... P30: =P29/P11 -> 0.279
B32: CAPEX Y DEPRECIACIÓN — ROLL-FORWARD DE PP&E
B33: PP&E neto inicial | C33: $M | F33: ='03 Historical'!E48 -> 4690 | G33: =F37 -> 5217 | H33: =G37 -> 5854.7891 | I33: =H37 -> 6255.3829 | J33: =I37 -> 6549.9753 | K33: =J37 -> 6704.2673 | L33: =K37 -> 6940.2152 | M33: =L37 -> 7232.2899 | N33: =M37 -> 7560.0906 | ... P33: =O37 -> 8254.8697
B34: Capex | C34: $M | D34: ='03 Historical'!D129 -> 1041 | E34: ='03 Historical'!E129 -> 1192 | F34: ='03 Historical'!F129 -> 2104 | G34: =G11*'02 Assumptions'!G42 -> 2021.7627 | H34: =H11*'02 Assumptions'!H42 -> 1914.3653 | I34: =I11*'02 Assumptions'!I42 -> 1895.2622 | J34: =J11*'02 Assumptions'!J42 -> 1811.0723 | K34: =K11*'02 Assumptions'!K42 -> 1941.5082 | L34: =L11*'02 Assumptions'!L42 -> 2063.6379 | M34: =M11*'02 Assumptions'!M42 -> 2176.8483 | N34: =N11*'02 Assumptions'!N42 -> 2276.0819 | ... P34: =P11*'02 Assumptions'!P42 -> 2456.4977
B35: Capex / Ingresos | C35: % | D35: =D34/D11 -> 0.026718341 | E35: =E34/E11 -> 0.026917171 | F35: =F34/F11 -> 0.049046576 | G35: =G34/G11 -> 0.045 | H35: =H34/H11 -> 0.038 | I35: =I34/I11 -> 0.034 | J35: =J34/J11 -> 0.03 | K35: =K34/K11 -> 0.03 | ... P35: =P34/P11 -> 0.03
B36: Depreciación = (PP&E inicial + Capex/2) / vida útil | C36: $M | D36: ='03 Historical'!D79 -> 1395 | E36: ='03 Historical'!E79 -> 1281 | F36: ='03 Historical'!F79 -> 1271.6667 | G36: =(G33+G34/2)/'02 Assumptions'!$C$43 -> 1383.9736 | H36: =(H33+H34/2)/'02 Assumptions'!$C$43 -> 1513.7715 | I36: =(I33+I34/2)/'02 Assumptions'!$C$43 -> 1600.6698 | J36: =(J33+J34/2)/'02 Assumptions'!$C$43 -> 1656.7803 | K36: =(K33+K34/2)/'02 Assumptions'!$C$43 -> 1705.5603 | L36: =(L33+L34/2)/'02 Assumptions'!$C$43 -> 1771.5631 | M36: =(M33+M34/2)/'02 Assumptions'!$C$43 -> 1849.0476 | N36: =(N33+N34/2)/'02 Assumptions'!$C$43 -> 1932.9181 | ... P36: =(P33+P34/2)/'02 Assumptions'!$C$43 -> 2107.3597
B37: PP&E neto final | C37: $M | E37: ='03 Historical'!E48 -> 4690 | F37: ='03 Historical'!F48 -> 5217 | G37: =G33+G34-G36 -> 5854.7891 | H37: =H33+H34-H36 -> 6255.3829 | I37: =I33+I34-I36 -> 6549.9753 | J37: =J33+J34-J36 -> 6704.2673 | K37: =K33+K34-K36 -> 6940.2152 | L37: =L33+L34-L36 -> 7232.2899 | M37: =M33+M34-M36 -> 7560.0906 | N37: =N33+N34-N36 -> 7903.2544 | ... P37: =P33+P34-P36 -> 8604.0076
B38: D&A total (depreciación + amortización de intangibles) | C38: $M | D38: =D36+D24 -> 1706 | E38: =E36+E24 -> 1602 | F38: =F36+F24 -> 1602.6667 | G38: =G36+G24 -> 1813.9736 | H38: =H36+H24 -> 1863.7715 | I38: =I36+I24 -> 1880.6698 | J38: =J36+J24 -> 1866.7803 | K38: =K36+K24 -> 1845.5603 | ... P38: =P36+P24 -> 2107.3597
B39: EBITDA (EBIT normalizado + D&A) | C39: $M | D39: =D29+D38 -> 11956 | E39: =E29+E38 -> 13996 | F39: =F29+F38 -> 10749.667 | G39: =G29+G38 -> 11492.787 | H39: =H29+H38 -> 13856.39 | I39: =I29+I38 -> 16261.08 | J39: =J29+J38 -> 17956.431 | K39: =K29+K38 -> 19502.719 | ... P39: =P29+P38 -> 24952.788
B40: EBITDA Margin | C40: % | D40: =D39/D11 -> 0.3068631 | E40: =E39/E11 -> 0.31605094 | F40: =F39/F11 -> 0.25058666 | G40: =G39/G11 -> 0.25580422 | H40: =H39/H11 -> 0.27504824 | I40: =I39/I11 -> 0.29171517 | J40: =J39/J11 -> 0.29744419 | K40: =K39/K11 -> 0.30135416 | ... P40: =P39/P11 -> 0.30473615
B41: Capex / D&A | C41: x | D41: =D34/D38 -> 0.6101993 | E41: =E34/E38 -> 0.74406991 | F41: =F34/F38 -> 1.312812 | G41: =G34/G38 -> 1.1145491 | H41: =H34/H38 -> 1.0271459 | I41: =I34/I38 -> 1.0077591 | J41: =J34/J38 -> 0.97015823 | K41: =K34/K38 -> 1.0519885 | ... P41: =P34/P38 -> 1.1656756
B43: CIRCULANTE OPERATIVO (drivers: DSO, proveedores sobre coste+capex, ingresos diferidos)
B44: Clientes (AR) | C44: $M | E44: ='03 Historical'!E45 -> 4315 | F44: ='03 Historical'!F45 -> 4668 | G44: ='02 Assumptions'!G48/365*G11 -> 4677.4419 | H44: ='02 Assumptions'!H48/365*H11 -> 5244.8365 | I44: ='02 Assumptions'!I48/365*I11 -> 5803.3813 | J44: ='02 Assumptions'!J48/365*J11 -> 6284.9997 | K44: ='02 Assumptions'!K48/365*K11 -> 6737.6541 | L44: ='02 Assumptions'!L48/365*L11 -> 7161.483 | M44: ='02 Assumptions'!M48/365*M11 -> 7554.3593 | N44: ='02 Assumptions'!N48/365*N11 -> 7898.7318 | ... P44: ='02 Assumptions'!P48/365*P11 -> 8524.832
B45: Inventarios y otros activos corrientes | C45: $M | E45: ='03 Historical'!E46 -> 8961 | F45: ='03 Historical'!F46 -> 10032 | G45: =G11*'02 Assumptions'!G51 -> 9434.8926 | H45: =H11*'02 Assumptions'!H51 -> 10075.607 | I45: =I11*'02 Assumptions'!I51 -> 11148.601 | J45: =J11*'02 Assumptions'!J51 -> 12073.815 | K45: =K11*'02 Assumptions'!K51 -> 12943.388 | L45: =L11*'02 Assumptions'!L51 -> 13757.586 | M45: =M11*'02 Assumptions'!M51 -> 14512.322 | N45: =N11*'02 Assumptions'!N51 -> 15173.879 | ... P45: =P11*'02 Assumptions'!P51 -> 16376.651
B46: Proveedores | C46: $M | E46: ='03 Historical'!E57 -> 2791 | F46: ='03 Historical'!F57 -> 2897 | G46: =(G18+G34)*'02 Assumptions'!G49 -> 3010.18 | H46: =(H18+H34)*'02 Assumptions'!H49 -> 3294.3205 | I46: =(I18+I34)*'02 Assumptions'!I49 -> 3577.9205 | J46: =(J18+J34)*'02 Assumptions'!J49 -> 3842.4917 | K46: =(K18+K34)*'02 Assumptions'!K49 -> 4119.2333 | L46: =(L18+L34)*'02 Assumptions'!L49 -> 4378.3517 | M46: =(M18+M34)*'02 Assumptions'!M49 -> 4618.5464 | N46: =(N18+N34)*'02 Assumptions'!N49 -> 4829.0871 | ... P46: =(P18+P34)*'02 Assumptions'!P49 -> 5211.8692
...

Sheet 05 Three Statement
A1: MODELO DE TRES ESTADOS INTEGRADO FY2027E–FY2036E — QUALCOMM INCORPORATED
A2: Sirve para verificar la CONSISTENCIA CONTABLE del forecast (cuadre de balance y de caja). NO alimenta el DCF: el DCF es un FCFF construido sobre '04 Operating Model'.
B4: Partida | C4: Unidad | D4: ='00 Panel del Analista'!D14 -> FY2024A | E4: ='00 Panel del Analista'!E14 -> FY2025A | F4: ='00 Panel del Analista'!F14 -> FY2026E | G4: ='00 Panel del Analista'!G14 -> FY2027E | H4: ='00 Panel del Analista'!H14 -> FY2028E | I4: ='00 Panel del Analista'!I14 -> FY2029E | J4: ='00 Panel del Analista'!J14 -> FY2030E | K4: ='00 Panel del Analista'!K14 -> FY2031E | ... P4: ='00 Panel del Analista'!P14 -> FY2036E
B6: CUENTA DE RESULTADOS
B7: Ingresos | C7: $M | G7: ='04 Operating Model'!G11 -> 44928.06 | H7: ='04 Operating Model'!H11 -> 50378.035 | I7: ='04 Operating Model'!I11 -> 55743.005 | J7: ='04 Operating Model'!J11 -> 60369.077 | K7: ='04 Operating Model'!K11 -> 64716.941 | L7: ='04 Operating Model'!L11 -> 68787.929 | M7: ='04 Operating Model'!M11 -> 72561.609 | N7: ='04 Operating Model'!N11 -> 75869.397 | ... P7: ='04 Operating Model'!P11 -> 81883.255
B8: Coste de los ingresos | C8: $M | G8: ='04 Operating Model'!G18 -> 20442.267 | H8: ='04 Operating Model'!H18 -> 22670.116 | I8: ='04 Operating Model'!I18 -> 24805.637 | J8: ='04 Operating Model'!J18 -> 26864.239 | K8: ='04 Operating Model'!K18 -> 28799.039 | L8: ='04 Operating Model'!L18 -> 30610.628 | M8: ='04 Operating Model'!M18 -> 32289.916 | N8: ='04 Operating Model'!N18 -> 33761.882 | ... P8: ='04 Operating Model'!P18 -> 36438.049
B9: Margen bruto | C9: $M | G9: =G7-G8 -> 24485.793 | H9: =H7-H8 -> 27707.919 | I9: =I7-I8 -> 30937.368 | J9: =J7-J8 -> 33504.837 | K9: =K7-K8 -> 35917.902 | L9: =L7-L8 -> 38177.3 | M9: =M7-M8 -> 40271.693 | N9: =N7-N8 -> 42107.515 | ... P9: =P7-P8 -> 45445.207
B10: Gastos operativos | C10: $M | G10: ='04 Operating Model'!G26 -> 14906.979 | H10: ='04 Operating Model'!H26 -> 15815.301 | I10: ='04 Operating Model'!I26 -> 16656.957 | J10: ='04 Operating Model'!J26 -> 17515.187 | K10: ='04 Operating Model'!K26 -> 18360.744 | L10: ='04 Operating Model'!L26 -> 19254.256 | M10: ='04 Operating Model'!M26 -> 20127.004 | N10: ='04 Operating Model'!N26 -> 21039.954 | ... P10: ='04 Operating Model'!P26 -> 22699.778
B11: EBIT reportado | C11: $M | G11: =G9-G10 -> 9578.8135 | H11: =H9-H10 -> 11892.619 | I11: =I9-I10 -> 14280.41 | J11: =J9-J10 -> 15989.651 | K11: =K9-K10 -> 17557.159 | L11: =L9-L10 -> 18923.044 | M11: =M9-M10 -> 20144.689 | N11: =N9-N10 -> 21067.562 | ... P11: =P9-P10 -> 22745.428
B12: (−) Gasto por intereses | C12: $M | G12: =G26 -> 687.15 | H12: =H26 -> 540.86704 | I12: =I26 -> 381.58908 | J12: =J26 -> 175.87719 | K12: =K26 -> 0 | L12: =L26 -> 0 | M12: =M26 -> 0 | N12: =N26 -> 0 | ... P12: =P26 -> 0
B13: (+) Resultado no operativo, neto (no proyectado) | C13: $M | G13: =0 -> 0 | H13: =0 -> 0 | I13: =0 -> 0 | J13: =0 -> 0 | K13: =0 -> 0 | L13: =0 -> 0 | M13: =0 -> 0 | N13: =0 -> 0 | ... P13: =0 -> 0
B14: Beneficio antes de impuestos | C14: $M | G14: =G11-G12+G13 -> 8891.6635 | H14: =H11-H12+H13 -> 11351.751 | I14: =I11-I12+I13 -> 13898.821 | J14: =J11-J12+J13 -> 15813.773 | K14: =K11-K12+K13 -> 17557.159 | L14: =L11-L12+L13 -> 18923.044 | M14: =M11-M12+M13 -> 20144.689 | N14: =N11-N12+N13 -> 21067.562 | ... P14: =P11-P12+P13 -> 22745.428
B15: (−) Impuestos | C15: $M | G15: =G14*'04 Operating Model'!G55 -> 1244.8329 | H15: =H14*'04 Operating Model'!H55 -> 1646.004 | I15: =I14*'04 Operating Model'!I55 -> 2084.8232 | J15: =J14*'04 Operating Model'!J55 -> 2451.1349 | K15: =K14*'04 Operating Model'!K55 -> 2809.1454 | L15: =L14*'04 Operating Model'!L55 -> 3122.3023 | M15: =M14*'04 Operating Model'!M55 -> 3424.5971 | N15: =N14*'04 Operating Model'!N55 -> 3581.4855 | ... P15: =P14*'04 Operating Model'!P55 -> 3866.7228
B16: BENEFICIO NETO | C16: $M | G16: =G14-G15 -> 7646.8306 | H16: =H14-H15 -> 9705.7475 | I16: =I14-I15 -> 11813.998 | J16: =J14-J15 -> 13362.639 | K16: =K14-K15 -> 14748.013 | L16: =L14-L15 -> 15800.742 | M16: =M14-M15 -> 16720.092 | N16: =N14-N15 -> 17486.076 | ... P16: =P14-P15 -> 18878.705
B17: (−) Dividendos de preferentes | C17: $M | G17: =G93 -> 0 | H17: =H93 -> 0 | I17: =I93 -> 0 | J17: =J93 -> 0 | K17: =K93 -> 0 | L17: =L93 -> 0 | M17: =M93 -> 0 | N17: =N93 -> 0 | ... P17: =P93 -> 0
B18: Beneficio atribuible a ordinarias | C18: $M | G18: =G16-G17 -> 7646.8306 | H18: =H16-H17 -> 9705.7475 | I18: =I16-I17 -> 11813.998 | J18: =J16-J17 -> 13362.639 | K18: =K16-K17 -> 14748.013 | L18: =L16-L17 -> 15800.742 | M18: =M16-M17 -> 16720.092 | N18: =N16-N17 -> 17486.076 | ... P18: =P16-P17 -> 18878.705
B20: ESQUEMA DE DEUDA (interés sobre deuda inicial: sin circularidad)
B21: Deuda inicial | C21: $M | G21: =F24 -> 15270 | H21: =G24 -> 12019.268 | I21: =H24 -> 8479.7573 | J21: =I24 -> 3908.3819 | K21: =J24 -> 0 | L21: =K24 -> 0 | M21: =L24 -> 0 | N21: =M24 -> 0 | ... P21: =O24 -> 0
B22: (+) Nueva deuda emitida | C22: $M | G22: =G32 -> 0 | H22: =H32 -> 0 | I22: =I32 -> 0 | J22: =J32 -> 0 | K22: =K32 -> 0 | L22: =L32 -> 0 | M22: =M32 -> 0 | N22: =N32 -> 0 | ... P22: =P32 -> 0
B23: (−) Repago de deuda | C23: $M | G23: =G34 -> 3250.7325 | H23: =H34 -> 3539.5103 | I23: =I34 -> 4571.3753 | J23: =J34 -> 3908.3819 | K23: =K34 -> 0 | L23: =L34 -> 0 | M23: =M34 -> 0 | N23: =N34 -> 0 | ... P23: =P34 -> 0
B24: Deuda final | C24: $M | F24: ='02 Assumptions'!$C$70 -> 15270 | G24: =G21+G22-G23 -> 12019.268 | H24: =H21+H22-H23 -> 8479.7573 | I24: =I21+I22-I23 -> 3908.3819 | J24: =J21+J22-J23 -> 0 | K24: =K21+K22-K23 -> 0 | L24: =L21+L22-L23 -> 0 | M24: =M21+M22-M23 -> 0 | N24: =N21+N22-N23 -> 0 | ... P24: =P21+P22-P23 -> 0
B25: Tipo de interés medio | C25: % | G25: ='02 Assumptions'!$C$98 -> 0.045 | H25: ='02 Assumptions'!$C$98 -> 0.045 | I25: ='02 Assumptions'!$C$98 -> 0.045 | J25: ='02 Assumptions'!$C$98 -> 0.045 | K25: ='02 Assumptions'!$C$98 -> 0.045 | L25: ='02 Assumptions'!$C$98 -> 0.045 | M25: ='02 Assumptions'!$C$98 -> 0.045 | N25: ='02 Assumptions'!$C$98 -> 0.045 | ... P25: ='02 Assumptions'!$C$98 -> 0.045
B26: Gasto por intereses = deuda inicial × tipo | C26: $M | G26: =G21*G25 -> 687.15 | H26: =H21*H25 -> 540.86704 | I26: =I21*I25 -> 381.58908 | J26: =J21*J25 -> 175.87719 | K26: =K21*K25 -> 0 | L26: =L21*L25 -> 0 | M26: =M21*M25 -> 0 | N26: =N21*N25 -> 0 | ... P26: =P21*P25 -> 0
B28: POLÍTICA DE FINANCIACIÓN (determina caja y deuda)
B29: Caja inicial | C29: $M | G29: =F35 -> 4533 | H29: =G35 -> 4149.2937 | I29: =H35 -> 4547.071 | J29: =I35 -> 5686.2355 | K29: =J35 -> 9190.9367 | L29: =K35 -> 17829.98 | M29: =L35 -> 27409.971 | N29: =M35 -> 37720.633 | ... P29: =O35 -> 60251.269
B30: Caja preliminar = inicial + CFO + CFI − dividendos − recompras | C30: $M | G30: =G29+G77+G79-G82-G83-G84 -> 7400.0261 | H30: =H29+H77+H79-H82-H83-H84 -> 8086.5812 | I30: =I29+I77+I79-I82-I83-I84 -> 10257.611 | J30: =J29+J77+J79-J82-J83-J84 -> 13099.319 | K30: =K29+K77+K79-K82-K83-K84 -> 17829.98 | L30: =L29+L77+L79-L82-L83-L84 -> 27409.971 | M30: =M29+M77+M79-M82-M83-M84 -> 37720.633 | N30: =N29+N77+N79-N82-N83-N84 -> 48695.916 | ... P30: =P29+P77+P79-P82-P83-P84 -> 72216.535
B31: Caja mínima requerida | C31: $M | G31: ='02 Assumptions'!$C$68*G7 -> 898.5612 | H31: ='02 Assumptions'!$C$68*H7 -> 1007.5607 | I31: ='02 Assumptions'!$C$68*I7 -> 1114.8601 | J31: ='02 Assumptions'!$C$68*J7 -> 1207.3815 | K31: ='02 Assumptions'!$C$68*K7 -> 1294.3388 | L31: ='02 Assumptions'!$C$68*L7 -> 1375.7586 | M31: ='02 Assumptions'!$C$68*M7 -> 1451.2322 | N31: ='02 Assumptions'!$C$68*N7 -> 1517.3879 | ... P31: ='02 Assumptions'!$C$68*P7 -> 1637.6651
B32: Nueva deuda necesaria = MAX(0; mínima − preliminar) | C32: $M | G32: =MAX(0,G31-G30) -> 0 | H32: =MAX(0,H31-H30) -> 0 | I32: =MAX(0,I31-I30) -> 0 | J32: =MAX(0,J31-J30) -> 0 | K32: =MAX(0,K31-K30) -> 0 | L32: =MAX(0,L31-L30) -> 0 | M32: =MAX(0,M31-M30) -> 0 | N32: =MAX(0,N31-N30) -> 0 | ... P32: =MAX(0,P31-P30) -> 0
B33: Excedente sobre la caja mínima | C33: $M | G33: =MAX(0,G30-G31) -> 6501.4649 | H33: =MAX(0,H30-H31) -> 7079.0205 | I33: =MAX(0,I30-I31) -> 9142.7507 | J33: =MAX(0,J30-J31) -> 11891.937 | K33: =MAX(0,K30-K31) -> 16535.641 | L33: =MAX(0,L30-L31) -> 26034.212 | M33: =MAX(0,M30-M31) -> 36269.401 | N33: =MAX(0,N30-N31) -> 47178.528 | ... P33: =MAX(0,P30-P31) -> 70578.87
B34: Repago efectivo = MIN(deuda inicial; excedente × %) | C34: $M | G34: =MIN(G21,G33*'02 Assumptions'!$C$97) -> 3250.7325 | H34: =MIN(H21,H33*'02 Assumptions'!$C$97) -> 3539.5103 | I34: =MIN(I21,I33*'02 Assumptions'!$C$97) -> 4571.3753 | J34: =MIN(J21,J33*'02 Assumptions'!$C$97) -> 3908.3819 | K34: =MIN(K21,K33*'02 Assumptions'!$C$97) -> 0 | L34: =MIN(L21,L33*'02 Assumptions'!$C$97) -> 0 | M34: =MIN(M21,M33*'02 Assumptions'!$C$97) -> 0 | N34: =MIN(N21,N33*'02 Assumptions'!$C$97) -> 0 | ... P34: =MIN(P21,P33*'02 Assumptions'!$C$97) -> 0
B35: Caja final | C35: $M | F35: ='02 Assumptions'!$C$72 -> 4533 | G35: =G30+G32-G34 -> 4149.2937 | H35: =H30+H32-H34 -> 4547.071 | I35: =I30+I32-I34 -> 5686.2355 | J35: =J30+J32-J34 -> 9190.9367 | K35: =K30+K32-K34 -> 17829.98 | L35: =L30+L32-L34 -> 27409.971 | M35: =M30+M32-M34 -> 37720.633 | N35: =N30+N32-N34 -> 48695.916 | ... P35: =P30+P32-P34 -> 72216.535
B37: BALANCE
B38: Caja y equivalentes | C38: $M | G38: =G35 -> 4149.2937 | H38: =H35 -> 4547.071 | I38: =I35 -> 5686.2355 | J38: =J35 -> 9190.9367 | K38: =K35 -> 17829.98 | L38: =L35 -> 27409.971 | M38: =M35 -> 37720.633 | N38: =N35 -> 48695.916 | ... P38: =P35 -> 72216.535
B39: Valores negociables | C39: $M | G39: ='02 Assumptions'!$C$73 -> 3771 | H39: ='02 Assumptions'!$C$73 -> 3771 | I39: ='02 Assumptions'!$C$73 -> 3771 | J39: ='02 Assumptions'!$C$73 -> 3771 | K39: ='02 Assumptions'!$C$73 -> 3771 | L39: ='02 Assumptions'!$C$73 -> 3771 | M39: ='02 Assumptions'!$C$73 -> 3771 | N39: ='02 Assumptions'!$C$73 -> 3771 | ... P39: ='02 Assumptions'!$C$73 -> 3771
B40: Clientes (AR) | C40: $M | G40: ='04 Operating Model'!G44 -> 4677.4419 | H40: ='04 Operating Model'!H44 -> 5244.8365 | I40: ='04 Operating Model'!I44 -> 5803.3813 | J40: ='04 Operating Model'!J44 -> 6284.9997 | K40: ='04 Operating Model'!K44 -> 6737.6541 | L40: ='04 Operating Model'!L44 -> 7161.483 | M40: ='04 Operating Model'!M44 -> 7554.3593 | N40: ='04 Operating Model'!N44 -> 7898.7318 | ... P40: ='04 Operating Model'!P44 -> 8524.832
B41: Otros activos corrientes | C41: $M | G41: ='04 Operating Model'!G45 -> 9434.8926 | H41: ='04 Operating Model'!H45 -> 10075.607 | I41: ='04 Operating Model'!I45 -> 11148.601 | J41: ='04 Operating Model'!J45 -> 12073.815 | K41: ='04 Operating Model'!K45 -> 12943.388 | L41: ='04 Operating Model'!L45 -> 13757.586 | M41: ='04 Operating Model'!M45 -> 14512.322 | N41: ='04 Operating Model'!N45 -> 15173.879 | ... P41: ='04 Operating Model'!P45 -> 16376.651
B42: PP&E neto | C42: $M | G42: ='04 Operating Model'!G37 -> 5854.7891 | H42: ='04 Operating Model'!H37 -> 6255.3829 | I42: ='04 Operating Model'!I37 -> 6549.9753 | J42: ='04 Operating Model'!J37 -> 6704.2673 | K42: ='04 Operating Model'!K37 -> 6940.2152 | L42: ='04 Operating Model'!L37 -> 7232.2899 | M42: ='04 Operating Model'!M37 -> 7560.0906 | N42: ='04 Operating Model'!N37 -> 7903.2544 | ... P42: ='04 Operating Model'!P37 -> 8604.0076
B43: ROU — leases operativos | C43: $M | G43: ='03 Historical'!$F$49 -> 735 | H43: ='03 Historical'!$F$49 -> 735 | I43: ='03 Historical'!$F$49 -> 735 | J43: ='03 Historical'!$F$49 -> 735 | K43: ='03 Historical'!$F$49 -> 735 | L43: ='03 Historical'!$F$49 -> 735 | M43: ='03 Historical'!$F$49 -> 735 | N43: ='03 Historical'!$F$49 -> 735 | ... P43: ='03 Historical'!$F$49 -> 735
B44: Fondo de comercio | C44: $M | G44: ='03 Historical'!$F$50 -> 14274 | H44: ='03 Historical'!$F$50 -> 14274 | I44: ='03 Historical'!$F$50 -> 14274 | J44: ='03 Historical'!$F$50 -> 14274 | K44: ='03 Historical'!$F$50 -> 14274 | L44: ='03 Historical'!$F$50 -> 14274 | M44: ='03 Historical'!$F$50 -> 14274 | N44: ='03 Historical'!$F$50 -> 14274 | ... P44: ='03 Historical'!$F$50 -> 14274
B45: Intangibles adquiridos, neto | C45: $M | F45: ='02 Assumptions'!$C$101 -> 1510 | G45: =F45-'04 Operating Model'!G24 -> 1080 | H45: =G45-'04 Operating Model'!H24 -> 730 | I45: =H45-'04 Operating Model'!I24 -> 450 | J45: =I45-'04 Operating Model'!J24 -> 240 | K45: =J45-'04 Operating Model'!K24 -> 100 | L45: =K45-'04 Operating Model'!L24 -> 0 | M45: =L45-'04 Operating Model'!M24 -> 0 | N45: =M45-'04 Operating Model'!N24 -> 0 | ... P45: =O45-'04 Operating Model'!P24 -> 0
...

Sheet 06 DCF
A1: DCF — FREE CASH FLOW TO FIRM — QUALCOMM INCORPORATED (QCOM) | R1: =1+1 -> 2
A2: USD millones. FCFF descontado al WACC. Ningún resultado está introducido a mano: todo se calcula desde '02 Assumptions', '04 Operating Model' y '07 WACC'.
B4: Partida | C4: Unidad | D4: ='00 Panel del Analista'!D14 -> FY2024A | E4: ='00 Panel del Analista'!E14 -> FY2025A | F4: ='00 Panel del Analista'!F14 -> FY2026E | G4: ='00 Panel del Analista'!G14 -> FY2027E | H4: ='00 Panel del Analista'!H14 -> FY2028E | I4: ='00 Panel del Analista'!I14 -> FY2029E | J4: ='00 Panel del Analista'!J14 -> FY2030E | K4: ='00 Panel del Analista'!K14 -> FY2031E | ... P4: ='00 Panel del Analista'!P14 -> FY2036E
B6: CÁLCULO DEL FREE CASH FLOW TO FIRM (FCFF)
B7: EBIT normalizado | C7: $M | D7: ='04 Operating Model'!D29 -> 10250 | E7: ='04 Operating Model'!E29 -> 12394 | F7: ='04 Operating Model'!F29 -> 9147 | G7: ='04 Operating Model'!G29 -> 9678.8135 | H7: ='04 Operating Model'!H29 -> 11992.619 | I7: ='04 Operating Model'!I29 -> 14380.41 | J7: ='04 Operating Model'!J29 -> 16089.651 | K7: ='04 Operating Model'!K29 -> 17657.159 | ... P7: ='04 Operating Model'!P29 -> 22845.428
B8: Tipo impositivo de caja | C8: % | G8: ='04 Operating Model'!G55 -> 0.14 | H8: ='04 Operating Model'!H55 -> 0.145 | I8: ='04 Operating Model'!I55 -> 0.15 | J8: ='04 Operating Model'!J55 -> 0.155 | K8: ='04 Operating Model'!K55 -> 0.16 | L8: ='04 Operating Model'!L55 -> 0.165 | M8: ='04 Operating Model'!M55 -> 0.17 | N8: ='04 Operating Model'!N55 -> 0.17 | ... P8: ='04 Operating Model'!P55 -> 0.17
B9: (−) Impuestos sobre el EBIT normalizado | C9: $M | G9: =-G7*G8 -> -1355.0339 | H9: =-H7*H8 -> -1738.9297 | I9: =-I7*I8 -> -2157.0615 | J9: =-J7*J8 -> -2493.8959 | K9: =-K7*K8 -> -2825.1454 | L9: =-L7*L8 -> -3138.8023 | M9: =-M7*M8 -> -3441.5971 | N9: =-N7*N8 -> -3598.4855 | ... P9: =-P7*P8 -> -3883.7228
B10: NOPAT | C10: $M | G10: =G7+G9 -> 8323.7796 | H10: =H7+H9 -> 10253.689 | I10: =I7+I9 -> 12223.349 | J10: =J7+J9 -> 13595.755 | K10: =K7+K9 -> 14832.013 | L10: =L7+L9 -> 15884.242 | M10: =M7+M9 -> 16803.092 | N10: =N7+N9 -> 17569.076 | ... P10: =P7+P9 -> 18961.705
B11: (+) D&A | C11: $M | G11: ='04 Operating Model'!G38 -> 1813.9736 | H11: ='04 Operating Model'!H38 -> 1863.7715 | I11: ='04 Operating Model'!I38 -> 1880.6698 | J11: ='04 Operating Model'!J38 -> 1866.7803 | K11: ='04 Operating Model'!K38 -> 1845.5603 | L11: ='04 Operating Model'!L38 -> 1871.5631 | M11: ='04 Operating Model'!M38 -> 1849.0476 | N11: ='04 Operating Model'!N38 -> 1932.9181 | ... P11: ='04 Operating Model'!P38 -> 2107.3597
B12: (−) Capex | C12: $M | G12: =-'04 Operating Model'!G34 -> -2021.7627 | H12: =-'04 Operating Model'!H34 -> -1914.3653 | I12: =-'04 Operating Model'!I34 -> -1895.2622 | J12: =-'04 Operating Model'!J34 -> -1811.0723 | K12: =-'04 Operating Model'!K34 -> -1941.5082 | L12: =-'04 Operating Model'!L34 -> -2063.6379 | M12: =-'04 Operating Model'!M34 -> -2176.8483 | N12: =-'04 Operating Model'!N34 -> -2276.0819 | ... P12: =-'04 Operating Model'!P34 -> -2456.4977
B13: (−) Variación del capital circulante neto | C13: $M | G13: =-'04 Operating Model'!G51 -> 1053.6301 | H13: =-'04 Operating Model'!H51 -> -150.07214 | I13: =-'04 Operating Model'!I51 -> -586.11305 | J13: =-'04 Operating Model'!J51 -> -485.35935 | K13: =-'04 Operating Model'!K51 -> -428.08896 | L13: =-'04 Operating Model'!L51 -> -400.82777 | M13: =-'04 Operating Model'!M51 -> -371.55498 | N13: =-'04 Operating Model'!N51 -> -325.6835 | ... P13: =-'04 Operating Model'!P51 -> -279.35248
